File: 488nm Raman/_2021_04_13_15_29_56_Stone Wall_488 nm_600 (500nm)_X50_VIS_LWD_100%__01.txt
#Acq. time (s)=	10
#Accumulations=	2
#Range (cm-¹)=	71...3780
#Windows=	2
#Auto scanning=	Off
#Autofocus=	Off
#Macrospot=	Off
#AutoExposure=	Off
#Spike filter=	Multiple accum.
#Delay time (s)=	0
#Binning=	1
#Readout mode=	Signal
#DeNoise=	Off
#ICS correction=	Off
#Dark correction=	Off
#Inst. Process=	Off
#Detector temperature (°C)=	-75.13
#Instrument=	LabRAM HR Evol
#Detector=	Synapse
#Objective=	X50_VIS_LWD
#Grating=	600 (500nm)
#ND Filter=	100%
#Laser (nm)=	488
#Hole=	49.98
#Range=	Visible
#StageXY=	Marzhauser
#StageZ=	Marzhauser
#X (µm)=	0
#Y (µm)=	0
#Z (µm)=	0
#Full time(s)=	59
#Project=	2021-4-13_Andrew_Fertilizer
#Sample=
#Site=
#Title=	_2021_04_13_15_29_00_Stone Wall_488 nm_600 (500nm)_X50_VIS_LWD_100%_
#Remark=
#Date=	13.04.2021 15:29
#Acquired=	13.04.2021 15:29:22
#ICS:Correction=	13.04.2021 15:30:08
73.8841	2913.82
77.3099	2626.68
80.7358	2421.05
84.1593	2492.44
87.583	2455.9
91.0042	2375.32
94.4242	2243.35
97.8444	2330.05
101.262	2315.46
104.679	2251.47
108.096	2302.64
111.51	2277.8
114.923	2268.85
118.335	2221.38
121.746	2266.49
125.156	2358.87
128.564	2329.46
131.973	2306.1
135.38	2294.58
138.785	2297.86
142.189	2297.26
145.591	2291.43
148.992	2285.3
152.393	2324.8
155.793	2255.09
159.191	2384.93
162.588	2397.01
165.983	2297.87
169.378	2356.79
172.772	2404.44
176.165	2467.01
179.555	2362.96
182.945	2399.08
186.333	2282.3
189.722	2325.73
193.107	2397.28
196.493	2415.21
199.877	2392.95
203.26	2452.09
206.642	2413.86
210.023	2414.33
213.402	2489.08
216.78	2416.24
220.158	2499.41
223.534	2387.81
226.908	2479.27
230.282	2547.77
233.654	2481.82
237.026	2556.39
240.396	2450.54
243.765	2514.05
247.133	2474.27
250.5	2606.97
253.865	2518.65
257.23	2587.83
260.593	2571.62
263.955	2577.22
267.315	2559.12
270.675	2592.29
274.034	2610.08
277.392	2646.21
280.748	2653.24
284.103	2636.82
287.457	2640.75
290.81	2621.21
294.161	2669.33
297.512	2673.21
300.862	2682.93
304.21	2774.06
307.557	2755.82
310.903	2732.99
314.247	2821.37
317.592	2833.75
320.934	2831.17
324.276	2850.98
327.616	2837.64
330.954	2867.08
334.293	2930.73
337.63	2888.06
340.965	2902.78
344.299	2942.81
347.633	2946.89
350.965	3029.08
354.296	2985.78
357.627	2931.32
360.956	3054.58
364.283	3022.63
367.61	3048.93
370.934	3087.04
374.259	3046.61
377.582	3073.18
380.904	3146.02
384.225	3163.22
387.545	3110.19
390.863	3181.71
394.181	3173.25
397.497	3248.37
400.812	3188.84
404.126	3281.11
407.44	3294.4
410.751	3316.12
414.062	3341.18
417.371	3285.38
420.68	3287.21
423.987	3345.65
427.294	3369.28
430.598	3316.84
433.902	3423.21
437.205	3431.76
440.507	3461.37
443.807	3481.98
447.106	3363.41
450.405	3434.53
453.702	3479.12
456.998	3477.56
460.293	3526.19
463.587	3429.54
466.879	3558.41
470.171	3538.36
473.461	3623.68
476.751	3628.32
480.039	3699.45
483.326	3652.66
486.612	3674.2
489.896	3735.52
493.18	3701.49
496.463	3774.58
499.745	3761.95
503.024	3655.05
506.304	3860.31
509.583	3788.53
512.859	3814.94
516.135	3762.96
519.41	3850.95
522.684	3891.14
525.956	3850.06
529.228	3848
532.498	3975.06
535.767	3876.84
539.036	3989.96
542.302	4020.4
545.568	3989.98
548.834	4066.21
552.097	4016.39
555.36	4063
558.621	4062.52
561.881	4143.06
565.14	4093.29
568.398	4177.26
571.655	4118.63
574.911	4196.51
578.166	4208.62
581.42	4262.61
584.673	4287.42
587.925	4248.71
591.175	4177.29
594.425	4241.69
597.674	4264.58
600.92	4292.07
604.166	4419.92
607.412	4235.3
610.655	4361.52
613.898	4449.79
617.139	4384.8
620.38	4327.33
623.62	4409.67
626.858	4462.56
630.095	4435.09
633.332	4416.93
636.566	4432.62
639.801	4496.23
643.034	4444.63
646.265	4508.21
649.496	4579.26
652.726	4528.23
655.955	4528.82
659.182	4636.24
662.408	4554.68
665.633	4586.84
668.857	4810.7
672.081	4671.15
675.303	4699
678.524	4701.16
681.744	4662.61
684.962	4821.58
688.18	4816.13
691.397	4816.26
694.613	4760.06
697.826	4828.72
701.04	4906.67
704.253	4802.39
707.463	4829.4
710.674	4836.45
713.883	4916.25
717.09	4808.67
720.298	4972.44
723.503	4940.99
726.708	4841.13
729.911	5006.1
733.115	4934.34
736.316	5025.36
739.516	5023.04
742.716	5006.18
745.914	5039.81
749.111	5036.82
752.307	5040.24
755.502	5011.04
758.696	5128.52
761.889	5087.69
765.081	5219.12
768.272	5202.73
771.461	5171.81
774.65	5210.85
777.838	5134.68
781.024	5199.86
784.208	5170.35
787.393	5204.62
790.576	5270.15
793.759	5434.82
796.94	5244.23
800.12	5270.33
803.299	5324.61
806.477	5264.51
809.653	5273.02
812.83	5106.26
816.004	5285.24
819.178	5181.4
822.35	5347.53
825.522	5315.12
828.692	5346.54
831.862	5348.97
835.03	5434.51
838.197	5390.08
841.363	5476.39
844.529	5404.5
847.693	5396.03
850.856	5371.98
854.018	5425.41
857.179	5549.06
860.338	5467.19
863.497	5462.59
866.655	5467.13
869.812	5408.49
872.967	5406.54
876.122	5416.34
879.276	5457.19
882.429	5556.73
885.58	5430.72
888.731	5500.82
891.879	5557.71
895.028	5615.07
898.176	5592.58
901.321	5528.41
904.467	5664.16
907.61	5615.67
910.754	5550.91
913.895	5677.97
917.037	5681.55
920.176	5597.45
923.316	5743.47
926.453	5717.54
929.589	5629.6
932.726	5722.78
935.86	5587.12
938.994	5528.84
942.126	5657.36
945.257	5671.37
948.389	5635.89
951.518	5702.4
954.647	5638.77
957.774	5779.81
960.9	5681.75
964.026	5760.98
967.149	5856.23
970.273	5743.82
973.394	5723.15
976.517	5631.43
979.636	5867.57
982.754	5731.35
985.874	5702.97
988.99	5882.14
992.105	5924.18
995.222	6000.29
998.335	5910.88
1001.45	5917.76
1004.56	5947.3
1007.67	6025.03
1010.78	5831.56
1013.89	5883.51
1017	5839.79
1020.1	5917.42
1023.21	5920.14
1026.31	5805.09
1029.42	5929.17
1032.52	5811.71
1035.62	5934.31
1038.72	5896.44
1041.82	5917.8
1044.92	5872.4
1048.02	5979.89
1051.11	5970.26
1054.21	5860.21
1057.3	5862.73
1060.4	5949.13
1063.49	5825.02
1066.58	5891.87
1069.67	5905.28
1072.76	5934.92
1075.85	5841.56
1078.93	5869.71
1082.02	5921.45
1085.11	5838.76
1088.19	5781.43
1091.27	5834.53
1094.35	5894.53
1097.44	5843.95
1100.51	5965.58
1103.59	5915.94
1106.67	5730.5
1109.75	5953.76
1112.82	5897.36
1115.9	5861.79
1118.97	5824.2
1122.05	5857.93
1125.12	5942.47
1128.19	5882.04
1131.26	5946.43
1134.33	5916.24
1137.39	5928.62
1140.46	5842.25
1143.53	5822.21
1146.59	5884.31
1149.66	5984.25
1152.72	5811.87
1155.78	5939.22
1158.84	5946.92
1161.9	5805.56
1164.96	5915.06
1168.02	5870.29
1171.07	5908.32
1174.13	6025
1177.18	6074.42
1180.24	5919.64
1183.29	5998.72
1186.34	5993.5
1189.39	6030.73
1192.44	5885.1
1195.49	5983.36
1198.54	5891.3
1201.59	5991.15
1204.63	6011.09
1207.68	5914.57
1210.72	5928.01
1213.76	5929.67
1216.8	5799.99
1219.84	5843.73
1222.88	5972.51
1225.92	5895.9
1228.96	5872.4
1232	5945.47
1235.03	5836.22
1238.07	5847.92
1241.1	5868.78
1244.13	5853.93
1247.16	5945.67
1250.19	5939.49
1253.22	5854.74
1256.25	5988
1259.28	5882.78
1262.31	5912.46
1265.33	5934.89
1268.36	5813.55
1271.38	5826.2
1274.4	5845.26
1277.42	5790.2
1280.45	5889.5
1283.47	5891.36
1286.48	5890.7
1289.5	5885.73
1292.52	5747.72
1295.53	5881.88
1298.55	5919.88
1301.56	5824.99
1304.58	5892.85
1307.59	5747.08
1310.6	5881.7
1313.61	5819.87
1316.62	5952.79
1319.63	5768.1
1322.63	5879.37
1325.64	5700.01
1328.64	5815.35
1331.65	5818.36
1334.65	5839.39
1337.65	5770.54
1340.65	5869.79
1343.65	5917.36
1346.65	5766.82
1349.65	5777.13
1352.65	5788.6
1355.64	5668.84
1358.64	5909.92
1361.63	5807.43
1364.63	5805.42
1367.62	5772.14
1370.61	5796.71
1373.6	5763.92
1376.59	5752.9
1379.58	5756.48
1382.56	5682.17
1385.55	5806.02
1388.53	5752.19
1391.52	5701.55
1394.5	5756.34
1397.49	5766.5
1400.47	5751.58
1403.45	5773.86
1406.43	5793.25
1409.4	5781.45
1412.38	5719.83
1415.36	5834.94
1418.33	5829.9
1421.31	5690.75
1424.28	5838.08
1427.26	5835.92
1430.23	5777.58
1433.2	5782.37
1436.17	5768.64
1439.14	5782.28
1442.1	5813.21
1445.07	5842.62
1448.04	5691.49
1451	5670.44
1453.97	5801.43
1456.93	5763.96
1459.89	5711.14
1462.85	5880.15
1465.81	5781.92
1468.77	5737.85
1471.73	5820.31
1474.69	5620.12
1477.64	5736.18
1480.6	5726.73
1483.55	5687.95
1486.51	5699.09
1489.46	5753.25
1492.41	5673.09
1495.36	5670.46
1498.31	5580.66
1501.26	5681.52
1504.21	5551.6
1507.15	5682.58
1510.1	5734.55
1513.04	5650.49
1515.99	5713.24
1518.93	5717.62
1521.87	5661.92
1524.81	5615.58
1527.75	5684.22
1530.69	5755.59
1533.63	5683.87
1536.57	5623.56
1539.5	5585.38
1542.44	5631.94
1545.37	5704.85
1548.31	5604.07
1551.24	5591.24
1554.17	5654.57
1557.1	5599.7
1560.03	5602.36
1562.96	5749.5
1565.89	5651.87
1568.81	5546.64
1571.74	5646.44
1574.66	5650.32
1577.59	5592.91
1580.51	5530.6
1583.43	5653.87
1586.35	5545.74
1589.27	5583.15
1592.19	5488.01
1595.11	5635.29
1598.03	5650.41
1600.94	5661.12
1603.86	5618.11
1606.77	5591.13
1609.69	5554.22
1612.6	5582.15
1615.51	5517.04
1618.42	5486.17
1621.33	5551.92
1624.24	5557.48
1627.15	5506.27
1630.05	5477.6
1632.96	5421.04
1635.87	5524.78
1638.77	5475.09
1641.67	5504.63
1644.58	5684.2
1647.48	5575.26
1650.38	5477.67
1653.28	5509.91
1656.17	5563.04
1659.07	5552.17
1661.97	5510.51
1664.87	5518.69
1667.76	5473.52
1670.65	5476.6
1673.55	5433.04
1676.44	5583.2
1679.33	5493.55
1682.22	5374.53
1685.11	5358.28
1688	5402.65
1690.88	5388.47
1693.77	5482.09
1696.65	5357.82
1699.54	5428.11
1702.42	5393.17
1705.31	5424.93
1708.19	5364.03
1711.07	5291.9
1713.95	5374.37
1716.83	5339.88
1719.7	5313.87
1722.58	5436.52
1725.46	5402.83
1728.33	5276.92
1731.21	5392.11
1734.08	5363.99
1736.95	5311.59
1739.82	5239.84
1742.7	5373.94
1745.57	5213.12
1748.43	5236.84
1751.3	5385.37
1754.17	5379.33
1757.04	5283.13
1759.9	5274.47
1762.77	5224.2
1765.63	5327.05
1768.49	5248.28
1771.35	5345.86
1774.21	5357.17
1777.07	5171.51
1779.93	5207.75
1782.79	5304.23
1785.64	5319.08
1788.5	5354.06
1791.36	5309.54
1794.21	5403
1797.06	5324.2
1799.92	5280.99
1802.77	5318.38
1805.62	5255.27
1808.47	5271.16
1811.32	5168.8
1814.16	5238.49
1817.01	5283.94
1819.86	5277.14
1822.7	5248.99
1825.55	5136
1828.39	5161.17
1831.23	5149.9
1834.07	5131.14
1836.91	5088.99
1839.75	5179.93
1842.59	5292.98
1845.43	5190.75
1848.27	5199.61
1851.1	5166.33
1853.94	5128.79
1856.77	5206.85
1859.6	5217.7
1862.44	5121.14
1865.27	5200.08
1868.1	5149.57
1870.93	5139.01
1873.76	5126.94
1876.58	5169.09
1879.41	5032.95
1882.24	5147.83
1885.06	5066.94
1887.89	5100.16
1890.71	5165.21
1893.53	5091.02
1896.35	5038.34
1899.17	5076.27
1901.99	5068.2
1904.81	5070.78
1907.63	5013.72
1910.45	5062.2
1913.26	5054.5
1916.08	4992.01
1918.89	5004.21
1921.71	5043.14
1924.52	5120.17
1927.33	5070.25
1930.14	5036.04
1932.95	5024.53
1935.76	5002.56
1938.57	5137.87
1941.37	5041.08
1944.18	5041.34
1946.99	5041.3
1949.79	5078.66
1952.59	4985.33
1955.4	5024.41
1958.2	4968.74
1961	5056.52
1963.8	4994.29
1966.6	5034.13
1969.4	4924.27
1972.19	4922.37
1974.99	4966.03
1977.79	4987.53
1980.58	4942.48
1983.37	5076.49
1986.17	4944.99
1988.96	5024.06
1991.75	5010.06
1994.54	5082.64
1997.33	5028.72
2000.12	5002.69
2002.9	4934.24
2005.69	4948.59
2008.48	4969.4
2011.26	4998.25
2014.05	5055.38
2016.83	5076.06
2019.61	4936.2
2022.39	4960.03
2025.18	4944.74
2027.95	5031.53
2030.73	5027.79
2033.51	4911.27
2036.29	5020.05
2039.06	4950.06
2041.84	5048.19
2044.61	4960.23
2047.39	4938.57
2050.16	4926.46
2052.93	4915.22
2055.7	4874.46
2058.47	4823.06
2061.24	4925.19
2064.01	4855.32
2066.78	4898.14
2069.54	4972.93
2072.31	4919.1
2075.07	4780.79
2077.84	4900.5
2080.6	4939.69
2083.36	4826.38
2086.12	4832.4
2088.88	4791.74
2091.64	4923.06
2094.4	4894.05
2097.16	4854.77
2099.92	4866.75
2102.67	4826.63
2105.43	4862.84
2108.18	4842.66
2110.94	4836.23
2113.69	4816.14
2116.44	4847.53
2119.19	4824.64
2121.94	4837.43
2124.69	4821.23
2127.44	4808.15
2130.19	4843.53
2132.93	4810.7
2135.68	4811.05
2138.42	4831.82
2141.17	4812.91
2143.91	4805.75
2146.65	4817.54
2149.39	4758.67
2152.13	4808.45
2154.87	4794.79
2157.61	4828.1
2160.35	4759.18
2163.09	4783.08
2165.76	4775.34
2168.51	4828.13
2171.26	4747.81
2174	4808.08
2176.75	4737.82
2179.49	4749.9
2182.24	4630.91
2184.98	4824.57
2187.72	4687.12
2190.46	4812.8
2193.2	4833.08
2195.94	4709.1
2198.68	4695.4
2201.42	4720.36
2204.16	4769.02
2206.89	4793.82
2209.63	4823.93
2212.36	4747.72
2215.09	4802.88
2217.83	4752.59
2220.56	4708.62
2223.29	4691.52
2226.02	4851.11
2228.75	4724.23
2231.48	4770.58
2234.2	4731.88
2236.93	4684.34
2239.66	4802.27
2242.38	4696.49
2245.11	4660.32
2247.83	4746.63
2250.55	4808.18
2253.27	4742.52
2255.99	4726.56
2258.71	4851.16
2261.43	4702.8
2264.15	4728.68
2266.87	4679.79
2269.59	4700.74
2272.3	4675.22
2275.02	4769.79
2277.73	4666.39
2280.44	4657.16
2283.16	4690.67
2285.87	4703.34
2288.58	4713.57
2291.29	4673.78
2294	4624.34
2296.7	4627.46
2299.41	4698.38
2302.12	4678.14
2304.82	4620.62
2307.53	4698.37
2310.23	4658.76
2312.94	4728.66
2315.64	4758.4
2318.34	4688.49
2321.04	4715.55
2323.74	4686.26
2326.44	4680.27
2329.14	4645.81
2331.83	4663.55
2334.53	4611.91
2337.23	4627.57
2339.92	4649.1
2342.61	4572.88
2345.31	4675.77
2348	4625.97
2350.69	4604.91
2353.38	4574.88
2356.07	4697.53
2358.76	4539.95
2361.45	4701.35
2364.14	4683.64
2366.82	4589.88
2369.51	4641.64
2372.19	4616.03
2374.88	4622.88
2377.56	4626.21
2380.24	4660.57
2382.92	4599.84
2385.6	4574.87
2388.28	4570.65
2390.96	4581.56
2393.64	4492.02
2396.32	4610.72
2398.99	4596.84
2401.67	4583.74
2404.35	4515.61
2407.02	4584.15
2409.69	4551.47
2412.36	4595.69
2415.04	4591.12
2417.71	4510.09
2420.38	4494.04
2423.05	4586.53
2425.71	4568.55
2428.38	4489.31
2431.05	4514.64
2433.71	4553.06
2436.38	4497.64
2439.04	4590.2
2441.71	4589.24
2444.37	4504.02
2447.03	4473.13
2449.69	4459.7
2452.35	4473.77
2455.01	4522.23
2457.67	4614.56
2460.33	4475.02
2462.98	4475.61
2465.64	4543.85
2468.29	4561.68
2470.95	4470.09
2473.6	4529.22
2476.26	4520.47
2478.91	4456.23
2481.56	4503.3
2484.21	4609.03
2486.86	4472.5
2489.51	4452.75
2492.15	4502.14
2494.8	4537.83
2497.45	4472.22
2500.09	4518.97
2502.74	4543.99
2505.38	4508.1
2508.02	4559.91
2510.67	4529.54
2513.31	4503.74
2515.95	4511.29
2518.59	4528.62
2521.23	4454.91
2523.86	4474
2526.5	4410.37
2529.14	4452.9
2531.77	4522.79
2534.41	4494.32
2537.04	4507.55
2539.68	4481.23
2542.31	4464.97
2544.94	4564.45
2547.57	4450.96
2550.2	4467.92
2552.83	4420.74
2555.46	4468.39
2558.09	4360.14
2560.71	4502.1
2563.34	4457.83
2565.96	4404.82
2568.59	4503.64
2571.21	4369.87
2573.84	4450.68
2576.46	4454.77
2579.08	4435.75
2581.7	4468.98
2584.32	4464.06
2586.94	4466.23
2589.55	4351.32
2592.17	4396.12
2594.79	4407.92
2597.4	4402.53
2600.02	4418.88
2602.63	4338.36
2605.25	4448.67
2607.86	4428.98
2610.47	4341.23
2613.08	4381.58
2615.69	4352.79
2618.3	4372.37
2620.91	4421.27
2623.52	4340.42
2626.12	4367.59
2628.73	4443.01
2631.33	4414.69
2633.94	4323.84
2636.54	4373.91
2639.15	4332.11
2641.75	4364.85
2644.35	4364.55
2646.95	4349.98
2649.55	4347.83
2652.15	4376.65
2654.75	4368.05
2657.34	4386.6
2659.94	4288.13
2662.54	4373.82
2665.13	4291.28
2667.72	4371.07
2670.32	4335.49
2672.91	4340.02
2675.5	4301.16
2678.09	4320.23
2680.68	4306.04
2683.27	4315.68
2685.86	4359.12
2688.45	4338.58
2691.04	4247.8
2693.62	4335.84
2696.21	4270.5
2698.79	4286.8
2701.38	4331.84
2703.96	4307.71
2706.54	4355.65
2709.13	4304.3
2711.71	4313.81
2714.28	4266.08
2716.86	4340.02
2719.44	4315.62
2722.02	4318.91
2724.6	4317.63
2727.17	4347.73
2729.75	4261.16
2732.32	4327.67
2734.9	4278.13
2737.47	4334.7
2740.04	4267.64
2742.61	4201.79
2745.18	4236.59
2747.75	4242.58
2750.32	4207.39
2752.89	4199.59
2755.46	4280.39
2758.03	4181.73
2760.59	4213.33
2763.16	4238.94
2765.72	4198.73
2768.28	4343.78
2770.85	4246.5
2773.41	4130.92
2775.97	4223.64
2778.53	4250.38
2781.09	4244.22
2783.65	4311.88
2786.21	4212.77
2788.76	4204.33
2791.32	4166.86
2793.88	4198.4
2796.43	4134.53
2798.99	4237.32
2801.54	4179.04
2804.09	4234.61
2806.65	4183.72
2809.2	4231.04
2811.75	4186.33
2814.3	4192.88
2816.85	4145.56
2819.39	4206
2821.94	4182.62
2824.49	4123.39
2827.03	4157.46
2829.58	4128.44
2832.12	4130.73
2834.67	4201.38
2837.21	4162.38
2839.75	4141.47
2842.29	4124.88
2844.83	4185.28
2847.37	4140.83
2849.91	4136.08
2852.45	4065.23
2854.99	4203.32
2857.52	4193.86
2860.06	4125.72
2862.6	4114.59
2865.13	4165.8
2867.66	4185.71
2870.2	4056.85
2872.73	4119.42
2875.26	4179.65
2877.79	4126.58
2880.32	4137.95
2882.85	4146.8
2885.38	4138.18
2887.9	4096.42
2890.43	4115.96
2892.96	4066.78
2895.48	4100.92
2898.01	4054.16
2900.53	4055.98
2903.05	4042.9
2905.57	4004.43
2908.1	4127
2910.62	4115.85
2913.14	3999.86
2915.66	4044.21
2918.17	4183.44
2920.69	4099.71
2923.21	4084.38
2925.72	4109.85
2928.24	4075.12
2930.76	4022.35
2933.27	4044.27
2935.78	4044.32
2938.3	4025.51
2940.81	4014.75
2943.32	4049.78
2945.83	4123.54
2948.34	3994.7
2950.84	4038.32
2953.35	4061.79
2955.86	4001.13
2958.37	4055.25
2960.87	4018.4
2963.38	4046.97
2965.88	3994.86
2968.38	4074.38
2970.89	4008.5
2973.39	4032.16
2975.89	4029.55
2978.39	4002.34
2980.89	3957.52
2983.39	4160.29
2985.89	4013.74
2988.38	4063.51
2990.88	3955.33
2993.38	4029.79
2995.87	4041.08
2998.36	4006.96
3000.86	4054.34
3003.35	4054.24
3005.84	4002.41
3008.33	3993.59
3010.82	4009.29
3013.31	4047.52
3015.8	3950.45
3018.29	3979.25
3020.78	4076.39
3023.27	4037.88
3025.75	4015.58
3028.24	3969.6
3030.72	3965.61
3033.21	3940.64
3035.69	3983.25
3038.17	3928.07
3040.65	4050.33
3043.13	4036.7
3045.61	4005.11
3048.09	3912.21
3050.57	4011
3053.05	3960.54
3055.53	4004.09
3058.01	3983.17
3060.48	3978.5
3062.96	3998.72
3065.43	4022.97
3067.9	4059.77
3070.38	4011.96
3072.85	4030.37
3075.32	4018.76
3077.79	3927.15
3080.26	4006.85
3082.73	4023.4
3085.2	4025.8
3087.66	3976.59
3090.13	3930.22
3092.6	3929.42
3095.06	4047.47
3097.53	4012.25
3099.99	4005.59
3102.45	3953.28
3104.92	3990.99
3107.38	3978.55
3109.84	3958.77
3112.3	4016.33
3114.76	4064.16
3117.22	4026.49
3119.68	3961.33
3122.13	4081.26
3124.59	4032.72
3127.05	3978.13
3129.5	4094.08
3131.96	4060.64
3134.41	4027.62
3136.86	4084.67
3139.32	4128.42
3141.77	4057.1
3144.22	4038.85
3146.67	4056.87
3149.12	4010.21
3151.57	4105.37
3154.01	4085.96
3156.46	4093.04
3158.91	4089.7
3161.35	4078.6
3163.8	4159.61
3166.24	4098.62
3168.69	4164.1
3171.13	4061.9
3173.57	4099.79
3176.01	4061.07
3178.45	4136.87
3180.89	4121.81
3183.33	4114.79
3185.77	4133.29
3188.21	4157.52
3190.64	4138.42
3193.08	4194.77
3195.52	4226.81
3197.95	4144.57
3200.38	4182.53
3202.82	4155.72
3205.25	4171.67
3207.68	4273.69
3210.11	4173.91
3212.54	4133.39
3214.97	4265.16
3217.4	4204.49
3219.83	4181.54
3222.26	4204.18
3224.69	4172.79
3227.11	4221.86
3229.54	4192.36
3231.96	4170.24
3234.39	4111.34
3236.81	4181.34
3239.23	4169.51
3241.65	4153.82
3244.07	4154.32
3246.49	4144.63
3248.91	4071.69
3251.33	4145.98
3253.75	4165.87
3256.17	4128.86
3258.59	4092.79
3261	4203.99
3263.42	4104.07
3265.83	4120.38
3268.25	4111.27
3270.66	4141.82
3273.07	4188.75
3275.48	4144.78
3277.9	4157.47
3280.31	4102.56
3282.72	4110.34
3285.13	4118.13
3287.53	4133.88
3289.94	4098.33
3292.35	4152.14
3294.75	4059.29
3297.16	4111.43
3299.56	4156.69
3301.97	4159.44
3304.37	4103.91
3306.77	4136.03
3309.18	4127.7
3311.58	4039.91
3313.98	4129.28
3316.38	4182.88
3318.78	4127.72
3321.18	4093.94
3323.57	4078.86
3325.97	4150.57
3328.37	4117.02
3330.76	4110.64
3333.16	4091.8
3335.55	4063
3337.94	4074.44
3340.34	4103.85
3342.73	4078.82
3345.12	4036.43
3347.51	4140.52
3349.9	4060.15
3352.29	4081.29
3354.68	4080.3
3357.07	4062.03
3359.45	4167.1
3361.84	4050.68
3364.23	4074
3366.61	4132.18
3369	4079.23
3371.38	4094.05
3373.76	4127.15
3376.14	4021.51
3378.52	4125.27
3380.91	4124.54
3383.29	4073.59
3385.67	4035.38
3388.04	4081.15
3390.42	4090.19
3392.8	4102.6
3395.18	4126.9
3397.55	4074.59
3399.93	4101.9
3402.3	4081.69
3404.68	4105.78
3407.05	4083.69
3409.42	4043.6
3411.79	4007.26
3414.16	3989.41
3416.53	4122.97
3418.9	4040.2
3421.27	4076.11
3423.64	4028.72
3426.01	3985.13
3428.38	3982.08
3430.74	4009.34
3433.11	3984.17
3435.47	4011.37
3437.84	3973.42
3440.2	3973.8
3442.56	4025.45
3444.92	3951.37
3447.28	3997.72
3449.65	3993.68
3452.01	3949.57
3454.37	3978.49
3456.72	3996.46
3459.08	3984.15
3461.44	4013.4
3463.8	3987.27
3466.15	3892.52
3468.51	3901.57
3470.86	3932.91
3473.21	3864.62
3475.57	3913.23
3477.92	3835.4
3480.27	3892.54
3482.62	3856.49
3484.97	3939.09
3487.32	3861.95
3489.67	3935.82
3492.02	3942.6
3494.37	3849.79
3496.71	3792.42
3499.06	3871.6
3501.4	3886.07
3503.75	3809.86
3506.09	3804.79
3508.44	3653.15
3510.78	3752.27
3513.12	3757.15
3515.46	3703.96
3517.8	3656.28
3520.14	3712.03
3522.48	3694.17
3524.82	3699.26
3527.16	3730.73
3529.5	3719.56
3531.83	3679.83
3534.17	3697.36
3536.5	3709.34
3538.84	3721.24
3541.17	3612.01
3543.51	3661.01
3545.84	3598.59
3548.17	3572.42
3550.5	3583.91
3552.83	3483.43
3555.16	3489.91
3557.49	3580.66
3559.82	3512.89
3562.15	3559.6
3564.48	3550.6
3566.8	3569.22
3569.13	3556.64
3571.45	3509.43
3573.78	3518.37
3576.1	3464.71
3578.42	3551.69
3580.75	3511.6
3583.07	3519.13
3585.39	3445.57
3587.71	3391.44
3590.03	3457.29
3592.35	3440.73
3594.67	3415.13
3596.98	3444.35
3599.3	3448.63
3601.62	3391.78
3603.93	3473.78
3606.25	3446.54
3608.56	3459.57
3610.87	3465.61
3613.19	3400.55
3615.5	3382.67
3617.81	3392.85
3620.12	3380.68
3622.43	3434.83
3624.74	3396.12
3627.05	3345.39
3629.36	3365.69
3631.67	3323.08
3633.97	3367.76
3636.28	3304.14
3638.59	3328.6
3640.89	3301.27
3643.2	3264.74
3645.5	3277.21
3647.8	3361.07
3650.1	3282.98
3652.41	3254.09
3654.71	3251.74
3657.01	3222.43
3659.31	3277.78
3661.6	3294.29
3663.9	3111.47
3666.2	3218.62
3668.5	3239.45
3670.79	3161.35
3673.09	3112.04
3675.38	3189.01
3677.68	3150.3
3679.97	3061.29
3682.27	3153.86
3684.56	3106.54
3686.85	3194.87
3689.14	3152.88
3691.43	3177.54
3693.72	3127.41
3696.01	3136.1
3698.3	3113.95
3700.58	3061.02
3702.87	3087.16
3705.16	3122.23
3707.44	2966.24
3709.73	3006.53
3712.01	3074.15
3714.3	3009.57
3716.58	3007.12
3718.86	3046.3
3721.14	3083.52
3723.42	3029.54
3725.7	3077.38
3727.98	2958.21
3730.26	2985.1
3732.54	2998.74
3734.82	3016.31
3737.1	2960.47
3739.37	2943.84
3741.65	2913.63
3743.92	2980.86
3746.2	3010.8
3748.47	2932.27
3750.75	2915.05
3753.02	2952.06
3755.29	3007.04
3757.56	2997.89
3759.83	2982.11
3762.1	2945.57
3764.37	2957.67
3766.64	3024.02
3768.91	2954.2
3771.17	2940.94
3773.44	3011.39
3775.71	2986.5
3777.97	2891.38
3779.48	2966.72