File: 488nm Raman/_2021_04_13_15_26_54_Lebanon_488 nm_600 (500nm)_X50_VIS_LWD_100%__01.txt
#Acq. time (s)=	10
#Accumulations=	2
#Range (cm-¹)=	71...3780
#Windows=	2
#Auto scanning=	Off
#Autofocus=	Off
#Macrospot=	Off
#AutoExposure=	Off
#Spike filter=	Multiple accum.
#Delay time (s)=	0
#Binning=	1
#Readout mode=	Signal
#DeNoise=	Off
#ICS correction=	Off
#Dark correction=	Off
#Inst. Process=	Off
#Detector temperature (°C)=	-75.13
#Instrument=	LabRAM HR Evol
#Detector=	Synapse
#Objective=	X50_VIS_LWD
#Grating=	600 (500nm)
#ND Filter=	100%
#Laser (nm)=	488
#Hole=	49.98
#Range=	Visible
#StageXY=	Marzhauser
#StageZ=	Marzhauser
#X (µm)=	0
#Y (µm)=	0
#Z (µm)=	0
#Full time(s)=	46
#Project=	2021-4-13_Andrew_Fertilizer
#Sample=
#Site=
#Title=	_2021_04_13_15_26_08_Lebanon_488 nm_600 (500nm)_X50_VIS_LWD_100%_
#Remark=
#Date=	13.04.2021 15:26
#Acquired=	13.04.2021 15:26:20
#ICS:Correction=	13.04.2021 15:26:58
73.8841	4772.11
77.3099	4136.72
80.7358	3870.46
84.1593	3913.22
87.583	3830.12
91.0042	3899.83
94.4242	3758.22
97.8444	3721.41
101.262	3744.82
104.679	3776.01
108.096	3712.35
111.51	3732.35
114.923	3755.21
118.335	3778.34
121.746	3787.56
125.156	3710.02
128.564	3785.78
131.973	3735.88
135.38	3728.19
138.785	3748.05
142.189	3698.25
145.591	3755.4
148.992	3743.56
152.393	3742.1
155.793	3775.09
159.191	3768.97
162.588	3876.89
165.983	3889.76
169.378	3859.31
172.772	3772.88
176.165	3919.39
179.555	3807.7
182.945	3830.59
186.333	3847.65
189.722	3884.76
193.107	3827.62
196.493	3932.16
199.877	3824.87
203.26	3898.83
206.642	3831.52
210.023	3898.29
213.402	3897.27
216.78	3966.65
220.158	3916.69
223.534	3887.59
226.908	3976.02
230.282	3974.48
233.654	3897.25
237.026	3994
240.396	3914.52
243.765	3959.18
247.133	4024.02
250.5	4023.22
253.865	4028.15
257.23	4073.82
260.593	4066.02
263.955	4007.39
267.315	3969.73
270.675	4037.19
274.034	3952.75
277.392	4048.09
280.748	4004.65
284.103	4116.85
287.457	4132.41
290.81	4100.17
294.161	4088.21
297.512	4112.67
300.862	4075.33
304.21	4112.07
307.557	4163.2
310.903	4112.43
314.247	4225.08
317.592	4278.1
320.934	4196.07
324.276	4217.28
327.616	4179.67
330.954	4234.23
334.293	4308.01
337.63	4273.68
340.965	4293.3
344.299	4343.26
347.633	4249.5
350.965	4300.16
354.296	4371.75
357.627	4264.92
360.956	4342.25
364.283	4358.97
367.61	4352.38
370.934	4439.02
374.259	4383.42
377.582	4438.31
380.904	4435.97
384.225	4475.58
387.545	4543.5
390.863	4503.69
394.181	4488.3
397.497	4542.83
400.812	4548.19
404.126	4546.01
407.44	4603.42
410.751	4538.82
414.062	4587.19
417.371	4632.79
420.68	4511.9
423.987	4607.89
427.294	4615.07
430.598	4642.85
433.902	4606.87
437.205	4639.24
440.507	4644.84
443.807	4652.65
447.106	4677.88
450.405	4637.53
453.702	4627.53
456.998	4600.33
460.293	4756.98
463.587	4668.18
466.879	4717.72
470.171	4752.83
473.461	4839.44
476.751	4856.4
480.039	4882.99
483.326	4702.94
486.612	4798.78
489.896	4884.46
493.18	4860.7
496.463	4817.13
499.745	4852.83
503.024	4821.87
506.304	4893.11
509.583	4893.58
512.859	5020.74
516.135	4842.11
519.41	4913.55
522.684	4953.69
525.956	5024.07
529.228	4992.65
532.498	4935.57
535.767	5019.77
539.036	5007.05
542.302	5009.29
545.568	4966.55
548.834	5044.33
552.097	4969.95
555.36	5107.62
558.621	5233.65
561.881	5206.01
565.14	5260.12
568.398	5147.05
571.655	5151.08
574.911	5085.75
578.166	5111.93
581.42	5176.24
584.673	5130.58
587.925	5198.06
591.175	5235.1
594.425	5344.58
597.674	5279.76
600.92	5298.29
604.166	5264.7
607.412	5238.19
610.655	5270.69
613.898	5255.79
617.139	5381.3
620.38	5392.93
623.62	5334.5
626.858	5441.7
630.095	5421.97
633.332	5369.21
636.566	5432.18
639.801	5459.1
643.034	5365.31
646.265	5400.86
649.496	5437.87
652.726	5442.83
655.955	5579.73
659.182	5419.4
662.408	5634.52
665.633	5597.26
668.857	5531
672.081	5586.52
675.303	5523.6
678.524	5540.29
681.744	5632.47
684.962	5529.58
688.18	5683.05
691.397	5629.61
694.613	5581.76
697.826	5664.12
701.04	5453.68
704.253	5587.72
707.463	5825.22
710.674	5722.25
713.883	5707.85
717.09	5721.04
720.298	5725.99
723.503	5758.87
726.708	5712.24
729.911	5640.29
733.115	5801.92
736.316	5705.01
739.516	5752.57
742.716	5811.42
745.914	5764.55
749.111	5771.48
752.307	5892.84
755.502	5783.88
758.696	5860.47
761.889	5810.39
765.081	5913.2
768.272	5914.72
771.461	5781.36
774.65	6078.5
777.838	5981.27
781.024	5810.8
784.208	5943.67
787.393	6048.14
790.576	5934.9
793.759	5926.95
796.94	6036.4
800.12	6004.17
803.299	6110.2
806.477	6078.43
809.653	5976.33
812.83	6083.34
816.004	6052.16
819.178	5989.47
822.35	6074.45
825.522	5892.59
828.692	6069.61
831.862	6022.77
835.03	6105.05
838.197	6024.49
841.363	6168
844.529	6106.8
847.693	6211.65
850.856	6198.06
854.018	6078.92
857.179	6144.83
860.338	6178.26
863.497	6117.3
866.655	6211.74
869.812	6159.42
872.967	6166.98
876.122	6215.87
879.276	6211.9
882.429	6268.37
885.58	6327.84
888.731	6161.25
891.879	6303.76
895.028	6327.59
898.176	6348.29
901.321	6365.29
904.467	6330.17
907.61	6375.76
910.754	6414.6
913.895	6328.58
917.037	6385.91
920.176	6325.48
923.316	6426.32
926.453	6348.98
929.589	6374.55
932.726	6331.12
935.86	6384.12
938.994	6501.45
942.126	6464.49
945.257	6416.74
948.389	6504.23
951.518	6420.43
954.647	6468.68
957.774	6462.88
960.9	6454.43
964.026	6455.52
967.149	6465.24
970.273	6548.88
973.394	6474.23
976.517	6583.6
979.636	6507.95
982.754	6667.71
985.874	6550.89
988.99	6693.28
992.105	6685.6
995.222	6755.47
998.335	6729.88
1001.45	6744.08
1004.56	6715.07
1007.67	6725.58
1010.78	6757.35
1013.89	6689.88
1017	6685.63
1020.1	6756.64
1023.21	6782.05
1026.31	6757.43
1029.42	6796.98
1032.52	6703.05
1035.62	6759.26
1038.72	6726.66
1041.82	6906.6
1044.92	6735.78
1048.02	6826.7
1051.11	6767.25
1054.21	6887.25
1057.3	6739.81
1060.4	6895.97
1063.49	6807.02
1066.58	6950.21
1069.67	6845.31
1072.76	6829.42
1075.85	6844.91
1078.93	6958.19
1082.02	6969.41
1085.11	6809
1088.19	6820.94
1091.27	6805.79
1094.35	6828.02
1097.44	6809.83
1100.51	6807.84
1103.59	6819.86
1106.67	6908.4
1109.75	6912.67
1112.82	6814.16
1115.9	6788.15
1118.97	7009.62
1122.05	6783.1
1125.12	7036.76
1128.19	7087.77
1131.26	6906.91
1134.33	6937.95
1137.39	6849.66
1140.46	6913.9
1143.53	6997.94
1146.59	6977.6
1149.66	7051.81
1152.72	6994.59
1155.78	6988.87
1158.84	6961.55
1161.9	7078.84
1164.96	7164.33
1168.02	7042.67
1171.07	7104.97
1174.13	7037.21
1177.18	7054.78
1180.24	7066.89
1183.29	7138.56
1186.34	6961.69
1189.39	7177.49
1192.44	7133.29
1195.49	7132.14
1198.54	7050.73
1201.59	7126.62
1204.63	7165.56
1207.68	7167.89
1210.72	7182.46
1213.76	7053.6
1216.8	7152.11
1219.84	7182.24
1222.88	7196.71
1225.92	7150.12
1228.96	7186.36
1232	7181.47
1235.03	7267.51
1238.07	7329.71
1241.1	7263.77
1244.13	7200.65
1247.16	7381.68
1250.19	7166.84
1253.22	7225.35
1256.25	7135.63
1259.28	7245.83
1262.31	7237.15
1265.33	7211.03
1268.36	7193.78
1271.38	7220.64
1274.4	7226.97
1277.42	7272.97
1280.45	7286.86
1283.47	7185.66
1286.48	7326.03
1289.5	7271.5
1292.52	7247
1295.53	7161.04
1298.55	7215.89
1301.56	7211.35
1304.58	7258.71
1307.59	7309.25
1310.6	7188.89
1313.61	7235.2
1316.62	7247
1319.63	7354.65
1322.63	7410.09
1325.64	7364.55
1328.64	7335.67
1331.65	7344.25
1334.65	7349.77
1337.65	7348.38
1340.65	7502.9
1343.65	7441.71
1346.65	7307.4
1349.65	7299.27
1352.65	7430.3
1355.64	7280.81
1358.64	7299.49
1361.63	7436.85
1364.63	7396.56
1367.62	7458.72
1370.61	7421.99
1373.6	7370.69
1376.59	7445.63
1379.58	7563.33
1382.56	7450.39
1385.55	7441.89
1388.53	7508.48
1391.52	7554.14
1394.5	7433.63
1397.49	7419.41
1400.47	7399.91
1403.45	7369.68
1406.43	7366.58
1409.4	7524.88
1412.38	7493.16
1415.36	7636.72
1418.33	7521.26
1421.31	7521.98
1424.28	7597.63
1427.26	7477.25
1430.23	7573.66
1433.2	7578.76
1436.17	7596.66
1439.14	7616
1442.1	7651.89
1445.07	7518.31
1448.04	7647.58
1451	7549.96
1453.97	7584.02
1456.93	7602.31
1459.89	7696.76
1462.85	7688.03
1465.81	7495.76
1468.77	7652.23
1471.73	7622.03
1474.69	7572.61
1477.64	7566.26
1480.6	7698.7
1483.55	7660.19
1486.51	7797.9
1489.46	7606.14
1492.41	7598.76
1495.36	7576.34
1498.31	7717.71
1501.26	7605.08
1504.21	7577.54
1507.15	7746.1
1510.1	7660.89
1513.04	7619.32
1515.99	7774.69
1518.93	7574.17
1521.87	7669.13
1524.81	7683.96
1527.75	7611.01
1530.69	7643.89
1533.63	7832.81
1536.57	7704.69
1539.5	7610.02
1542.44	7745.6
1545.37	7877.62
1548.31	7691.48
1551.24	7697.65
1554.17	7650.51
1557.1	7614.38
1560.03	7672.23
1562.96	7678.04
1565.89	7722.36
1568.81	7679.01
1571.74	7787.71
1574.66	7744.34
1577.59	7715.84
1580.51	7787.53
1583.43	7773.95
1586.35	7740.91
1589.27	7816.47
1592.19	7834.67
1595.11	7646.75
1598.03	7793.42
1600.94	7679.08
1603.86	7800.2
1606.77	7787.08
1609.69	7799.9
1612.6	7707.89
1615.51	7817.77
1618.42	7781.86
1621.33	7926.72
1624.24	7707.32
1627.15	7721.81
1630.05	7814.8
1632.96	7620.27
1635.87	7725.32
1638.77	7930.15
1641.67	7686.37
1644.58	7620.72
1647.48	7646.87
1650.38	7706.12
1653.28	7747.84
1656.17	7754.54
1659.07	7741.71
1661.97	7894.67
1664.87	7867.95
1667.76	7859.54
1670.65	7841.8
1673.55	7755.17
1676.44	7859.34
1679.33	7764.86
1682.22	7838.78
1685.11	7794.33
1688	7779.46
1690.88	7745.39
1693.77	7799.86
1696.65	7714.88
1699.54	7736.1
1702.42	7656.52
1705.31	7679.58
1708.19	7801.01
1711.07	7712.01
1713.95	7843.83
1716.83	7722
1719.7	7784.31
1722.58	7862.82
1725.46	7713.83
1728.33	7597.68
1731.21	7788.37
1734.08	7805.16
1736.95	7755.62
1739.82	7881.98
1742.7	7844.85
1745.57	7796.11
1748.43	7816.23
1751.3	7812.16
1754.17	7686.13
1757.04	7611.64
1759.9	7775.58
1762.77	7733.47
1765.63	7791.24
1768.49	7828.89
1771.35	7740.19
1774.21	7820.49
1777.07	7809.71
1779.93	7758.74
1782.79	7592.86
1785.64	7733.1
1788.5	7637.17
1791.36	7681.96
1794.21	7810.22
1797.06	7770.83
1799.92	7688.3
1802.77	7741.5
1805.62	7723.01
1808.47	7742.07
1811.32	7713.33
1814.16	7833.91
1817.01	7686.46
1819.86	7769.24
1822.7	7839.54
1825.55	7704.25
1828.39	7667.92
1831.23	7679.98
1834.07	7709.07
1836.91	7808.78
1839.75	7863.51
1842.59	7834.69
1845.43	7806.92
1848.27	7770.73
1851.1	7750.83
1853.94	7796.94
1856.77	7676.41
1859.6	7679.06
1862.44	7627.27
1865.27	7564.95
1868.1	7699.74
1870.93	7817.3
1873.76	7708.99
1876.58	7766.94
1879.41	7737.49
1882.24	7795
1885.06	7751
1887.89	7809.82
1890.71	7670.73
1893.53	7681.8
1896.35	7810.18
1899.17	7592.57
1901.99	7645.43
1904.81	7713.49
1907.63	7665.42
1910.45	7763.72
1913.26	7744.33
1916.08	7770.43
1918.89	7635.32
1921.71	7703.17
1924.52	7630.4
1927.33	7704.46
1930.14	7677.08
1932.95	7784.98
1935.76	7789.55
1938.57	7771.28
1941.37	7606.85
1944.18	7618.82
1946.99	7596.73
1949.79	7619.33
1952.59	7593.89
1955.4	7742.14
1958.2	7631.73
1961	7662.06
1963.8	7677.03
1966.6	7620.64
1969.4	7792
1972.19	7701.92
1974.99	7698.84
1977.79	7639.96
1980.58	7646.25
1983.37	7679.11
1986.17	7627.89
1988.96	7605.6
1991.75	7602.49
1994.54	7727
1997.33	7637.82
2000.12	7668.69
2002.9	7752.64
2005.69	7744.67
2008.48	7802.23
2011.26	7689.56
2014.05	7682.15
2016.83	7604.78
2019.61	7755.18
2022.39	7630.87
2025.18	7733.63
2027.95	7699.26
2030.73	7631.92
2033.51	7682.11
2036.29	7662.8
2039.06	7657.98
2041.84	7644.43
2044.61	7603.93
2047.39	7615.73
2050.16	7775.56
2052.93	7711.12
2055.7	7631.03
2058.47	7686.76
2061.24	7616.58
2064.01	7711.77
2066.78	7672.6
2069.54	7671.46
2072.31	7667.04
2075.07	7767.89
2077.84	7584.3
2080.6	7593.67
2083.36	7596.05
2086.12	7567.94
2088.88	7642.61
2091.64	7596.8
2094.4	7574.48
2097.16	7581.48
2099.92	7595.64
2102.67	7577.72
2105.43	7577.27
2108.18	7609.08
2110.94	7607.02
2113.69	7586.27
2116.44	7672.91
2119.19	7681.03
2121.94	7549.54
2124.69	7531.72
2127.44	7599.29
2130.19	7618.92
2132.93	7561.78
2135.68	7638.52
2138.42	7629.46
2141.17	7610.95
2143.91	7600.69
2146.65	7585.95
2149.39	7611.43
2152.13	7569.96
2154.87	7719.08
2157.61	7577.16
2160.35	7551.84
2163.09	7579.23
2165.76	7590.02
2168.51	7710.29
2171.26	7618.77
2174	7589.07
2176.75	7621.57
2179.49	7589.62
2182.24	7591.06
2184.98	7636.75
2187.72	7586.88
2190.46	7439.56
2193.2	7655.85
2195.94	7679.14
2198.68	7679.04
2201.42	7665.52
2204.16	7505.99
2206.89	7635.1
2209.63	7563.91
2212.36	7591.1
2215.09	7640.36
2217.83	7656.43
2220.56	7740.4
2223.29	7529.67
2226.02	7594.41
2228.75	7645.6
2231.48	7565.76
2234.2	7588.93
2236.93	7647.11
2239.66	7620.7
2242.38	7579.47
2245.11	7512.8
2247.83	7612.5
2250.55	7598.42
2253.27	7479.91
2255.99	7585.52
2258.71	7531.11
2261.43	7664.83
2264.15	7589.89
2266.87	7587.65
2269.59	7549.96
2272.3	7510.92
2275.02	7496.63
2277.73	7533.85
2280.44	7485.41
2283.16	7540.84
2285.87	7515.15
2288.58	7528.2
2291.29	7606.67
2294	7499.27
2296.7	7537.87
2299.41	7461.2
2302.12	7491.48
2304.82	7631.02
2307.53	7629.76
2310.23	7486.22
2312.94	7537.15
2315.64	7617.67
2318.34	7558.1
2321.04	7563.38
2323.74	7499.68
2326.44	7411.33
2329.14	7477.52
2331.83	7542.91
2334.53	7461.6
2337.23	7647.73
2339.92	7628.37
2342.61	7522.93
2345.31	7579.22
2348	7532.49
2350.69	7489.17
2353.38	7447.97
2356.07	7493.58
2358.76	7518.43
2361.45	7525.25
2364.14	7447.82
2366.82	7605.84
2369.51	7488.06
2372.19	7526.42
2374.88	7528.41
2377.56	7589.06
2380.24	7442.5
2382.92	7534.83
2385.6	7526.62
2388.28	7463.49
2390.96	7412.88
2393.64	7555.63
2396.32	7639.42
2398.99	7532.26
2401.67	7482.49
2404.35	7394.25
2407.02	7424.39
2409.69	7387.4
2412.36	7446.1
2415.04	7409.14
2417.71	7613.48
2420.38	7539.19
2423.05	7434.73
2425.71	7495.44
2428.38	7323.29
2431.05	7512.72
2433.71	7475.02
2436.38	7452.55
2439.04	7455.83
2441.71	7380.06
2444.37	7460.1
2447.03	7456.97
2449.69	7444.62
2452.35	7474.42
2455.01	7480.5
2457.67	7414.82
2460.33	7449.85
2462.98	7360.91
2465.64	7559.22
2468.29	7554.24
2470.95	7490.74
2473.6	7434.08
2476.26	7461.76
2478.91	7403.65
2481.56	7319.1
2484.21	7529.21
2486.86	7469.61
2489.51	7488.09
2492.15	7505.14
2494.8	7466.09
2497.45	7358.49
2500.09	7410.24
2502.74	7412.56
2505.38	7482.07
2508.02	7514.22
2510.67	7423.35
2513.31	7492.03
2515.95	7502.46
2518.59	7556.05
2521.23	7460.91
2523.86	7419.74
2526.5	7360.27
2529.14	7479.99
2531.77	7438.47
2534.41	7460.02
2537.04	7360.01
2539.68	7425.31
2542.31	7510.37
2544.94	7510.54
2547.57	7448.78
2550.2	7440.44
2552.83	7365.43
2555.46	7406.9
2558.09	7486.15
2560.71	7357.04
2563.34	7416.05
2565.96	7471.65
2568.59	7368.24
2571.21	7352.34
2573.84	7278.01
2576.46	7251.99
2579.08	7410.35
2581.7	7349.01
2584.32	7346.99
2586.94	7369.86
2589.55	7441.43
2592.17	7290.79
2594.79	7486.71
2597.4	7266.33
2600.02	7328.22
2602.63	7378.09
2605.25	7373.56
2607.86	7410.49
2610.47	7425.33
2613.08	7305.51
2615.69	7251.63
2618.3	7384.88
2620.91	7380.13
2623.52	7314.91
2626.12	7435.33
2628.73	7291.51
2631.33	7457.47
2633.94	7382.61
2636.54	7304.52
2639.15	7334.75
2641.75	7287.51
2644.35	7317.75
2646.95	7297.39
2649.55	7403.12
2652.15	7337.55
2654.75	7347.98
2657.34	7256.18
2659.94	7386.83
2662.54	7354.86
2665.13	7268.64
2667.72	7351.97
2670.32	7264.05
2672.91	7323
2675.5	7369.88
2678.09	7279.62
2680.68	7349.32
2683.27	7335.61
2685.86	7278.05
2688.45	7325.88
2691.04	7308.97
2693.62	7294.6
2696.21	7313.86
2698.79	7395.14
2701.38	7259.01
2703.96	7300.66
2706.54	7332.8
2709.13	7293.32
2711.71	7210.57
2714.28	7251.49
2716.86	7186.79
2719.44	7262.01
2722.02	7259.34
2724.6	7300.63
2727.17	7364.82
2729.75	7196.43
2732.32	7278.3
2734.9	7212.43
2737.47	7257.9
2740.04	7259.17
2742.61	7162.6
2745.18	7244.01
2747.75	7177.28
2750.32	7191.81
2752.89	7265.58
2755.46	7103.65
2758.03	7187.71
2760.59	7316.04
2763.16	7285.05
2765.72	7231.26
2768.28	7289.58
2770.85	7324.47
2773.41	7105.35
2775.97	7181.61
2778.53	7164
2781.09	7159.29
2783.65	7192.04
2786.21	7223.04
2788.76	7175.37
2791.32	7165.04
2793.88	7187.95
2796.43	7217.03
2798.99	7204.23
2801.54	7204.32
2804.09	7163.17
2806.65	7187.6
2809.2	7256.73
2811.75	7185.81
2814.3	7211.42
2816.85	7064.4
2819.39	7197.27
2821.94	7128.28
2824.49	7186.48
2827.03	7103.46
2829.58	7174.72
2832.12	7103.6
2834.67	7142.56
2837.21	7063.58
2839.75	7154.4
2842.29	7169.14
2844.83	7249.92
2847.37	7222.74
2849.91	7102.71
2852.45	7116.22
2854.99	7058.47
2857.52	7242.57
2860.06	7079.39
2862.6	7078.14
2865.13	7113.55
2867.66	7158.89
2870.2	7108.47
2872.73	7142.75
2875.26	7020.4
2877.79	7094.26
2880.32	7072.27
2882.85	7169.76
2885.38	7016.8
2887.9	7151.77
2890.43	7107.87
2892.96	7069.89
2895.48	7025.82
2898.01	6970.37
2900.53	7028.12
2903.05	7069.92
2905.57	7101.64
2908.1	7078.07
2910.62	7141.63
2913.14	7037.8
2915.66	7089.53
2918.17	7024.33
2920.69	6953.37
2923.21	7139.78
2925.72	7064.87
2928.24	7115.27
2930.76	7028.9
2933.27	7029.39
2935.78	7079.67
2938.3	7065.08
2940.81	6956.95
2943.32	7064.39
2945.83	7015.57
2948.34	7096.03
2950.84	6987.92
2953.35	7066.92
2955.86	7020.07
2958.37	6902.53
2960.87	6981.1
2963.38	7018.26
2965.88	7097.23
2968.38	6991.55
2970.89	6945.77
2973.39	7050.02
2975.89	7030.77
2978.39	7018.23
2980.89	6973.18
2983.39	6964.37
2985.89	6887.33
2988.38	6931.76
2990.88	7010.82
2993.38	6986.27
2995.87	7045.83
2998.36	7002.03
3000.86	6974.15
3003.35	6942.36
3005.84	6964.33
3008.33	6988.01
3010.82	6902.07
3013.31	7050.41
3015.8	6922.06
3018.29	6969.8
3020.78	6992.05
3023.27	7008.69
3025.75	7015.16
3028.24	6962.47
3030.72	7075.52
3033.21	6982.62
3035.69	6975.83
3038.17	6901.5
3040.65	6893.48
3043.13	6918.98
3045.61	6900.45
3048.09	7007.12
3050.57	6894.12
3053.05	6961.32
3055.53	6910.05
3058.01	6959.41
3060.48	6985.53
3062.96	6955.32
3065.43	7036.4
3067.9	6936.42
3070.38	7045.17
3072.85	6925.05
3075.32	6932.73
3077.79	6956.04
3080.26	6863.89
3082.73	7010.86
3085.2	6974.5
3087.66	6921.96
3090.13	6892.04
3092.6	6976.22
3095.06	6933.41
3097.53	6802.49
3099.99	6966.36
3102.45	6923.35
3104.92	6944.78
3107.38	6908.77
3109.84	6874.54
3112.3	6904.62
3114.76	6988.98
3117.22	6940.41
3119.68	6753.65
3122.13	6823.36
3124.59	6985.41
3127.05	6922.38
3129.5	7020.65
3131.96	7024.87
3134.41	6959.6
3136.86	6877.49
3139.32	7012.33
3141.77	7061.18
3144.22	6981.45
3146.67	7015.5
3149.12	6976.31
3151.57	7073.16
3154.01	6908.71
3156.46	6933.21
3158.91	6892.31
3161.35	7038.12
3163.8	7002.36
3166.24	6932.84
3168.69	6958.9
3171.13	6917.2
3173.57	6984.19
3176.01	6988.87
3178.45	6924.96
3180.89	6957.79
3183.33	6995.45
3185.77	6987.37
3188.21	6936.72
3190.64	7046.84
3193.08	7009.37
3195.52	6854.27
3197.95	7049.72
3200.38	7007.29
3202.82	7072.96
3205.25	7113.73
3207.68	6999.07
3210.11	7031.53
3212.54	7050.38
3214.97	7015.84
3217.4	7019.47
3219.83	6950.94
3222.26	7000.68
3224.69	6966.19
3227.11	6901.76
3229.54	7019.2
3231.96	7023.3
3234.39	7001.44
3236.81	6989.95
3239.23	6977.09
3241.65	7013.1
3244.07	6934.51
3246.49	6930.48
3248.91	6901.36
3251.33	6836.06
3253.75	6927.4
3256.17	6877.51
3258.59	6925.04
3261	6926.38
3263.42	6856.5
3265.83	6923.12
3268.25	6940.46
3270.66	6945.54
3273.07	6906.54
3275.48	6843.82
3277.9	6939.36
3280.31	6944.52
3282.72	6903.68
3285.13	6943.4
3287.53	7010.74
3289.94	6839.15
3292.35	6951.27
3294.75	6896.42
3297.16	6898.39
3299.56	6985.88
3301.97	6843.33
3304.37	6958.8
3306.77	6917.86
3309.18	6932.76
3311.58	6841.23
3313.98	6877.55
3316.38	6852.26
3318.78	6946.52
3321.18	6829.01
3323.57	6950.9
3325.97	7013.52
3328.37	6921.21
3330.76	6928.82
3333.16	6901.98
3335.55	6913.27
3337.94	6799.83
3340.34	6888.15
3342.73	6830.4
3345.12	6882.96
3347.51	6765.82
3349.9	6894.82
3352.29	6861.58
3354.68	6711.16
3357.07	6780.48
3359.45	6799.94
3361.84	6848.45
3364.23	6982.39
3366.61	6921.45
3369	6973.84
3371.38	6766.34
3373.76	6890.2
3376.14	6793.02
3378.52	6975.28
3380.91	6863.98
3383.29	6834.15
3385.67	6797.62
3388.04	6770.16
3390.42	6834.06
3392.8	6788.27
3395.18	6818.39
3397.55	6777.42
3399.93	6824.8
3402.3	6751.21
3404.68	6753.19
3407.05	6814.07
3409.42	6861.64
3411.79	6792.12
3414.16	6803.3
3416.53	6768.92
3418.9	6704.42
3421.27	6827.43
3423.64	6824.27
3426.01	6806.03
3428.38	6693.93
3430.74	6692.43
3433.11	6751.71
3435.47	6668.76
3437.84	6582.67
3440.2	6634.99
3442.56	6640.31
3444.92	6724.33
3447.28	6600.91
3449.65	6663.6
3452.01	6641.57
3454.37	6791.8
3456.72	6640.21
3459.08	6719.34
3461.44	6746.03
3463.8	6606.79
3466.15	6681.25
3468.51	6686.2
3470.86	6521.63
3473.21	6605.58
3475.57	6504.98
3477.92	6477.31
3480.27	6642.95
3482.62	6617.36
3484.97	6617.94
3487.32	6609.59
3489.67	6530.73
3492.02	6584.62
3494.37	6608.89
3496.71	6563.06
3499.06	6615.76
3501.4	6470.64
3503.75	6615.49
3506.09	6402.96
3508.44	6418.5
3510.78	6469.9
3513.12	6405.55
3515.46	6413.26
3517.8	6369.54
3520.14	6378.25
3522.48	6448.92
3524.82	6398.3
3527.16	6404.69
3529.5	6367.37
3531.83	6344.52
3534.17	6393.06
3536.5	6324.36
3538.84	6438.29
3541.17	6293.39
3543.51	6278.63
3545.84	6318.27
3548.17	6169.42
3550.5	6262.03
3552.83	6215.68
3555.16	6232.88
3557.49	6246.42
3559.82	6331.99
3562.15	6293.94
3564.48	6272.7
3566.8	6197.5
3569.13	6287.71
3571.45	6256.08
3573.78	6203.56
3576.1	6125.68
3578.42	6156.34
3580.75	6088.64
3583.07	6123.03
3585.39	6052.55
3587.71	6045.59
3590.03	6109.35
3592.35	5999.72
3594.67	6037.97
3596.98	6039.23
3599.3	6146.37
3601.62	6018.35
3603.93	6089.25
3606.25	6136.07
3608.56	6026.59
3610.87	6037.65
3613.19	5983.46
3615.5	6089.29
3617.81	6126.17
3620.12	6111.88
3622.43	6000.83
3624.74	6006.21
3627.05	5944.72
3629.36	6002.83
3631.67	5925.86
3633.97	5877.18
3636.28	5853.59
3638.59	5908.08
3640.89	5872.19
3643.2	5947.92
3645.5	5953.48
3647.8	5955.34
3650.1	6046.97
3652.41	5958.26
3654.71	5943.86
3657.01	5963.54
3659.31	5861.23
3661.6	5849.85
3663.9	5878.12
3666.2	5783.55
3668.5	5781.87
3670.79	5802.14
3673.09	5742.34
3675.38	5695.59
3677.68	5740.41
3679.97	5810.48
3682.27	5721.1
3684.56	5778.79
3686.85	5689.63
3689.14	5748.3
3691.43	5626.55
3693.72	5644.65
3696.01	5657.6
3698.3	5682.9
3700.58	5682.78
3702.87	5694.23
3705.16	5607.37
3707.44	5595.33
3709.73	5688.96
3712.01	5703.79
3714.3	5616.33
3716.58	5603.52
3718.86	5726.19
3721.14	5715.28
3723.42	5619.13
3725.7	5627.22
3727.98	5565.04
3730.26	5528.18
3732.54	5531.36
3734.82	5493.82
3737.1	5449.21
3739.37	5485.44
3741.65	5452.54
3743.92	5460.6
3746.2	5527.47
3748.47	5494.56
3750.75	5444.31
3753.02	5353.13
3755.29	5453.67
3757.56	5507.5
3759.83	5425.51
3762.1	5538.59
3764.37	5506.37
3766.64	5531.68
3768.91	5559.08
3771.17	5487.77
3773.44	5472.97
3775.71	5362.2
3777.97	5448.22
3779.48	5453.56