File: 488nm Raman/_2021_04_13_15_35_45_10-1_Water-CP_488 nm_600 (500nm)_X50_VIS_LWD_100%__01.txt
#Acq. time (s)=	10
#Accumulations=	2
#Range (cm-¹)=	71...3780
#Windows=	2
#Auto scanning=	Off
#Autofocus=	Off
#Macrospot=	Off
#AutoExposure=	Off
#Spike filter=	Multiple accum.
#Delay time (s)=	0
#Binning=	1
#Readout mode=	Signal
#DeNoise=	Off
#ICS correction=	On
#Dark correction=	Off
#Inst. Process=	Off
#Detector temperature (°C)=	-75.13
#Instrument=	LabRAM HR Evol
#Detector=	Synapse
#Objective=	X50_VIS_LWD
#Grating=	600 (500nm)
#ND Filter=	100%
#Laser (nm)=	488
#Hole=	49.98
#Range=	Visible
#StageXY=	Marzhauser
#StageZ=	Marzhauser
#X (µm)=	0
#Y (µm)=	0
#Z (µm)=	0
#Full time(s)=	55
#Project=	2021-4-13_Andrew_Fertilizer
#Sample=
#Site=
#Title=	_2021_04_13_15_34_49_10-1_Water-CP_488 nm_600 (500nm)_X50_VIS_LWD_100%_
#Remark=
#Date=	13.04.2021 15:35
#Acquired=	13.04.2021 15:35:11
73.8841	11530.8
77.3099	10055.9
80.7358	9542.75
84.1593	9747.97
87.583	9764.98
91.0042	9674.63
94.4242	9459.29
97.8444	9599.6
101.262	9618.61
104.679	9481.78
108.096	9578.44
111.51	9644.05
114.923	9608.93
118.335	9867.71
121.746	9707.51
125.156	9579.39
128.564	9779.07
131.973	9605.12
135.38	9845.4
138.785	9709.46
142.189	9838.57
145.591	9934.83
148.992	9920.1
152.393	9904.09
155.793	10004.8
159.191	9934.31
162.588	10067.7
165.983	10073.8
169.378	10126.5
172.772	10171
176.165	10348.5
179.555	10092.7
182.945	10308.8
186.333	10112.7
189.722	10131.4
193.107	10328.9
196.493	10424.3
199.877	10190.9
203.26	10403.4
206.642	10283.5
210.023	10334.7
213.402	10332
216.78	10494.9
220.158	10499.9
223.534	10398.7
226.908	10519.2
230.282	10562
233.654	10572.4
237.026	10739.4
240.396	10722.5
243.765	10577.3
247.133	10655.2
250.5	10590
253.865	10624.7
257.23	10835.6
260.593	10647.2
263.955	10668
267.315	10809.8
270.675	10803.6
274.034	10800.9
277.392	10871.1
280.748	10886
284.103	10802.1
287.457	10912.4
290.81	10769.5
294.161	10964.9
297.512	10993.6
300.862	11036.7
304.21	11045.2
307.557	11093.5
310.903	11131.8
314.247	11259.8
317.592	11280.2
320.934	11298.4
324.276	11361.5
327.616	11499.2
330.954	11499
334.293	11250.5
337.63	11507.6
340.965	11585.1
344.299	11469.3
347.633	11525.6
350.965	11572.7
354.296	11608.2
357.627	11619.6
360.956	11791.6
364.283	11655
367.61	11905.3
370.934	11690.1
374.259	11812.1
377.582	11789.6
380.904	11858.9
384.225	11878.2
387.545	11897.1
390.863	12045.8
394.181	11994.1
397.497	12284.7
400.812	12103.3
404.126	12219.9
407.44	12147.3
410.751	12162.1
414.062	12243.5
417.371	12144.2
420.68	12272.2
423.987	12151.5
427.294	12164.3
430.598	12161.5
433.902	12354.1
437.205	12101.3
440.507	12359.3
443.807	12365.9
447.106	12354
450.405	12494.5
453.702	12410.1
456.998	12461
460.293	12476.6
463.587	12531.4
466.879	12491.6
470.171	12718.6
473.461	12642.5
476.751	12843.1
480.039	12581.8
483.326	12726.2
486.612	12679.4
489.896	12785.4
493.18	12955.1
496.463	12855.1
499.745	12997.7
503.024	12963.9
506.304	12906.7
509.583	12819.7
512.859	13118.1
516.135	12901.9
519.41	12915.7
522.684	13000.8
525.956	13206
529.228	13179.1
532.498	13137.9
535.767	13255.4
539.036	13082.6
542.302	13203.2
545.568	13169.7
548.834	13355.9
552.097	13281.9
555.36	13311.7
558.621	13374.4
561.881	13526
565.14	13611.1
568.398	13411.8
571.655	13414.5
574.911	13509.2
578.166	13604.9
581.42	13692.2
584.673	13649.3
587.925	13681.8
591.175	13793.9
594.425	13796.4
597.674	13836.3
600.92	13729.6
604.166	13877.4
607.412	13887.9
610.655	13858.1
613.898	13969.7
617.139	14109.6
620.38	13829.5
623.62	14215.9
626.858	14131.4
630.095	14040.9
633.332	14169
636.566	14164.4
639.801	14405.4
643.034	14188
646.265	14152.8
649.496	14239.9
652.726	14295.3
655.955	14342.1
659.182	14494.5
662.408	14323
665.633	14560.9
668.857	14678
672.081	14587.8
675.303	14634.5
678.524	14488.3
681.744	14747.6
684.962	14496.2
688.18	14776.8
691.397	14851.3
694.613	14906.9
697.826	15008.7
701.04	14958.3
704.253	15079
707.463	14885.8
710.674	15045.2
713.883	15018.6
717.09	15083.5
720.298	14879.8
723.503	14794.6
726.708	15145.1
729.911	15133.4
733.115	15153.4
736.316	15075.2
739.516	15222.7
742.716	15009.4
745.914	15148.3
749.111	15299.5
752.307	15523.6
755.502	15254.9
758.696	15147.5
761.889	15420.6
765.081	15569.9
768.272	15279.9
771.461	15509.6
774.65	15725
777.838	15426.6
781.024	15366.1
784.208	15530.9
787.393	15701.1
790.576	15642.4
793.759	15646.4
796.94	15774
800.12	15730.2
803.299	15804.6
806.477	15844
809.653	15779.1
812.83	15824.5
816.004	15928.7
819.178	15960
822.35	15984.5
825.522	15948.5
828.692	16035.9
831.862	15937.5
835.03	15848.8
838.197	15916.6
841.363	15868.6
844.529	16096.5
847.693	16314
850.856	16148.8
854.018	16180.7
857.179	16110.1
860.338	16177.9
863.497	16131.8
866.655	16103.4
869.812	16155.3
872.967	16438.7
876.122	16475.9
879.276	16362.7
882.429	16468.3
885.58	16419.7
888.731	16355.7
891.879	16540.1
895.028	16475.8
898.176	16546.9
901.321	16577.7
904.467	16528.4
907.61	16688
910.754	16481.1
913.895	16623
917.037	16583.7
920.176	16781
923.316	16685.9
926.453	16869.4
929.589	16752.1
932.726	16847.7
935.86	16754.2
938.994	16622
942.126	17011.1
945.257	17014.5
948.389	16848.4
951.518	16860.4
954.647	16993.2
957.774	16764.6
960.9	17060.8
964.026	17091.9
967.149	17032.6
970.273	17070.5
973.394	17038.6
976.517	17040.7
979.636	17144.2
982.754	17078.9
985.874	17376.5
988.99	17369.5
992.105	17310
995.222	17450.1
998.335	17257.6
1001.45	17330.5
1004.56	17290.5
1007.67	17404.2
1010.78	17537.8
1013.89	17773.7
1017	17724.5
1020.1	17477.1
1023.21	17440.7
1026.31	17887.8
1029.42	17803.2
1032.52	17743.1
1035.62	17793.9
1038.72	17913.4
1041.82	17818.9
1044.92	17804.2
1048.02	17860.1
1051.11	17825.8
1054.21	17800.7
1057.3	18005.6
1060.4	17911
1063.49	17982.2
1066.58	18014.7
1069.67	17718.3
1072.76	17925
1075.85	17806.3
1078.93	17918.1
1082.02	17886.1
1085.11	18017
1088.19	17947.1
1091.27	17924.4
1094.35	18203.6
1097.44	17950.9
1100.51	18045.7
1103.59	18129.6
1106.67	18127.3
1109.75	18056.1
1112.82	17702.3
1115.9	17921.8
1118.97	18089
1122.05	17966.1
1125.12	18076.3
1128.19	18183.2
1131.26	17943.2
1134.33	18358.3
1137.39	18583.8
1140.46	18425.4
1143.53	18282.1
1146.59	18296.4
1149.66	18447.7
1152.72	18358.4
1155.78	18487.8
1158.84	18485.2
1161.9	18450.3
1164.96	18469.3
1168.02	18559.7
1171.07	18797.1
1174.13	18476.9
1177.18	18597.7
1180.24	18701.9
1183.29	18894.6
1186.34	18736.8
1189.39	18522.3
1192.44	18746.7
1195.49	18765.3
1198.54	18719.5
1201.59	18850.5
1204.63	18912.5
1207.68	18824.3
1210.72	18935.6
1213.76	18767.6
1216.8	18871.9
1219.84	18936.9
1222.88	19070.9
1225.92	19106.7
1228.96	18818.9
1232	18887.4
1235.03	18975.9
1238.07	19025.8
1241.1	19354.2
1244.13	19215.5
1247.16	19051.8
1250.19	19098.9
1253.22	19110.4
1256.25	19147.2
1259.28	19044.6
1262.31	18940.3
1265.33	19195.3
1268.36	19251.5
1271.38	19103.3
1274.4	19201.9
1277.42	19102.6
1280.45	19066.4
1283.47	19028.5
1286.48	19268.4
1289.5	19249.1
1292.52	19235.3
1295.53	19022.7
1298.55	19343.9
1301.56	19302
1304.58	19203.2
1307.59	19394.5
1310.6	19397.7
1313.61	19138.3
1316.62	19495.4
1319.63	19622
1322.63	19425.9
1325.64	19469.6
1328.64	19600.5
1331.65	19459.7
1334.65	19456.3
1337.65	19571.8
1340.65	19495.6
1343.65	19700.4
1346.65	19617.9
1349.65	19400.8
1352.65	19485.7
1355.64	19760.8
1358.64	19809.3
1361.63	19569.4
1364.63	19880.3
1367.62	19717.4
1370.61	19656.2
1373.6	19766.7
1376.59	19596.4
1379.58	19756.9
1382.56	19839.1
1385.55	19765.7
1388.53	19836.5
1391.52	20091.4
1394.5	19813.1
1397.49	20120.2
1400.47	19979.9
1403.45	19878
1406.43	20048.1
1409.4	19941.2
1412.38	19673.8
1415.36	20053.4
1418.33	20213.8
1421.31	19908.9
1424.28	20057.2
1427.26	20217.2
1430.23	20360.5
1433.2	20023.1
1436.17	20206.5
1439.14	20360.2
1442.1	20340.1
1445.07	20411.5
1448.04	20296.1
1451	20188
1453.97	20574.4
1456.93	20433.6
1459.89	20486.8
1462.85	20712.1
1465.81	20408
1468.77	20687.9
1471.73	20459.2
1474.69	20448.5
1477.64	20628.2
1480.6	20540.8
1483.55	20412.5
1486.51	20473.6
1489.46	20442.5
1492.41	20591.7
1495.36	20574
1498.31	20413.7
1501.26	20281.5
1504.21	20250.8
1507.15	20559.7
1510.1	20537.5
1513.04	20460.3
1515.99	20620.7
1518.93	20449
1521.87	20469.3
1524.81	20722
1527.75	20680.5
1530.69	20609.2
1533.63	20589.5
1536.57	20804.1
1539.5	20736.4
1542.44	20503.2
1545.37	20707.1
1548.31	20908.4
1551.24	20785.6
1554.17	20753.2
1557.1	20694
1560.03	20886.4
1562.96	20752.8
1565.89	20972.9
1568.81	20555.9
1571.74	20868.8
1574.66	20870.9
1577.59	20971.9
1580.51	20897.1
1583.43	20901.9
1586.35	20879
1589.27	20878.8
1592.19	20997.1
1595.11	21048
1598.03	20861.1
1600.94	20891.6
1603.86	20765.6
1606.77	20919.9
1609.69	20963.1
1612.6	21008.7
1615.51	20910.2
1618.42	20953
1621.33	20952.5
1624.24	20842.3
1627.15	21001.9
1630.05	20906.8
1632.96	20787
1635.87	21035.7
1638.77	20957.4
1641.67	21258.8
1644.58	21074.6
1647.48	21065.7
1650.38	20885.3
1653.28	20932.6
1656.17	21028.7
1659.07	21431.2
1661.97	21136.8
1664.87	21167.1
1667.76	21385.1
1670.65	21006.8
1673.55	21264.3
1676.44	21297.6
1679.33	21109.6
1682.22	20908
1685.11	21032.7
1688	20911.2
1690.88	21164.5
1693.77	20984.5
1696.65	20907.7
1699.54	21119.7
1702.42	21020.3
1705.31	21118.7
1708.19	20896.6
1711.07	21205.3
1713.95	20917.5
1716.83	20945.6
1719.7	20911.1
1722.58	21003.3
1725.46	21189.9
1728.33	21139.6
1731.21	21254
1734.08	21015.2
1736.95	21110.3
1739.82	21199.8
1742.7	20978.7
1745.57	21134.1
1748.43	21138.1
1751.3	21059.5
1754.17	21230.7
1757.04	21326.7
1759.9	20929.2
1762.77	20963.8
1765.63	20885.8
1768.49	21124
1771.35	21009.6
1774.21	21058.6
1777.07	20916.6
1779.93	21021.9
1782.79	21222.3
1785.64	21098.2
1788.5	21076.5
1791.36	21247.8
1794.21	21031
1797.06	21231.7
1799.92	21179.9
1802.77	21244.5
1805.62	21149.6
1808.47	21280.6
1811.32	21225.6
1814.16	20977.9
1817.01	21033.6
1819.86	20981.1
1822.7	21147.5
1825.55	21016.7
1828.39	21016.8
1831.23	20917.8
1834.07	21025.4
1836.91	20961.9
1839.75	21324.4
1842.59	21131.8
1845.43	20761.1
1848.27	20917.9
1851.1	20738.1
1853.94	20712.2
1856.77	20901.8
1859.6	20875.7
1862.44	21148.9
1865.27	21060.2
1868.1	20952.2
1870.93	21171.2
1873.76	20921.4
1876.58	20756.4
1879.41	20970
1882.24	21107.6
1885.06	20977.5
1887.89	20784.6
1890.71	20988.9
1893.53	21043.6
1896.35	21088
1899.17	20910.3
1901.99	20818.9
1904.81	20889.8
1907.63	21026.9
1910.45	21184.2
1913.26	20870.9
1916.08	20929.5
1918.89	21000.3
1921.71	20991.7
1924.52	20814.6
1927.33	20758.4
1930.14	20872.2
1932.95	21020.4
1935.76	20801.1
1938.57	20918.9
1941.37	20758
1944.18	20883
1946.99	20849.6
1949.79	20680.2
1952.59	20778.5
1955.4	20872
1958.2	20737.3
1961	21055
1963.8	20645.4
1966.6	20891.1
1969.4	20916.2
1972.19	20977.2
1974.99	20833.7
1977.79	20833.3
1980.58	20837.1
1983.37	20821.4
1986.17	20558.7
1988.96	21181.8
1991.75	21042.9
1994.54	20935.2
1997.33	20913.6
2000.12	20928.1
2002.9	20712.1
2005.69	20846.7
2008.48	21024.6
2011.26	20847.7
2014.05	20794.9
2016.83	20710.3
2019.61	20940.7
2022.39	20580.6
2025.18	20833.9
2027.95	20895.3
2030.73	20832.1
2033.51	20711.9
2036.29	20856.7
2039.06	21045.9
2041.84	20954
2044.61	20855.7
2047.39	20822
2050.16	20959.8
2052.93	20932.8
2055.7	20650
2058.47	20571.1
2061.24	20681.4
2064.01	20727.8
2066.78	20834.6
2069.54	20675.2
2072.31	20817.4
2075.07	20736.9
2077.84	20471.4
2080.6	20835.3
2083.36	20593.3
2086.12	20509.5
2088.88	20519.2
2091.64	20617.5
2094.4	20603
2097.16	20379.1
2099.92	20513.2
2102.67	20677.8
2105.43	20553.6
2108.18	20490.3
2110.94	20596.8
2113.69	20630.1
2116.44	20562.3
2119.19	20529.2
2121.94	20487
2124.69	20561.6
2127.44	20628.9
2130.19	20527.9
2132.93	20482.1
2135.68	20636.2
2138.42	20574.6
2141.17	20461.7
2143.91	20592.9
2146.65	20601.5
2149.39	20477.1
2152.13	20599.1
2154.87	20630.3
2157.61	20605.1
2160.35	20509
2163.09	20591
2165.76	20610.5
2168.51	20565.6
2171.26	20510.7
2174	20600.6
2176.75	20634.8
2179.49	20530.1
2182.24	20374.5
2184.98	20476.6
2187.72	20404.6
2190.46	20564.1
2193.2	20542.3
2195.94	20639.1
2198.68	20640.4
2201.42	20545
2204.16	20685.6
2206.89	20515.3
2209.63	20535.6
2212.36	20400.5
2215.09	20629.7
2217.83	20590.6
2220.56	20436
2223.29	20502.7
2226.02	20634.1
2228.75	20554.9
2231.48	20460.7
2234.2	20525.6
2236.93	20398.5
2239.66	20615.1
2242.38	20493.2
2245.11	20327.3
2247.83	20432.3
2250.55	20445.2
2253.27	20409.5
2255.99	20257.1
2258.71	20363
2261.43	20409.7
2264.15	20535.5
2266.87	20383.2
2269.59	20336.7
2272.3	20461.5
2275.02	20324.1
2277.73	20382.2
2280.44	20430.6
2283.16	20341.2
2285.87	20189.3
2288.58	20285.8
2291.29	20385.5
2294	20299.9
2296.7	20196.1
2299.41	20192
2302.12	20134.6
2304.82	20229.6
2307.53	20457.4
2310.23	20298
2312.94	20318.8
2315.64	20319.2
2318.34	20289.5
2321.04	20238.4
2323.74	20350.7
2326.44	20252.9
2329.14	20148.9
2331.83	20206.9
2334.53	20283.6
2337.23	20331.5
2339.92	20198.3
2342.61	20297.8
2345.31	20088.4
2348	20059
2350.69	20005.7
2353.38	20074.9
2356.07	20023.4
2358.76	20293
2361.45	20218.5
2364.14	20164.9
2366.82	20159.2
2369.51	19996.8
2372.19	20272
2374.88	20241.8
2377.56	20138.5
2380.24	20242.5
2382.92	19963.9
2385.6	20126.6
2388.28	20119
2390.96	20167.8
2393.64	20191.8
2396.32	20193
2398.99	20063.2
2401.67	20053.8
2404.35	20112
2407.02	20081.4
2409.69	19916.2
2412.36	20110.9
2415.04	19957.6
2417.71	20071.2
2420.38	19830.3
2423.05	20121.2
2425.71	19853.1
2428.38	19996.7
2431.05	20151.6
2433.71	19982.7
2436.38	20093.2
2439.04	20063.7
2441.71	20013.4
2444.37	19987.9
2447.03	19843
2449.69	19806.1
2452.35	19911.9
2455.01	20022
2457.67	19824.5
2460.33	19901
2462.98	19937
2465.64	20091.5
2468.29	20024.4
2470.95	19894.8
2473.6	19918.2
2476.26	19858.1
2478.91	19781.7
2481.56	19856.1
2484.21	19960.1
2486.86	19784.6
2489.51	19864.6
2492.15	19929.4
2494.8	19887.4
2497.45	19920.6
2500.09	19925.5
2502.74	19720.8
2505.38	19985.3
2508.02	19729
2510.67	19787.9
2513.31	19812.5
2515.95	19868
2518.59	19853.7
2521.23	19642.7
2523.86	19813.6
2526.5	19690.7
2529.14	19754.4
2531.77	19780.9
2534.41	19883.2
2537.04	19758.1
2539.68	19610.4
2542.31	19888.3
2544.94	19822.2
2547.57	19835.5
2550.2	20034
2552.83	19893.7
2555.46	19667.2
2558.09	19634.1
2560.71	19810.9
2563.34	19726.8
2565.96	19743
2568.59	19722.1
2571.21	19753.4
2573.84	19742.5
2576.46	19576.6
2579.08	19569.1
2581.7	19555.4
2584.32	19614.3
2586.94	19653.7
2589.55	19613.3
2592.17	19645.9
2594.79	19518.1
2597.4	19533.4
2600.02	19684
2602.63	19518.5
2605.25	19586.6
2607.86	19485.7
2610.47	19665
2613.08	19506
2615.69	19312.3
2618.3	19498.1
2620.91	19628
2623.52	19460.8
2626.12	19596.2
2628.73	19537.7
2631.33	19356.7
2633.94	19611.4
2636.54	19518
2639.15	19505.9
2641.75	19548.8
2644.35	19518.7
2646.95	19402.1
2649.55	19425
2652.15	19459.7
2654.75	19567.1
2657.34	19430.8
2659.94	19469.5
2662.54	19504.8
2665.13	19350
2667.72	19573.5
2670.32	19386.1
2672.91	19384.9
2675.5	19403.4
2678.09	19385.4
2680.68	19232.5
2683.27	19380.8
2685.86	19332.5
2688.45	19452.9
2691.04	19486.4
2693.62	19329.8
2696.21	19257.1
2698.79	19246.3
2701.38	19268.6
2703.96	19355.1
2706.54	19225.6
2709.13	19374.9
2711.71	19269.1
2714.28	19191.5
2716.86	19245.5
2719.44	19207.8
2722.02	19228.6
2724.6	19300.2
2727.17	19085.5
2729.75	19262.7
2732.32	19270.3
2734.9	19182.8
2737.47	19259
2740.04	19204.1
2742.61	19091.3
2745.18	19158.5
2747.75	19186.3
2750.32	19022.1
2752.89	18972.7
2755.46	19058.4
2758.03	19070
2760.59	19062.2
2763.16	19010.8
2765.72	19240.8
2768.28	18871.4
2770.85	19076.2
2773.41	18837.4
2775.97	19063.3
2778.53	19067.8
2781.09	18829.8
2783.65	19124.1
2786.21	18971.6
2788.76	18876.7
2791.32	19033.6
2793.88	19153.3
2796.43	18913.1
2798.99	18891.6
2801.54	18997.3
2804.09	18885.5
2806.65	18791
2809.2	18880.9
2811.75	18914.4
2814.3	19014.1
2816.85	18783.5
2819.39	18860.5
2821.94	18788.6
2824.49	18875.7
2827.03	18650.1
2829.58	18807
2832.12	18800.6
2834.67	18713.3
2837.21	18812.5
2839.75	18903.4
2842.29	18765.8
2844.83	18631.1
2847.37	18720.6
2849.91	18692.7
2852.45	18772.5
2854.99	18582.8
2857.52	18576.3
2860.06	18556.2
2862.6	18617.5
2865.13	18626.4
2867.66	18725.1
2870.2	18556.7
2872.73	18662.9
2875.26	18599.9
2877.79	18558.6
2880.32	18589.6
2882.85	18714.2
2885.38	18604.8
2887.9	18593.8
2890.43	18300.6
2892.96	18519.6
2895.48	18487.8
2898.01	18512.9
2900.53	18568.1
2903.05	18388.2
2905.57	18350
2908.1	18384.2
2910.62	18392.1
2913.14	18444.1
2915.66	18561.8
2918.17	18407.4
2920.69	18257.4
2923.21	18453.5
2925.72	18398.6
2928.24	18345.2
2930.76	18232
2933.27	18213.8
2935.78	18341.2
2938.3	18190.6
2940.81	18354.1
2943.32	18121.5
2945.83	18273.8
2948.34	18267.7
2950.84	18134
2953.35	18253.7
2955.86	18217.2
2958.37	18215.8
2960.87	17944.2
2963.38	18028.8
2965.88	17991.6
2968.38	18204.8
2970.89	18158.8
2973.39	18179.4
2975.89	18176.2
2978.39	18189.5
2980.89	18124.2
2983.39	18038.4
2985.89	17796.3
2988.38	17963.9
2990.88	17973.9
2993.38	18049.1
2995.87	18016.4
2998.36	18024.7
3000.86	18057
3003.35	18065.6
3005.84	18040.9
3008.33	18013.3
3010.82	17996.4
3013.31	18119.4
3015.8	17934.9
3018.29	17914
3020.78	17865.8
3023.27	17765.8
3025.75	18057.8
3028.24	17831.6
3030.72	17972.3
3033.21	17787.5
3035.69	17805.5
3038.17	17839.6
3040.65	17966.6
3043.13	17650.7
3045.61	17883.8
3048.09	17873.3
3050.57	17646.4
3053.05	17593.2
3055.53	17661.6
3058.01	17653.4
3060.48	17601.6
3062.96	17750.4
3065.43	17665.4
3067.9	17945.2
3070.38	17788.1
3072.85	17788.2
3075.32	17717.7
3077.79	17623.4
3080.26	17769
3082.73	17610.2
3085.2	17545.7
3087.66	17312
3090.13	17559.7
3092.6	17517.1
3095.06	17419.2
3097.53	17583.6
3099.99	17512.5
3102.45	17397
3104.92	17510.9
3107.38	17560.4
3109.84	17388.2
3112.3	17549.8
3114.76	17496.4
3117.22	17517.9
3119.68	17419.7
3122.13	17441.3
3124.59	17370.7
3127.05	17394.9
3129.5	17424.5
3131.96	17371.7
3134.41	17553.6
3136.86	17580.7
3139.32	17508.4
3141.77	17535.3
3144.22	17242.4
3146.67	17470.2
3149.12	17333.6
3151.57	17210.2
3154.01	17352.7
3156.46	17241.4
3158.91	17318.5
3161.35	17275.6
3163.8	17264.7
3166.24	17334.9
3168.69	17414
3171.13	17186.6
3173.57	17289.6
3176.01	17303.3
3178.45	17140.5
3180.89	17201.1
3183.33	17311.8
3185.77	17293.1
3188.21	17268.7
3190.64	17201.2
3193.08	17287.7
3195.52	17158.1
3197.95	17285.8
3200.38	17164.8
3202.82	17345.7
3205.25	17218.7
3207.68	17098.3
3210.11	17220
3212.54	16938
3214.97	17123.4
3217.4	17104
3219.83	17128.9
3222.26	17073.6
3224.69	17161.3
3227.11	17152.4
3229.54	16970.9
3231.96	17091.7
3234.39	17166.7
3236.81	16975
3239.23	16992
3241.65	16940.3
3244.07	17022.9
3246.49	16981.6
3248.91	17046.7
3251.33	16892.8
3253.75	16826
3256.17	16870.7
3258.59	16840.1
3261	16937.7
3263.42	16862.9
3265.83	16758.6
3268.25	16761
3270.66	16832
3273.07	16796.1
3275.48	16654.2
3277.9	16800
3280.31	16674.9
3282.72	16882.8
3285.13	16745.4
3287.53	16791.7
3289.94	16703.9
3292.35	16649.2
3294.75	16593.9
3297.16	16757.5
3299.56	16768.5
3301.97	16633
3304.37	16750.7
3306.77	16650.6
3309.18	16693.1
3311.58	16709.1
3313.98	16613.1
3316.38	16641.7
3318.78	16562.9
3321.18	16664.8
3323.57	16550.6
3325.97	16609.5
3328.37	16552.1
3330.76	16535
3333.16	16411.4
3335.55	16420.6
3337.94	16515.4
3340.34	16577.6
3342.73	16322.1
3345.12	16472.4
3347.51	16366.8
3349.9	16304.4
3352.29	16277.7
3354.68	16284.2
3357.07	16293.9
3359.45	16340.8
3361.84	16489.8
3364.23	16390.3
3366.61	16291.5
3369	16536
3371.38	16477.8
3373.76	16199.7
3376.14	16274.2
3378.52	16352
3380.91	16137.5
3383.29	16016.9
3385.67	15917.6
3388.04	16252
3390.42	16098.8
3392.8	16016.8
3395.18	16155.1
3397.55	16013.7
3399.93	16102.5
3402.3	16043.7
3404.68	16012.4
3407.05	16026.7
3409.42	16184.6
3411.79	16064
3414.16	16004.1
3416.53	16064.1
3418.9	16121.6
3421.27	15840.8
3423.64	16000.8
3426.01	16066
3428.38	15868.8
3430.74	16003.7
3433.11	16013.1
3435.47	15871.5
3437.84	15775.3
3440.2	15849.4
3442.56	15923
3444.92	15825.5
3447.28	15695.3
3449.65	15704.2
3452.01	15894.7
3454.37	15918.2
3456.72	15788.5
3459.08	15877.2
3461.44	15902.4
3463.8	15866.2
3466.15	15690.3
3468.51	15649.6
3470.86	15733.9
3473.21	15556.5
3475.57	15796.1
3477.92	15732.2
3480.27	15565.3
3482.62	15651.3
3484.97	15538.8
3487.32	15591.4
3489.67	15586.6
3492.02	15458.5
3494.37	15627.5
3496.71	15529.6
3499.06	15674.8
3501.4	15596.5
3503.75	15620.3
3506.09	15413.7
3508.44	15488.7
3510.78	15466.1
3513.12	15458.3
3515.46	15247.5
3517.8	15353.3
3520.14	15368.9
3522.48	15446.4
3524.82	15393.1
3527.16	15447.7
3529.5	15450.2
3531.83	15462.5
3534.17	15255
3536.5	15386.4
3538.84	15291.1
3541.17	15286.9
3543.51	15305.9
3545.84	15146.8
3548.17	15115.1
3550.5	15144.8
3552.83	15179.5
3555.16	15034.7
3557.49	15158.3
3559.82	15141.8
3562.15	15111.2
3564.48	15231
3566.8	15157.1
3569.13	15106.2
3571.45	14873.1
3573.78	14896.4
3576.1	14937.2
3578.42	14978.3
3580.75	14957
3583.07	14791.4
3585.39	14842.7
3587.71	14669
3590.03	14883.2
3592.35	14757.4
3594.67	14737.7
3596.98	14678
3599.3	14734.3
3601.62	14854.3
3603.93	14713.2
3606.25	14758.8
3608.56	14818
3610.87	14827.9
3613.19	14667
3615.5	14804.4
3617.81	14625.9
3620.12	14927.4
3622.43	14719.5
3624.74	14756.3
3627.05	14723.8
3629.36	14759.8
3631.67	14532.1
3633.97	14535.6
3636.28	14607.5
3638.59	14659.5
3640.89	14335
3643.2	14686.4
3645.5	14546.1
3647.8	14547.9
3650.1	14662.9
3652.41	14643.8
3654.71	14525.6
3657.01	14402.9
3659.31	14525.5
3661.6	14391.9
3663.9	14219.5
3666.2	14207.3
3668.5	14222.4
3670.79	14303.9
3673.09	14075.8
3675.38	14258.7
3677.68	14177.7
3679.97	14329.4
3682.27	14204.1
3684.56	14133
3686.85	14236.1
3689.14	14206
3691.43	14125.2
3693.72	14225.6
3696.01	14122.8
3698.3	14152
3700.58	14023.5
3702.87	13936.3
3705.16	13932.7
3707.44	13883.2
3709.73	13943.7
3712.01	13790.5
3714.3	13918.4
3716.58	13826.5
3718.86	13782.2
3721.14	13886.4
3723.42	14038.6
3725.7	13995.5
3727.98	13871
3730.26	13859.7
3732.54	13650.3
3734.82	13561.1
3737.1	13701.9
3739.37	13565.7
3741.65	13609.1
3743.92	13536.6
3746.2	13408.3
3748.47	13421.6
3750.75	13503.9
3753.02	13568.4
3755.29	13395.1
3757.56	13469.3
3759.83	13558.5
3762.1	13505.7
3764.37	13657.3
3766.64	13652
3768.91	13638.1
3771.17	13477.3
3773.44	13493.2
3775.71	13472
3777.97	13315
3779.48	13491.5