File: 488nm Raman/_2021_04_13_15_20_07_Gro Fine_30-0-4_488 nm_600 (500nm)_X50_VIS_LWD_100%__01.txt
#Acq. time (s)=	10
#Accumulations=	2
#Range (cm-¹)=	-20...3600
#Windows=	2
#Auto scanning=	Off
#Autofocus=	Off
#Macrospot=	Off
#AutoExposure=	Off
#Spike filter=	Multiple accum.
#Delay time (s)=	0
#Binning=	1
#Readout mode=	Signal
#DeNoise=	Off
#ICS correction=	Off
#Dark correction=	Off
#Inst. Process=	Off
#Detector temperature (°C)=	-75.13
#Instrument=	LabRAM HR Evol
#Detector=	Synapse
#Objective=	X50_VIS_LWD
#Grating=	600 (500nm)
#ND Filter=	100%
#Laser (nm)=	488
#Hole=	49.98
#Range=	Visible
#StageXY=	Marzhauser
#StageZ=	Marzhauser
#X (µm)=	0
#Y (µm)=	0
#Z (µm)=	0
#Full time(s)=	53
#Project=	2021-4-13_Andrew_Fertilizer
#Sample=
#Site=
#Title=	_2021_04_13_15_19_13_Gro Fine_30-0-4_488 nm_600 (500nm)_X50_VIS_LWD_100%_
#Remark=
#Date=	13.04.2021 15:19
#Acquired=	13.04.2021 15:19:32
-19.9276	1
-16.469	10
-13.0115	5
-9.55521	13
-6.10007	153
-2.64609	257
0.805451	9
4.25711	6
7.7076	9
11.1569	7
14.6038	10
18.0508	14
21.4967	11
24.9401	11
28.3836	25
31.826	87
35.2659	266
38.706	673
42.1436	885
45.5813	880
49.0167	860
52.4508	759
55.8851	798
59.317	824
62.7477	1013
66.1785	1264
69.6069	1323
73.0341	1309
76.4602	1196
79.8852	1120
83.3102	1078
86.7329	1022
90.1544	993
93.5747	915
96.9939	831
100.412	792
103.829	786
107.245	731
110.658	657
114.072	655
117.484	607
120.895	598
124.305	603
127.713	553
131.121	509
134.527	518
137.931	496
141.336	517
144.739	466
148.14	483
151.541	451
154.939	475
158.338	432.995
161.734	459.979
165.131	406.964
168.525	427.949
171.917	437.933
175.31	378.918
178.701	387.902
182.091	391.887
185.479	355.871
188.867	351.856
192.253	345.841
195.638	315.825
199.022	335.81
202.405	312.794
205.786	333.779
209.167	298.763
212.546	317.748
215.924	296.732
219.301	282.717
222.677	272.702
226.052	262.686
229.426	239.671
232.798	243.655
236.169	225.64
239.539	233.624
242.908	218.609
246.276	202.594
249.642	227.578
253.008	210.563
256.371	193.547
259.735	228.532
263.097	199.516
266.458	172.501
269.818	181.486
273.176	169.47
276.532	190.455
279.889	173.439
283.244	185.424
286.599	174.408
289.951	159.393
293.302	162.377
296.652	159.362
300.002	169.347
303.35	166.331
306.697	163.316
310.043	169.3
313.387	149.285
316.731	161.269
320.073	164.254
323.414	160.239
326.754	176.223
330.093	160.208
333.431	151.192
336.768	141.177
340.104	170.161
343.437	146.146
346.771	138.131
350.103	163.115
353.434	165.1
356.763	163.084
360.092	172.069
363.42	163.053
366.746	166.038
370.072	147.022
373.395	159.007
376.719	160.992
380.04	165.976
383.361	187.961
386.68	159.945
389.998	171.93
393.316	173.914
396.632	155.899
399.947	172.884
403.262	149.868
406.574	187.853
409.886	155.837
413.196	158.822
416.505	168.806
419.813	145.791
423.12	168.776
426.426	163.76
429.731	172.745
433.035	179.729
436.338	180.714
439.639	168.698
442.94	169.683
446.239	153.667
449.537	161.652
452.833	166.637
456.13	179.621
459.425	170.606
462.719	177.59
466.01	182.575
469.302	159.559
472.592	180.544
475.881	167.529
479.169	150.513
482.456	183.498
485.741	167.482
489.027	197.467
492.31	179.451
495.593	167.436
498.874	177.421
502.154	170.405
505.433	178.39
508.711	179.374
511.988	164.359
515.264	203.343
518.538	193.328
521.811	188.312
525.084	188.297
528.355	174.282
531.625	178.266
534.894	196.251
538.162	182.235
541.429	174.22
544.695	188.204
547.96	185.189
551.223	178.174
554.486	175.158
557.747	172.143
561.007	193.127
564.267	188.112
567.524	169.096
570.781	193.081
574.037	160.066
577.291	187.05
580.545	179.035
583.797	174.019
587.049	197.004
590.299	178.988
593.548	168.973
596.797	187.957
600.043	177.942
603.289	172.927
606.534	162.911
609.778	177.896
613.02	143.88
616.261	184.865
619.502	155.849
622.742	169.834
625.98	166.819
629.217	176.803
632.453	173.788
635.688	174.772
638.922	153.757
642.154	153.741
645.385	158.726
648.616	159.711
651.846	158.695
655.074	158.68
658.301	161.664
661.527	165.649
664.753	157.633
667.977	172.618
671.199	178.602
674.422	177.587
677.642	165.572
680.862	158.556
684.08	169.541
687.298	197.525
690.514	172.51
693.729	162.494
696.944	168.479
700.157	176.464
703.368	186.448
706.58	171.433
709.79	176.417
712.998	182.402
716.206	172.386
719.413	177.371
722.618	176.356
725.823	161.34
729.026	161.325
732.228	190.309
735.43	173.294
738.63	177.278
741.829	163.263
745.027	186.247
748.225	160.232
751.421	172.217
754.615	177.201
757.809	167.186
761.002	177.17
764.193	175.155
767.384	163.139
770.572	178.124
773.761	170.109
776.949	185.093
780.135	167.078
783.319	178.062
786.504	162.047
789.687	171.031
792.87	175.016
796.05	169.001
799.23	177.985
802.408	174.97
805.587	181.954
808.763	173.939
811.938	158.923
815.113	177.908
818.286	169.892
821.459	163.877
824.63	182.862
827.8	192.846
830.969	186.831
834.138	179.815
837.305	181.8
840.471	171.784
843.635	164.769
846.799	176.754
849.962	178.738
853.124	172.723
856.284	174.707
859.444	169.692
862.602	159.676
865.76	173.661
868.916	165.646
872.072	161.63
875.226	153.615
878.38	147.599
881.532	155.584
884.684	157.568
887.834	164.553
890.982	161.537
894.13	169.522
897.278	180.507
900.424	163.491
903.569	174.476
906.712	192.46
909.855	173.445
912.997	153.429
916.137	185.414
919.277	182.399
922.416	174.383
925.553	168.368
928.69	169.352
931.826	170.337
934.959	177.321
938.093	168.306
941.226	184.291
944.357	174.275
947.487	156.26
950.616	186.244
953.744	190.229
956.871	182.213
959.998	169.198
963.122	193.182
966.246	190.167
969.368	190.152
972.492	191.136
975.613	184.121
978.732	197.105
981.851	220.09
984.968	259.074
988.085	301.059
991.2	343.044
994.315	450.028
997.43	480.013
1000.54	520.997
1003.65	509.982
1006.76	472.966
1009.87	354.951
1012.98	305.936
1016.09	265.92
1019.19	246.905
1022.3	205.889
1025.4	228.874
1028.51	183.858
1031.61	192.843
1034.71	201.827
1037.81	192.812
1040.91	204.797
1044.01	196.781
1047.11	195.766
1050.2	209.75
1053.3	193.735
1056.39	177.719
1059.49	190.704
1062.58	213.689
1065.67	194.673
1068.76	199.658
1071.85	200.642
1074.93	200.627
1078.02	211.611
1081.11	199.596
1084.19	175.581
1087.28	186.565
1090.36	212.55
1093.44	209.534
1096.52	199.519
1099.6	189.503
1102.68	194.488
1105.76	173.472
1108.83	186.457
1111.91	199.442
1114.98	190.426
1118.06	190.411
1121.13	193.395
1124.2	198.38
1127.27	177.364
1130.34	194.349
1133.41	219.334
1136.48	203.318
1139.55	228.303
1142.61	212.287
1145.67	196.272
1148.74	207.256
1151.8	228.241
1154.86	223.226
1157.92	228.21
1160.98	203.195
1164.04	209.179
1167.1	212.164
1170.15	208.148
1173.21	193.133
1176.26	210.117
1179.32	202.102
1182.37	205.087
1185.42	186.071
1188.47	205.056
1191.52	194.04
1194.57	188.025
1197.61	197.009
1200.66	204.994
1203.71	188.979
1206.75	196.963
1209.8	179.948
1212.84	199.932
1215.88	189.917
1218.92	182.901
1221.96	201.886
1225	203.871
1228.03	202.855
1231.07	184.84
1234.11	183.824
1237.14	204.809
1240.17	181.793
1243.21	184.778
1246.24	200.762
1249.27	203.747
1252.3	197.732
1255.33	190.716
1258.35	190.701
1261.38	174.685
1264.4	203.67
1267.43	181.654
1270.45	192.639
1273.48	180.624
1276.5	165.608
1279.52	204.593
1282.54	183.577
1285.55	185.562
1288.57	182.546
1291.59	184.531
1294.6	171.516
1297.62	164.5
1300.63	195.485
1303.64	191.469
1306.66	194.454
1309.67	197.438
1312.67	192.423
1315.68	202.408
1318.69	197.392
1321.7	205.377
1324.7	192.361
1327.71	213.346
1330.71	186.33
1333.71	211.315
1336.72	188.299
1339.72	188.284
1342.72	231.269
1345.71	177.253
1348.71	205.238
1351.71	199.222
1354.71	191.207
1357.7	182.191
1360.69	203.176
1363.69	193.161
1366.68	202.145
1369.67	208.13
1372.66	203.114
1375.65	183.099
1378.64	203.083
1381.62	213.068
1384.61	192.053
1387.59	177.037
1390.58	187.022
1393.56	200.006
1396.54	188.991
1399.53	201.975
1402.5	195.96
1405.48	183.944
1408.46	211.929
1411.44	223.914
1414.41	220.898
1417.39	202.883
1420.36	194.867
1423.34	182.852
1426.31	187.836
1429.28	218.821
1432.25	206.806
1435.22	216.79
1438.19	208.775
1441.16	215.759
1444.13	219.744
1447.09	213.728
1450.05	221.713
1453.02	217.697
1455.98	224.682
1458.94	222.667
1461.91	239.651
1464.86	240.636
1467.82	212.62
1470.78	236.605
1473.74	221.589
1476.69	219.574
1479.65	225.559
1482.6	217.543
1485.56	207.528
1488.51	223.512
1491.46	223.497
1494.41	214.481
1497.36	217.466
1500.31	231.451
1503.25	237.435
1506.2	222.42
1509.15	210.404
1512.09	235.389
1515.04	238.373
1517.98	227.358
1520.92	224.342
1523.86	231.327
1526.8	205.312
1529.74	225.296
1532.67	215.281
1535.61	226.265
1538.55	240.25
1541.48	223.234
1544.42	222.219
1547.35	220.204
1550.28	220.188
1553.21	206.173
1556.14	242.157
1559.07	223.142
1562	213.126
1564.93	237.111
1567.85	232.096
1570.78	237.08
1573.7	244.065
1576.63	247.049
1579.55	286.034
1582.47	268.018
1585.39	262.003
1588.31	247.988
1591.23	259.972
1594.15	281.957
1597.07	270.941
1599.98	293.926
1602.9	261.91
1605.81	253.895
1608.72	278.879
1611.64	254.864
1614.55	265.849
1617.46	252.833
1620.37	271.818
1623.28	288.802
1626.18	251.787
1629.09	260.771
1632	276.756
1634.9	293.741
1637.8	260.725
1640.71	267.71
1643.61	269.694
1646.51	275.679
1649.41	276.663
1652.31	273.648
1655.21	257.633
1658.1	299.617
1661	287.602
1663.9	275.586
1666.79	250.571
1669.68	264.555
1672.58	284.54
1675.47	279.524
1678.36	243.509
1681.25	218.494
1684.14	250.478
1687.02	270.463
1689.91	225.447
1692.8	214.432
1695.68	245.416
1698.57	238.401
1701.45	251.386
1704.33	231.37
1707.21	224.355
1710.1	236.339
1712.97	224.324
1715.85	218.308
1718.73	252.293
1721.61	226.278
1724.48	219.262
1727.36	224.247
1730.23	226.231
1733.1	212.216
1735.98	227.2
1738.85	221.185
1741.72	211.169
1744.59	223.154
1747.46	228.139
1750.32	224.123
1753.19	226.108
1756.06	234.092
1758.92	219.077
1761.78	241.061
1764.65	235.046
1767.51	223.031
1770.37	210.015
1773.23	229
1776.09	228.984
1778.95	214.969
1781.81	203.953
1784.66	238.938
1787.52	233.923
1790.37	224.907
1793.23	226.892
1796.08	222.876
1798.93	236.861
1801.78	226.845
1804.63	204.83
1807.48	213.814
1810.33	219.799
1813.18	194.784
1816.02	229.768
1818.87	222.753
1821.71	228.737
1824.56	240.722
1827.4	184.706
1830.24	214.691
1833.08	218.676
1835.92	225.66
1838.76	222.645
1841.6	202.629
1844.44	208.614
1847.28	225.598
1850.11	224.583
1852.95	200.568
1855.78	208.552
1858.61	213.537
1861.44	221.521
1864.27	236.506
1867.11	226.49
1869.93	231.475
1872.76	220.459
1875.59	250.444
1878.42	204.429
1881.24	218.413
1884.07	211.398
1886.89	215.382
1889.71	204.367
1892.54	219.351
1895.36	232.336
1898.18	226.321
1901	217.305
1903.82	218.29
1906.63	236.274
1909.45	223.259
1912.26	208.243
1915.08	220.228
1917.89	197.213
1920.71	225.197
1923.52	224.182
1926.33	215.166
1929.14	234.151
1931.95	234.135
1934.76	228.12
1937.57	257.104
1940.37	227.089
1943.18	224.074
1945.98	246.058
1948.79	231.043
1951.59	226.027
1954.39	224.012
1957.19	230.996
1960	244.981
1962.8	244.966
1965.59	243.95
1968.39	219.935
1971.19	254.919
1973.99	230.904
1976.78	232.888
1979.57	222.873
1982.37	226.858
1985.16	249.842
1987.95	228.827
1990.74	249.811
1993.53	255.672
1996.32	265.958
1999.11	246.193
2001.9	219.025
2004.68	241.71
2007.47	239.062
2010.25	237.922
2013.04	231.54
2015.82	251.505
2018.6	254.563
2021.38	255.158
2024.16	226.908
2026.94	226.073
2029.72	245.686
2032.5	229.117
2035.28	238.154
2038.05	246.466
2040.83	254.513
2043.6	245.183
2046.37	229.287
2049.15	240.575
2051.92	241.175
2054.69	257.303
2057.46	241.349
2060.23	244.314
2062.99	257.788
2065.76	249.054
2068.53	235.914
2071.29	246.615
2074.06	257.361
2076.82	250.799
2079.58	253.297
2082.34	249.338
2085.11	231.343
2087.87	218.583
2089.72	249.217
2092.49	260.207
2095.26	245.196
2098.03	270.186
2100.8	258.176
2103.56	256.165
2106.33	248.155
2109.1	257.144
2111.86	237.134
2114.63	260.123
2117.39	261.113
2120.15	235.103
2122.92	240.092
2125.68	247.082
2128.44	240.071
2131.2	236.061
2133.95	246.05
2136.71	251.04
2139.47	252.03
2142.22	252.019
2144.98	236.009
2147.73	235.998
2150.49	254.988
2153.24	239.977
2155.99	234.967
2158.74	243.957
2161.49	249.946
2164.24	237.936
2166.99	237.925
2169.73	241.915
2172.48	262.904
2175.23	252.894
2177.97	243.884
2180.71	255.873
2183.46	242.863
2186.2	233.852
2188.94	261.842
2191.68	251.831
2194.42	234.821
2197.16	262.811
2199.9	240.8
2202.63	235.79
2205.37	258.779
2208.1	243.769
2210.84	254.758
2213.57	255.748
2216.31	243.737
2219.04	255.727
2221.77	241.717
2224.5	266.706
2227.23	252.696
2229.96	251.685
2232.68	261.675
2235.41	287.664
2238.14	233.654
2240.86	244.644
2243.59	249.633
2246.31	243.623
2249.03	229.612
2251.75	249.602
2254.47	254.591
2257.19	289.581
2259.91	264.571
2262.63	234.56
2265.35	236.55
2268.07	264.539
2270.78	251.529
2273.5	235.518
2276.21	238.508
2278.92	249.498
2281.64	235.487
2284.35	249.477
2287.06	248.466
2289.77	230.456
2292.48	263.445
2295.18	251.435
2297.89	269.425
2300.6	261.414
2303.3	246.404
2306.01	239.393
2308.71	250.383
2311.42	255.372
2314.12	267.362
2316.82	265.352
2319.52	270.341
2322.22	261.331
2324.92	258.32
2327.62	253.31
2330.31	242.299
2333.01	248.289
2335.71	242.278
2338.4	257.268
2341.1	251.258
2343.79	240.247
2346.48	262.237
2349.17	273.226
2351.86	257.216
2354.55	252.205
2357.24	252.195
2359.93	262.185
2362.62	271.174
2365.3	250.164
2367.99	264.153
2370.67	241.143
2373.36	285.132
2376.04	258.122
2378.72	217.112
2381.41	272.101
2384.09	243.091
2386.77	231.08
2389.44	237.07
2392.12	265.059
2394.8	239.049
2397.48	258.039
2400.15	266.028
2402.83	258.018
2405.5	249.007
2408.17	230.997
2410.85	242.986
2413.52	248.976
2416.19	259.966
2418.86	257.955
2421.53	257.945
2424.2	245.934
2426.86	248.924
2429.53	267.913
2432.2	238.903
2434.86	248.893
2437.53	253.882
2440.19	259.872
2442.85	234.861
2445.51	243.851
2448.18	230.84
2450.83	222.83
2453.49	224.819
2456.15	247.809
2458.81	252.799
2461.47	273.788
2464.12	231.778
2466.78	238.767
2469.43	251.757
2472.09	243.746
2474.74	264.736
2477.39	225.726
2480.04	246.715
2482.69	253.705
2485.34	248.694
2487.99	238.684
2490.64	259.673
2493.28	246.663
2495.93	256.653
2498.58	241.642
2501.22	250.632
2503.87	237.621
2506.51	247.611
2509.15	261.6
2511.79	249.59
2514.43	229.58
2517.07	263.569
2519.71	276.559
2522.35	208.548
2524.99	262.538
2527.62	257.527
2530.26	250.517
2532.89	254.507
2535.53	234.496
2538.16	231.486
2540.79	248.475
2543.43	224.465
2546.06	268.454
2548.69	266.444
2551.31	258.434
2553.94	227.423
2556.57	269.413
2559.2	229.402
2561.82	273.392
2564.45	236.381
2567.07	245.371
2569.7	246.36
2572.32	259.35
2574.94	244.34
2577.56	238.329
2580.18	220.319
2582.8	247.308
2585.42	254.298
2588.04	272.287
2590.66	240.277
2593.27	249.267
2595.89	256.256
2598.5	242.246
2601.12	237.235
2603.73	232.225
2606.34	271.214
2608.96	242.204
2611.57	244.194
2614.18	236.183
2616.79	242.173
2619.39	248.162
2622	233.152
2624.61	241.141
2627.21	248.131
2629.82	236.121
2632.42	253.11
2635.03	265.1
2637.63	235.089
2640.23	228.079
2642.83	234.068
2645.43	229.058
2648.03	256.048
2650.63	253.037
2653.23	234.027
2655.83	234.016
2658.42	233.006
2661.02	253.995
2663.62	254.985
2666.21	266.975
2668.8	227.964
2671.4	244.954
2673.99	260.943
2676.58	267.933
2679.17	247.922
2681.76	236.912
2684.35	245.901
2686.93	249.891
2689.52	236.881
2692.11	242.87
2694.69	248.86
2697.28	240.849
2699.86	255.839
2702.44	228.828
2705.03	258.818
2707.61	243.808
2710.19	257.797
2712.77	239.787
2715.35	264.776
2717.93	230.766
2720.5	247.755
2723.08	230.745
2725.66	237.735
2728.23	259.724
2730.81	254.714
2733.38	237.703
2735.96	229.693
2738.53	271.682
2741.1	253.672
2743.67	231.662
2746.24	237.651
2748.81	238.641
2751.38	248.63
2753.94	261.62
2756.51	260.609
2759.08	249.599
2761.64	253.589
2764.2	222.578
2766.77	215.568
2769.33	236.557
2771.89	242.547
2774.46	237.536
2777.01	229.526
2779.58	249.516
2782.13	236.505
2784.69	254.495
2787.25	256.484
2789.81	238.474
2792.36	241.463
2794.92	241.453
2797.47	223.442
2800.02	270.432
2802.58	240.422
2805.13	250.411
2807.68	254.401
2810.23	244.39
2812.78	252.38
2815.33	243.369
2817.88	237.359
2820.42	226.349
2822.97	221.338
2825.52	239.328
2828.06	252.317
2830.61	230.307
2833.15	224.296
2835.69	231.286
2838.23	247.276
2840.78	239.265
2843.32	243.255
2845.86	261.244
2848.39	242.234
2850.93	228.223
2853.47	228.213
2856.01	242.203
2858.54	244.192
2861.08	226.182
2863.61	250.171
2866.15	276.161
2868.68	245.15
2871.21	237.14
2873.74	240.13
2876.27	246.119
2878.8	231.109
2881.33	278.098
2883.86	265.088
2886.39	265.077
2888.91	257.067
2891.44	264.057
2893.96	261.046
2896.49	247.036
2899.01	241.025
2901.54	258.015
2904.06	278.004
2906.58	260.994
2909.1	236.983
2911.62	242.973
2914.14	270.963
2916.66	261.952
2919.18	257.942
2921.69	250.931
2924.21	268.921
2926.72	275.91
2929.24	273.9
2931.75	274.89
2934.26	272.879
2936.78	268.869
2939.29	264.858
2941.8	244.848
2944.31	285.837
2946.82	273.827
2949.33	271.817
2951.83	291.806
2954.34	273.796
2956.85	286.785
2959.35	308.775
2961.86	310.764
2964.36	286.754
2966.86	314.744
2969.37	299.733
2971.87	270.723
2974.37	304.712
2976.87	289.702
2979.37	296.691
2981.87	305.681
2984.37	301.671
2986.86	317.66
2989.36	331.65
2991.86	290.639
2994.35	321.629
2996.85	311.618
2999.34	328.608
3001.83	309.598
3004.32	336.587
3006.81	328.577
3009.31	335.566
3011.8	294.556
3014.29	322.545
3016.77	354.535
3019.26	327.525
3021.75	323.514
3024.23	334.504
3026.72	341.493
3029.2	365.483
3031.69	365.472
3034.17	360.462
3036.65	362.451
3039.13	370.441
3041.62	387.431
3044.09	396.42
3046.58	384.41
3049.05	376.399
3051.53	390.389
3054.01	384.378
3056.48	421.368
3058.96	413.358
3061.44	418.347
3063.91	443.337
3066.38	443.326
3068.86	434.316
3071.33	425.305
3073.8	433.295
3076.27	481.285
3078.74	486.274
3081.21	460.264
3083.68	457.253
3086.14	523.243
3088.61	473.232
3091.08	513.222
3093.54	521.212
3096.01	510.201
3098.47	511.191
3100.93	562.18
3103.4	532.17
3105.86	583.159
3108.32	561.149
3110.78	557.139
3113.24	592.128
3115.7	606.118
3118.15	621.107
3120.61	603.097
3123.07	648.086
3125.53	629.076
3127.98	651.065
3130.43	656.055
3132.89	677.045
3135.34	695.034
3137.79	714.024
3140.24	708.013
3142.69	738.003
3145.15	738.992
3147.59	768.982
3150.04	749.972
3152.49	781.961
3154.94	778.951
3157.38	827.94
3159.83	775.93
3162.27	798.919
3164.72	837.909
3167.16	851.899
3169.61	847.888
3172.05	892.878
3174.49	868.867
3176.93	876.857
3179.37	893.846
3181.81	913.836
3184.25	875.826
3186.68	942.815
3189.12	931.805
3191.56	929.794
3193.99	975.784
3196.43	993.773
3198.86	976.763
3201.29	1018.75
3203.73	1017.74
3206.16	1041.73
3208.59	1043.72
3211.02	1038.71
3213.45	1038.7
3215.88	1034.69
3218.31	1059.68
3220.73	1051.67
3223.16	1065.66
3225.59	1044.65
3228.01	1127.64
3230.44	1085.63
3232.86	1077.62
3235.28	1089.61
3237.71	1086.6
3240.13	1122.59
3242.55	1108.58
3244.97	1101.56
3247.39	1095.55
3249.81	1125.54
3252.23	1147.53
3254.64	1095.52
3257.06	1058.51
3259.48	1114.5
3261.89	1086.49
3264.31	1119.48
3266.72	1146.47
3269.14	1113.46
3271.55	1137.45
3273.96	1128.44
3276.37	1114.43
3278.78	1100.42
3281.19	1135.41
3283.6	1141.4
3286.01	1142.39
3288.41	1142.38
3290.82	1168.37
3293.23	1104.36
3295.63	1153.35
3298.04	1124.34
3300.44	1141.32
3302.84	1166.31
3305.25	1196.3
3307.65	1182.29
3310.05	1242.28
3312.45	1172.27
3314.85	1187.26
3317.25	1174.25
3319.65	1194.24
3322.04	1236.23
3324.44	1185.22
3326.84	1218.21
3329.23	1167.2
3331.63	1229.19
3334.02	1194.18
3336.42	1271.17
3338.81	1202.16
3341.2	1214.15
3343.59	1201.14
3345.98	1238.13
3348.37	1264.12
3350.76	1264.11
3353.15	1223.1
3355.54	1317.08
3357.92	1280.07
3360.31	1314.06
3362.7	1246.05
3365.08	1282.04
3367.46	1348.03
3369.85	1306.02
3372.23	1279.01
3374.61	1307
3376.99	1297.99
3379.38	1341.98
3381.75	1348.97
3384.13	1348.96
3386.51	1285.95
3388.89	1299.94
3391.27	1376.93
3393.64	1316.92
3396.02	1319.91
3398.4	1298.9
3400.77	1292.89
3403.14	1318.88
3405.52	1330.87
3407.89	1299.86
3410.26	1326.84
3412.63	1301.83
3415	1314.82
3417.37	1301.81
3419.74	1255.8
3422.11	1264.79
3424.48	1349.78
3426.84	1294.77
3429.21	1221.76
3431.57	1287.75
3433.94	1249.74
3436.3	1254.73
3438.67	1205.72
3441.03	1247.71
3443.39	1245.7
3445.75	1268.69
3448.11	1221.68
3450.47	1263.67
3452.83	1229.66
3455.19	1234.65
3457.55	1199.64
3459.9	1240.63
3462.26	1223.62
3464.62	1160.61
3466.97	1175.59
3469.33	1167.58
3471.68	1187.57
3474.03	1228.56
3476.38	1162.55
3478.74	1148.54
3481.09	1141.53
3483.44	1176.52
3485.79	1078.51
3488.14	1115.5
3490.48	1092.49
3492.83	1076.48
3495.18	1088.47
3497.52	1087.46
3499.87	1061.45
3502.21	1080.44
3504.56	1093.43
3506.9	1050.42
3509.24	1007.41
3511.59	971.396
3513.93	1002.39
3516.27	955.376
3518.61	967.365
3520.95	970.355
3523.29	924.344
3525.62	914.334
3527.96	887.323
3530.3	880.313
3532.63	845.303
3534.97	894.292
3537.3	850.282
3539.64	867.271
3541.97	828.261
3544.3	846.25
3546.63	840.24
3548.96	820.229
3551.29	855.219
3553.62	814.209
3555.95	779.198
3558.28	770.188
3560.61	787.177
3562.94	725.167
3565.26	757.156
3567.59	706.146
3569.91	717.136
3572.24	698.125
3574.56	715.115
3576.88	662.104
3579.21	659.094
3581.53	662.083
3583.85	645.073
3586.17	660.063
3588.49	659.052
3590.81	635.042
3593.13	600.031
3595.44	628.021
3597.76	617.01
3599.3	614.003