File: DUV Raman/_13_58_13_2021_04_15_Gro Fine_3_120 s_229 nm_1800 (500nm)_X40_UVB_150_100%_01.txt
#Acq. time (s)=	120
#Accumulations=	3
#Range=	Off
#Autofocus=	Off
#Macrospot=	Off
#AutoExposure=	Off
#Spike filter=	Multiple accum.
#Delay time (s)=	0
#Binning=	1
#Readout mode=	Signal-Dark
#DeNoise=	Off
#ICS correction=	Off
#Dark correction=	Off
#Inst. Process=	Off
#Detector temperature (°C)=	-75.13
#Instrument=	LabRAM HR Evol
#Detector=	Synapse
#Objective=	X40_UVB
#Grating=	1800 (500nm)
#ND Filter=	100%
#Laser (nm)=	229
#Spectro (cm-¹)=	2350.07
#Hole=	150.001
#Range=	UV
#StageXY=	Marzhauser
#StageZ=	Marzhauser
#X (µm)=	0
#Y (µm)=	0
#Z (µm)=	0
#Full time(mm:ss)=	8:02
#Project=	2021-4-15_Andrew_fertilizer_DUV
#Sample=
#Site=
#Title=	_13_50_11_2021_04_15_Gro Fine_3_120 s_229 nm_1800 (500nm)_X40_UVB_150_100%
#Remark=
#Date=	15.04.2021 13:54
#Acquired=	15.04.2021 13:54:13
727.454	22
730.763	31.5
734.071	30
737.376	40
740.683	42
743.989	47
747.295	36
750.6	48
753.905	43
757.21	55.5
760.511	50
763.814	48.5
767.117	60.5
770.42	59
773.721	61
777.02	49
780.321	76.5
783.621	68
786.921	56.5
790.218	67
793.517	83.5
796.815	79
800.113	60.5
803.407	66
806.704	69.5
810	61
813.293	67
816.589	52
819.881	78.5
823.175	66
826.469	73
829.759	75.5
833.052	47
836.341	69
839.633	56
842.924	60
846.212	51
849.502	66
852.789	55
856.079	74.5
859.365	65.5
862.653	64
865.938	58
869.225	59
872.509	43
875.792	62
879.078	45
882.36	59
885.645	64.5
888.926	48.5
892.207	49
895.49	56
898.77	63.5
902.05	66
905.331	56
908.61	65.5
911.887	61
915.168	63
918.444	56.5
921.721	51.5
924.999	58.5
928.275	66
931.55	55.5
934.824	60
938.098	89
941.374	61
944.647	94.5
947.919	90.5
951.191	66
954.462	81
957.736	91
961.006	103
964.276	105
967.545	119
970.814	153
974.083	190.5
977.35	215
980.618	266.5
983.884	360
987.151	511
990.417	707
993.682	973
996.947	1224
1000.21	1409
1003.47	1498.5
1006.74	1269
1010	1070
1013.26	797
1016.53	569.5
1019.79	387.5
1023.05	297
1026.31	230
1029.57	162
1032.83	146
1036.09	135
1039.34	122
1042.6	95
1045.86	121.5
1049.11	108.5
1052.37	92
1055.63	102
1058.88	102
1062.13	95.5
1065.39	83.5
1068.64	78
1071.89	82.5
1075.14	90.5
1078.4	74
1081.65	80.5
1084.9	63
1088.15	94.5
1091.4	84
1094.65	105
1097.9	100
1101.14	103
1104.39	86
1107.64	75
1110.89	92.5
1114.13	112
1117.38	108
1120.62	120
1123.86	104
1127.11	132
1130.35	123.5
1133.6	147.5
1136.84	126
1140.08	176
1143.32	175
1146.56	216
1149.8	210
1153.04	244
1156.28	232
1159.52	221.5
1162.75	191
1165.99	189
1169.23	195
1172.46	165
1175.7	153
1178.94	119
1182.17	109
1185.4	94
1188.64	71.5
1191.87	76
1195.1	65
1198.34	77
1201.57	54.5
1204.8	51.5
1208.03	59
1211.26	45
1214.49	48
1217.72	56
1220.95	53
1224.18	47
1227.4	49
1230.63	46
1233.86	49
1237.08	30
1240.31	59
1243.53	50
1246.76	46.5
1249.98	43.5
1253.2	46.5
1256.43	50
1259.65	52.5
1262.87	45.5
1266.09	49.5
1269.31	57.5
1272.53	45
1275.75	40.5
1278.97	50
1282.19	53
1285.41	57
1288.62	53.5
1291.84	65.5
1295.06	61.5
1298.27	61
1301.49	50
1304.7	66.5
1307.92	54
1311.13	57
1314.35	54
1317.56	75.5
1320.77	50
1323.98	55
1327.19	76
1330.41	65
1333.61	70
1336.82	68
1340.03	60.5
1343.24	68
1346.45	85
1349.66	72
1352.87	94
1356.07	86
1359.28	81
1362.48	72
1365.69	79
1368.89	93
1372.1	94.5
1375.3	94
1378.5	98
1381.71	101
1384.91	104
1388.11	116
1391.31	102
1394.51	131.5
1397.71	108
1400.91	108.2
1404.11	114.6
1407.31	111
1410.5	98.9
1413.7	101.8
1416.9	102.5
1420.1	93
1423.29	109
1426.48	89.5
1429.68	108.5
1432.87	100
1436.07	115
1439.26	118
1442.46	129.5
1445.65	128
1448.84	167
1452.03	172.5
1455.22	181
1458.41	158
1461.6	229
1464.79	196
1467.98	196.5
1471.17	219
1474.35	198
1477.54	210
1480.72	199.5
1483.91	170
1487.1	144
1490.28	150
1493.47	142
1496.65	157
1499.83	139
1503.02	128
1506.2	123
1509.38	134.5
1512.56	121
1515.74	126
1518.92	138
1522.1	141
1525.28	133
1528.46	135
1531.64	134
1534.82	155.5
1537.99	135.5
1541.17	152.5
1544.35	158
1547.52	170
1550.7	177.5
1553.87	185
1557.05	213.5
1560.22	208
1563.39	236.5
1566.56	240.5
1569.74	257.5
1572.91	273
1576.08	269
1579.25	315
1582.42	334
1585.59	339
1588.76	370
1591.93	393.5
1595.1	429
1598.26	416
1601.43	386
1604.6	373
1607.76	339
1610.93	340
1614.09	296
1617.26	305
1620.42	263
1623.59	261.5
1626.75	260.5
1629.91	256
1633.07	271.5
1636.24	244.5
1639.39	256
1642.56	272
1645.72	259
1648.87	271
1652.03	299
1655.19	300.5
1658.35	310.5
1661.51	312
1664.66	333.5
1667.82	326
1670.98	313
1674.13	298
1677.29	314
1680.44	262
1683.59	256
1686.75	225.5
1689.9	206
1693.05	182
1696.21	148
1699.36	148
1702.51	133
1705.66	119
1708.81	112
1711.96	94
1715.1	99.5
1718.25	91.5
1721.4	80
1724.55	83
1727.69	75
1730.84	70
1733.99	77.5
1737.13	69
1740.28	62
1743.42	49
1746.56	62
1749.71	51.5
1752.85	50
1755.99	50.5
1759.14	38
1762.28	33
1765.42	33
1768.56	47
1771.7	25
1774.83	46
1777.97	37.5
1781.11	26
1784.25	36
1787.38	36.5
1790.52	39
1793.66	45
1796.8	37.5
1799.93	37.5
1803.07	28
1806.2	42.5
1809.33	45
1812.47	35
1815.6	30
1818.73	32.5
1821.86	28
1824.99	29
1828.12	23
1831.25	26
1834.38	30.5
1837.51	25
1840.64	15
1843.77	34
1846.9	31.5
1850.02	37
1853.15	36
1856.28	40
1859.4	32.5
1862.53	30.5
1865.65	35
1868.78	33.5
1871.9	44
1875.02	36
1878.14	30
1881.26	39
1884.39	27
1887.51	30
1890.63	20.5
1893.75	19
1896.87	25.5
1899.99	19
1903.11	29
1906.22	27.5
1909.34	20
1912.46	27.5
1915.58	31
1918.69	26
1921.81	32
1924.92	29
1928.04	36.5
1931.15	33
1934.26	37.5
1937.38	27
1940.49	20
1943.6	19
1946.71	34
1949.82	33
1952.94	33
1956.05	32
1959.15	40.5
1962.27	33
1965.37	39
1968.48	31.5
1971.59	24
1974.7	41
1977.8	22
1980.91	29
1984.01	23
1987.12	28
1990.22	34.5
1993.33	37.5
1996.43	33
1999.53	41.5
2002.64	49
2005.74	31
2008.84	56
2011.94	45.5
2015.04	54
2018.14	36
2021.24	38
2024.34	37
2027.44	42.5
2030.54	41.5
2033.64	55
2036.73	45.5
2039.83	39
2042.93	46.5
2046.02	52
2049.12	56
2052.21	50.5
2055.31	41
2058.4	50.5
2061.49	39
2064.59	38.5
2067.68	43
2070.77	39.5
2073.86	38
2076.95	34
2080.04	57
2083.13	46
2086.22	41
2089.31	34.5
2092.4	37
2095.49	42
2098.57	44
2101.66	40
2104.75	38.5
2107.83	22
2110.92	37.5
2114	37
2117.09	31
2120.17	35.5
2123.26	33
2126.34	49.5
2129.42	46.5
2132.5	38
2135.58	36
2138.67	39
2141.75	41
2144.82	45
2147.91	32.5
2150.98	34.5
2154.06	39
2157.14	36.5
2160.22	49.5
2163.29	47
2166.37	50.5
2169.45	34
2172.52	36
2175.6	49
2178.67	50
2181.75	49
2184.82	43
2187.89	45.5
2190.97	42
2194.04	50.5
2197.11	34.5
2200.18	27.5
2203.25	42
2206.32	41
2209.39	34.5
2212.46	36
2215.53	40.5
2218.6	49
2221.67	45
2224.73	33
2227.8	43
2230.87	44.5
2233.93	44
2237	28
2240.06	33
2243.12	40
2246.19	36.5
2249.25	33.5
2252.32	42.5
2255.38	39
2258.44	26
2261.5	40.5
2264.56	27
2267.62	34
2270.68	36
2273.74	42
2276.8	29
2279.86	39.5
2282.92	28
2285.98	28
2289.03	33
2292.09	35
2295.15	39.5
2298.2	26
2301.25	40.5
2304.31	37.5
2307.36	33
2310.42	15
2313.47	42
2316.52	30
2319.58	30.5
2322.63	16
2325.68	23.5
2328.73	36.5
2331.78	42.5
2334.83	25.5
2337.88	33.5
2340.93	40.5
2343.97	28
2347.02	27
2350.07	38.5
2353.12	30
2356.16	30
2359.21	30
2362.25	26.5
2365.3	40
2368.34	21
2371.39	41
2374.43	34.5
2377.47	36
2380.52	28
2383.56	25.5
2386.6	26.5
2389.64	30
2392.68	34
2395.72	27.5
2398.76	18
2401.8	16
2404.84	36
2407.88	29.5
2410.91	26.5
2413.95	23.5
2416.99	19
2420.02	25
2423.06	30
2426.09	24
2429.13	23
2432.16	35.5
2435.2	26.6
2438.23	25.2
2441.26	25.8
2444.3	16.4
2447.33	22
2450.36	20
2453.39	28
2456.42	35.5
2459.45	25
2462.48	25.5
2465.51	28.5
2468.54	28.5
2471.57	32.5
2474.59	28
2477.62	31.5
2480.65	23
2483.67	36
2486.7	29.5
2489.72	24
2492.75	31.5
2495.77	25
2498.8	27.5
2501.82	28.5
2504.84	31
2507.86	19.5
2510.89	15.5
2513.91	22
2516.93	26
2519.95	28
2522.97	26
2525.99	30
2529.01	20
2532.03	25
2535.04	37
2538.06	23
2541.08	34
2544.09	36.5
2547.11	23
2550.13	36
2553.14	28
2556.16	22.5
2559.17	30
2562.18	24
2565.2	24.5
2568.21	27
2571.22	28.5
2574.23	23.5
2577.25	32
2580.26	34
2583.27	22
2586.28	15
2589.29	29
2592.29	28
2595.3	33
2598.31	31.5
2601.32	29.5
2604.33	26
2607.33	40.5
2610.34	28.5
2613.34	23
2616.35	22
2619.35	35
2622.36	30
2625.36	21.5
2628.36	14
2631.37	24
2634.37	39.5
2637.37	34
2640.37	31
2643.38	39
2646.37	21
2649.37	19
2652.37	35
2655.37	33.5
2658.37	36.5
2661.37	35
2664.37	25
2667.36	30.5
2670.36	35.5
2673.36	40
2676.35	35
2679.35	45
2682.34	37
2685.34	40
2688.33	43
2691.32	36
2694.32	27.5
2697.31	45
2700.3	40.5
2703.29	36
2706.28	34
2709.27	26
2712.26	40.5
2715.25	46
2718.24	35
2721.23	44
2724.22	28
2727.21	29
2730.19	39
2733.18	36
2736.17	40.5
2739.15	40
2742.14	33
2745.12	34
2748.11	47
2751.09	34.5
2754.07	56
2757.06	41
2760.04	44
2763.02	49.5
2766	42
2768.98	44
2771.96	54.5
2774.94	36.5
2777.92	63.5
2780.9	44
2783.88	48
2786.86	49.5
2789.84	28
2792.81	44.5
2795.79	49.5
2798.77	41
2801.74	42.5
2804.72	39
2807.69	44
2810.67	39
2813.64	46
2816.62	49
2819.59	51
2822.56	55
2825.53	57
2828.5	52
2831.48	50
2834.45	55
2837.42	56
2840.39	56
2843.36	53
2846.32	61.5
2849.29	61
2852.26	57
2855.23	61
2858.2	75
2861.16	71
2864.13	63
2867.09	63.5
2870.06	63
2873.02	68
2875.99	69
2878.95	62.5
2881.91	75
2884.88	63
2887.84	88
2890.8	82
2893.76	86
2896.73	83
2899.69	74
2902.65	88.5
2905.6	90.5
2908.56	99
2911.52	111
2914.48	86
2917.44	103.5
2920.4	97
2923.35	109.5
2926.31	99
2929.27	70
2932.22	109.5
2935.18	105.5
2938.13	108
2941.08	120.5
2944.04	110.5
2946.99	115
2949.94	124
2952.89	138
2955.85	146
2958.8	153.5
2961.75	148
2964.7	144
2967.65	142.5
2970.6	171
2973.54	152.5
2976.49	159
2979.44	162
2982.39	156
2985.34	179.5
2988.28	181.5
2991.23	167
2994.17	190
2997.12	206
3000.07	200
3003.01	205
3005.95	220
3008.9	227.5
3011.84	224
3014.78	217
3017.72	234
3020.67	247
3023.6	245
3026.55	263
3029.49	260
3032.43	278.5
3035.37	271
3038.31	301.5
3041.24	305
3044.18	310.5
3047.12	310
3050.06	311
3052.99	342
3055.93	351
3058.86	323
3061.8	397
3064.73	395
3067.67	372
3070.6	427.5
3073.53	404.5
3076.47	425
3079.4	416
3082.33	414
3085.26	464
3088.19	474.5
3091.12	490.5
3094.05	484
3096.98	465
3099.91	552
3102.84	547.5
3105.77	522
3108.69	553
3111.62	590.5
3114.55	627.5
3117.48	626
3120.4	630
3123.33	649
3126.25	711
3129.18	695
3132.1	688
3135.02	724
3137.95	748
3140.87	756
3143.79	820
3146.71	827
3149.63	810
3152.56	860
3155.48	885
3158.4	900
3161.31	915
3164.23	989
3167.15	959
3170.07	1022.5
3172.99	1010
3175.91	1051
3178.82	1088.5
3181.74	1036
3184.66	1102
3187.57	1137
3190.48	1139
3193.4	1179
3196.31	1142.5
3199.23	1227
3202.14	1266
3205.05	1225
3207.96	1277
3210.88	1252
3213.79	1238
3216.7	1287
3219.61	1300
3222.52	1317
3225.43	1324
3228.34	1354
3231.25	1364
3234.15	1382
3237.06	1400
3239.97	1364
3242.88	1390
3245.78	1446
3248.69	1382.5
3251.59	1366
3254.5	1386.5
3257.4	1411
3260.31	1434
3263.21	1373
3266.11	1395
3269.02	1364.5
3271.92	1393
3274.82	1339
3277.72	1435.5
3280.62	1426
3283.52	1430
3286.42	1442
3289.32	1411
3292.22	1497
3295.12	1473
3298.02	1467
3300.91	1492
3303.81	1521
3306.71	1447
3309.61	1529.5
3312.5	1486
3315.4	1500
3318.29	1517.5
3321.18	1531
3324.08	1623
3326.97	1564.5
3329.87	1486
3332.76	1582.5
3335.65	1571.5
3338.54	1588
3341.43	1636
3344.32	1601
3347.21	1710.5
3350.11	1652.5
3353	1624
3355.88	1670
3358.77	1718.5
3361.66	1691.5
3364.55	1682
3367.44	1693
3370.32	1748
3373.21	1766.5
3376.09	1732.5
3378.98	1804.5
3381.86	1769.5
3384.75	1763.5
3387.63	1707
3390.52	1733.5
3393.4	1754
3396.28	1761
3399.17	1767
3402.05	1787
3404.93	1671
3407.81	1692
3410.69	1674.5
3413.57	1685
3416.45	1628
3419.33	1593
3422.21	1623
3425.09	1596.5
3427.96	1638
3430.84	1561.5
3433.72	1556
3436.59	1524
3439.47	1455
3442.35	1578
3445.22	1480
3448.1	1497
3450.97	1563
3453.85	1467.5
3456.72	1410
3459.59	1479
3462.46	1434
3465.34	1443.5
3468.21	1426
3471.08	1391.5
3473.95	1387
3476.82	1372.5
3479.69	1343.5
3482.56	1306
3485.43	1336
3488.3	1321
3491.16	1284
3494.03	1252
3496.9	1211
3499.77	1226
3502.63	1210
3505.5	1156.5
3508.36	1136
3511.23	1178.5
3514.09	1134.5
3516.96	1132
3519.82	1063
3522.68	1093
3525.55	1054.5
3528.41	978
3531.27	1009
3534.13	1019
3536.99	970
3539.85	935.5
3542.71	924.5
3545.57	886
3548.43	886.5
3551.29	901
3554.15	895
3557.01	821
3559.86	849
3562.72	799
3565.58	773
3568.43	733
3571.29	747
3574.14	792.5
3577	732.5
3579.85	720
3582.71	713
3585.56	711
3588.41	649
3591.26	625
3594.12	652
3596.97	675.5
3599.82	597
3602.67	585
3605.52	591
3608.37	589.5
3611.22	597
3614.07	597
3616.92	570
3619.77	557.5
3622.61	498
3625.46	522
3628.31	524.5
3631.15	482
3634	477
3636.84	450.5
3639.69	458
3642.53	439
3645.38	458
3648.22	384
3651.06	391.5
3653.91	389
3656.75	361
3659.59	345
3662.43	335.5
3665.27	280
3668.11	288.5
3670.95	276.5
3673.8	277
3676.63	263.5
3679.47	230
3682.31	221
3685.15	213
3687.99	189.5
3690.82	185
3693.66	168
3696.5	155.5
3699.33	148
3702.17	131
3705	130
3707.84	129
3710.67	103
3713.5	113
3716.34	113
3719.17	96.5
3722	102
3724.83	87
3727.66	96
3730.5	78
3733.33	75.5
3736.16	71.5
3738.99	65
3741.81	70
3744.64	63
3747.47	68
3750.3	63
3753.13	59
3755.95	55
3758.78	56.5
3761.61	56
3764.43	53.5
3767.26	51
3770.08	46
3772.91	41
3775.73	40
3778.55	49
3781.38	43
3784.2	45.5
3787.02	43
3789.84	46.5
3792.67	35
3795.49	33
3798.31	34
3801.13	50.5
3803.95	39
3806.76	43
3809.58	30
3812.4	38.5
3815.22	47
3818.04	46
3820.85	29
3823.67	31
3826.49	30
3829.3	31
3832.12	37
3834.93	18
3837.75	38
3840.56	41
3843.37	31
3846.19	39
3849	34
3850.41	26