File: DUV Raman/_13_20_52_2021_04_15_Gro Fine_2_60 s_229 nm_1800 (500nm)_X40_UVB_150_100%_01.txt
#Acq. time (s)=	60
#Accumulations=	2
#Range=	Off
#Autofocus=	Off
#Macrospot=	Off
#AutoExposure=	Off
#Spike filter=	Multiple accum.
#Delay time (s)=	0
#Binning=	1
#Readout mode=	Signal
#DeNoise=	Off
#ICS correction=	Off
#Dark correction=	Off
#Inst. Process=	Off
#Detector temperature (°C)=	-74.9
#Instrument=	LabRAM HR Evol
#Detector=	Synapse
#Objective=	X40_UVB
#Grating=	1800 (500nm)
#ND Filter=	100%
#Laser (nm)=	229
#Spectro (cm-¹)=	2350.07
#Hole=	150.001
#Range=	UV
#StageXY=	Marzhauser
#StageZ=	Marzhauser
#X (µm)=	0
#Y (µm)=	0
#Z (µm)=	0
#Full time(mm:ss)=	2:12
#Project=	2021-4-15_Andrew_fertilizer_DUV
#Sample=
#Site=
#Title=	_13_18_50_2021_04_15_Gro Fine_2_60 s_229 nm_1800 (500nm)_X40_UVB_150_100%
#Remark=
#Date=	15.04.2021 13:19
#Acquired=	15.04.2021 13:19:52
#Base:Fit=	15.04.2021 13:30:11
#Base:Sub=	15.04.2021 13:30:12
#Peaks:Edit=	15.04.2021 13:30:14
#Peaks:Fit=	15.04.2021 13:30:17
#Peaks:Fit=	15.04.2021 13:30:17
727.454	-3.52861
730.763	13.4714
734.071	4.47139
737.376	12.4714
740.683	8.47139
743.989	4.47139
747.295	11.4714
750.6	14.4714
753.905	18.4714
757.21	14.4714
760.511	4.47139
763.814	18.4714
767.117	19.4714
770.42	15.4714
773.721	19.4714
777.02	24.4714
780.321	15.4714
783.621	15.4714
786.921	16.4714
790.218	31.4714
793.517	18.4714
796.815	17.4714
800.113	21.4714
803.407	21.4714
806.704	17.4714
810	20.4714
813.293	12.4714
816.589	20.4714
819.881	17.4714
823.175	25.4714
826.469	13.4714
829.759	14.4714
833.052	16.4714
836.341	26.4714
839.633	22.4714
842.924	24.4714
846.212	20.4714
849.502	15.4714
852.789	15.4714
856.079	31.4714
859.365	10.4714
862.653	14.4714
865.938	19.4714
869.225	19.4714
872.509	6.47139
875.792	11.4714
879.078	15.4714
882.36	12.4714
885.645	20.4714
888.926	21.4714
892.207	21.4714
895.49	15.4714
898.77	18.4714
902.05	19.4714
905.331	11.4714
908.61	13.4714
911.887	12.4714
915.168	16.4714
918.444	17.4714
921.721	12.4714
924.999	2.47139
928.275	7.47139
931.55	29.4714
934.824	22.4714
938.098	13.4714
941.374	19.4714
944.647	23.4714
947.919	20.4714
951.191	22.4714
954.462	19.4714
957.736	19.4714
961.006	30.4714
964.276	38.4714
967.545	25.4714
970.814	43.4714
974.083	48.4714
977.35	58.4714
980.618	96.4714
983.884	127.471
987.151	172.471
990.417	247.471
993.682	346.471
996.947	426.471
1000.21	516.471
1003.47	595.471
1006.74	518.471
1010	454.471
1013.26	360.471
1016.53	240.471
1019.79	167.471
1023.05	116.471
1026.31	90.4714
1029.57	74.4714
1032.83	58.4714
1036.09	41.4714
1039.34	34.4714
1042.6	36.4714
1045.86	28.4714
1049.11	38.4714
1052.37	27.4714
1055.63	23.4714
1058.88	21.4714
1062.13	28.4714
1065.39	27.4714
1068.64	25.4714
1071.89	24.4714
1075.14	23.4714
1078.4	20.4714
1081.65	30.4714
1084.9	29.4714
1088.15	30.4714
1091.4	12.4714
1094.65	16.4714
1097.9	21.4714
1101.14	27.4714
1104.39	35.4714
1107.64	21.4714
1110.89	29.4714
1114.13	37.4714
1117.38	23.4714
1120.62	30.4714
1123.86	32.4714
1127.11	50.4714
1130.35	42.4714
1133.6	47.4714
1136.84	49.4714
1140.08	52.4714
1143.32	55.4714
1146.56	80.4714
1149.8	90.4714
1153.04	88.4714
1156.28	83.4714
1159.52	81.4714
1162.75	82.4714
1165.99	73.4714
1169.23	79.4714
1172.46	74.4714
1175.7	41.4714
1178.94	56.4714
1182.17	32.4714
1185.4	21.4714
1188.64	20.4714
1191.87	26.4714
1195.1	15.4714
1198.34	25.4714
1201.57	10.4714
1204.8	17.4714
1208.03	13.4714
1211.26	9.47139
1214.49	19.4714
1217.72	6.47139
1220.95	0.471388
1224.18	11.4714
1227.4	18.4714
1230.63	13.4714
1233.86	5.47139
1237.08	6.47139
1240.31	14.4714
1243.53	10.4714
1246.76	15.4714
1249.98	19.4714
1253.2	8.47139
1256.43	5.47139
1259.65	10.4714
1262.87	11.4714
1266.09	12.4714
1269.31	5.47139
1272.53	17.4714
1275.75	8.47139
1278.97	24.4714
1282.19	9.47139
1285.41	8.47139
1288.62	8.47139
1291.84	9.47139
1295.06	7.47139
1298.27	17.4714
1301.49	4.47139
1304.7	21.4714
1307.92	22.4714
1311.13	23.4714
1314.35	10.4714
1317.56	30.4714
1320.77	30.4714
1323.98	9.47139
1327.19	19.4714
1330.41	24.4714
1333.61	20.4714
1336.82	28.4714
1340.03	25.4714
1343.24	13.4714
1346.45	26.4714
1349.66	33.4714
1352.87	20.4714
1356.07	22.4714
1359.28	23.4714
1362.48	19.4714
1365.69	15.4714
1368.89	17.4714
1372.1	29.4714
1375.3	30.4714
1378.5	30.4714
1381.71	35.4714
1384.91	23.4714
1388.11	30.4714
1391.31	39.4714
1394.51	47.4714
1397.71	44.4714
1400.91	46.4714
1404.11	30.4714
1407.31	40.4714
1410.5	42.4714
1413.7	45.4714
1416.9	47.4714
1420.1	40.4714
1423.29	28.4714
1426.48	40.4714
1429.68	24.4714
1432.87	31.4714
1436.07	32.4714
1439.26	38.4714
1442.46	30.4714
1445.65	45.4714
1448.84	51.4714
1452.03	54.4714
1455.22	62.4714
1458.41	61.4714
1461.6	64.4714
1464.79	71.4714
1467.98	86.4714
1471.17	66.4714
1474.35	60.4714
1477.54	78.4714
1480.72	65.4714
1483.91	57.4714
1487.1	40.4714
1490.28	63.4714
1493.47	52.4714
1496.65	37.4714
1499.83	48.4714
1503.02	40.4714
1506.2	38.4714
1509.38	46.4714
1512.56	56.4714
1515.74	38.4714
1518.92	58.4714
1522.1	43.4714
1525.28	58.4714
1528.46	37.4714
1531.64	60.4714
1534.82	41.4714
1537.99	50.4714
1541.17	50.4714
1544.35	52.4714
1547.52	51.4714
1550.7	62.4714
1553.87	66.4714
1557.05	67.4714
1560.22	85.4714
1563.39	89.4714
1566.56	95.4714
1569.74	82.4714
1572.91	94.4714
1576.08	129.471
1579.25	108.471
1582.42	114.471
1585.59	132.471
1588.76	144.471
1591.93	134.471
1595.1	181.471
1598.26	155.471
1601.43	162.471
1604.6	144.471
1607.76	168.471
1610.93	139.471
1614.09	139.471
1617.26	132.471
1620.42	107.471
1623.59	94.4714
1626.75	96.4714
1629.91	104.471
1633.07	96.4714
1636.24	91.4714
1639.39	96.4714
1642.56	83.4714
1645.72	111.471
1648.87	110.471
1652.03	103.471
1655.19	123.471
1658.35	125.471
1661.51	128.471
1664.66	124.471
1667.82	133.471
1670.98	134.471
1674.13	142.471
1677.29	107.471
1680.44	89.4714
1683.59	93.4714
1686.75	92.4714
1689.9	93.4714
1693.05	59.4714
1696.21	61.4714
1699.36	68.4714
1702.51	47.4714
1705.66	36.4714
1708.81	36.4714
1711.96	43.4714
1715.1	35.4714
1718.25	33.4714
1721.4	11.4714
1724.55	25.4714
1727.69	22.4714
1730.84	21.4714
1733.99	17.4714
1737.13	11.4714
1740.28	9.47139
1743.42	13.4714
1746.56	7.47139
1749.71	12.4714
1752.85	9.47139
1755.99	10.4714
1759.14	4.47139
1762.28	9.47139
1765.42	9.47139
1768.56	1.47139
1771.7	0.471388
1774.83	5.47139
1777.97	5.47139
1781.11	3.47139
1784.25	4.47139
1787.38	10.4714
1790.52	0.471388
1793.66	0.471388
1796.8	0.471388
1799.93	-0.528612
1803.07	2.47139
1806.2	3.47139
1809.33	3.47139
1812.47	-5.52861
1815.6	4.47139
1818.73	-0.528612
1821.86	2.47139
1824.99	7.47139
1828.12	1.47139
1831.25	3.47139
1834.38	-7.52861
1837.51	0.471388
1840.64	3.47139
1843.77	5.47139
1846.9	2.47139
1850.02	1.47139
1853.15	1.47139
1856.28	1.47139
1859.4	-2.52861
1862.53	1.47139
1865.65	-2.52861
1868.78	2.47139
1871.9	5.47139
1875.02	-4.52861
1878.14	-2.52861
1881.26	-1.52861
1884.39	3.47139
1887.51	-3.52861
1890.63	2.47139
1893.75	-2.52861
1896.87	-3.52861
1899.99	-1.52861
1903.11	1.47139
1906.22	-4.52861
1909.34	-1.52861
1912.46	4.47139
1915.58	3.47139
1918.69	4.47139
1921.81	-3.52861
1924.92	2.47139
1928.04	1.47139
1931.15	-1.52861
1934.26	5.47139
1937.38	-1.52861
1940.49	0.471388
1943.6	0.471388
1946.71	8.47139
1949.82	-2.52861
1952.94	-0.528612
1956.05	1.47139
1959.15	7.47139
1962.27	4.47139
1965.37	-2.52861
1968.48	-1.52861
1971.59	1.47139
1974.7	-3.52861
1977.8	-1.52861
1980.91	4.47139
1984.01	4.47139
1987.12	6.47139
1990.22	5.47139
1993.33	5.47139
1996.43	7.47139
1999.53	4.47139
2002.64	-0.528612
2005.74	0.471388
2008.84	2.47139
2011.94	8.47139
2015.04	5.47139
2018.14	-1.52861
2021.24	14.4714
2024.34	6.47139
2027.44	7.47139
2030.54	8.47139
2033.64	5.47139
2036.73	7.47139
2039.83	0.471388
2042.93	12.4714
2046.02	9.47139
2049.12	6.47139
2052.21	8.47139
2055.31	4.47139
2058.4	0.471388
2061.49	1.47139
2064.59	9.47139
2067.68	11.4714
2070.77	0.471388
2073.86	13.4714
2076.95	8.47139
2080.04	3.47139
2083.13	5.47139
2086.22	-0.528612
2089.31	4.47139
2092.4	0.471388
2095.49	1.47139
2098.57	12.4714
2101.66	3.47139
2104.75	-5.52861
2107.83	8.47139
2110.92	-0.528612
2114	10.4714
2117.09	3.47139
2120.17	11.4714
2123.26	4.47139
2126.34	0.471388
2129.42	8.47139
2132.5	12.4714
2135.58	9.47139
2138.67	3.47139
2141.75	0.471388
2144.82	8.47139
2147.91	5.47139
2150.98	2.47139
2154.06	12.4714
2157.14	0.471388
2160.22	5.47139
2163.29	4.47139
2166.37	11.4714
2169.45	3.47139
2172.52	2.47139
2175.6	8.47139
2178.67	13.4714
2181.75	14.4714
2184.82	-2.52861
2187.89	7.47139
2190.97	0.471388
2194.04	3.47139
2197.11	-2.52861
2200.18	10.4714
2203.25	-0.528612
2206.32	12.4714
2209.39	4.47139
2212.46	8.47139
2215.53	1.47139
2218.6	7.47139
2221.67	5.47139
2224.73	5.47139
2227.8	3.47139
2230.87	8.47139
2233.93	10.4714
2237	5.47139
2240.06	4.47139
2243.12	-1.52861
2246.19	3.47139
2249.25	8.47139
2252.32	-2.52861
2255.38	2.47139
2258.44	2.47139
2261.5	8.47139
2264.56	-0.528612
2267.62	2.47139
2270.68	12.4714
2273.74	-3.52861
2276.8	1.47139
2279.86	9.47139
2282.92	0.471388
2285.98	8.47139
2289.03	4.47139
2292.09	-5.52861
2295.15	2.47139
2298.2	-1.52861
2301.25	1.47139
2304.31	8.47139
2307.36	4.47139
2310.42	2.47139
2313.47	2.47139
2316.52	2.47139
2319.58	-2.52861
2322.63	3.47139
2325.68	0.471388
2328.73	8.47139
2331.78	-1.52861
2334.83	-1.52861
2337.88	8.47139
2340.93	-2.52861
2343.97	0.471388
2347.02	3.47139
2350.07	7.47139
2353.12	2.47139
2356.16	6.47139
2359.21	-3.52861
2362.25	3.47139
2365.3	0.471388
2368.34	4.47139
2371.39	0.471388
2374.43	-3.52861
2377.47	-1.52861
2380.52	0.471388
2383.56	1.47139
2386.6	-5.52861
2389.64	8.47139
2392.68	0.471388
2395.72	1.47139
2398.76	14.4714
2401.8	0.471388
2404.84	-6.52861
2407.88	4.47139
2410.91	1.47139
2413.95	-2.52861
2416.99	-0.528612
2420.02	-7.52861
2423.06	-4.52861
2426.09	-4.52861
2429.13	-0.528612
2432.16	0.471388
2435.2	6.47139
2438.23	-7.52861
2441.26	-8.52861
2444.3	-4.52861
2447.33	4.47139
2450.36	-4.52861
2453.39	-1.52861
2456.42	-0.528612
2459.45	-6.52861
2462.48	0.471388
2465.51	-0.528612
2468.54	-0.528612
2471.57	-5.52861
2474.59	-0.528612
2477.62	-1.52861
2480.65	1.47139
2483.67	-1.52861
2486.7	4.47139
2489.72	-2.52861
2492.75	-2.52861
2495.77	1.47139
2498.8	6.47139
2501.82	-2.52861
2504.84	-2.52861
2507.86	-5.52861
2510.89	-1.52861
2513.91	1.47139
2516.93	-0.528612
2519.95	1.47139
2522.97	-3.52861
2525.99	-7.52861
2529.01	3.47139
2532.03	3.47139
2535.04	-1.52861
2538.06	3.47139
2541.08	-3.52861
2544.09	3.47139
2547.11	9.47139
2550.13	2.47139
2553.14	-0.528612
2556.16	1.47139
2559.17	4.47139
2562.18	-0.528612
2565.2	-1.52861
2568.21	-0.528612
2571.22	0.471388
2574.23	0.471388
2577.25	7.47139
2580.26	7.47139
2583.27	-0.528612
2586.28	-0.528612
2589.29	1.47139
2592.29	-0.528612
2595.3	3.47139
2598.31	-2.52861
2601.32	10.4714
2604.33	1.47139
2607.33	0.471388
2610.34	-1.52861
2613.34	-0.528612
2616.35	0.471388
2619.35	0.471388
2622.36	2.47139
2625.36	3.47139
2628.36	8.47139
2631.37	2.47139
2634.37	6.47139
2637.37	6.47139
2640.37	-0.528612
2643.38	-0.528612
2646.37	0.471388
2649.37	-1.52861
2652.37	5.47139
2655.37	-3.52861
2658.37	-2.52861
2661.37	5.47139
2664.37	0.471388
2667.36	0.471388
2670.36	-1.52861
2673.36	1.47139
2676.35	1.47139
2679.35	8.47139
2682.34	3.47139
2685.34	5.47139
2688.33	15.4714
2691.32	-2.52861
2694.32	2.47139
2697.31	1.47139
2700.3	6.47139
2703.29	1.47139
2706.28	7.47139
2709.27	4.47139
2712.26	4.47139
2715.25	10.4714
2718.24	2.47139
2721.23	5.47139
2724.22	9.47139
2727.21	-1.52861
2730.19	5.47139
2733.18	1.47139
2736.17	4.47139
2739.15	12.4714
2742.14	4.47139
2745.12	10.4714
2748.11	6.47139
2751.09	12.4714
2754.07	-1.52861
2757.06	10.4714
2760.04	1.47139
2763.02	15.4714
2766	11.4714
2768.98	17.4714
2771.96	8.47139
2774.94	8.47139
2777.92	8.47139
2780.9	18.4714
2783.88	11.4714
2786.86	15.4714
2789.84	10.4714
2792.81	15.4714
2795.79	9.47139
2798.77	10.4714
2801.74	21.4714
2804.72	0.471388
2807.69	16.4714
2810.67	10.4714
2813.64	7.47139
2816.62	22.4714
2819.59	13.4714
2822.56	12.4714
2825.53	25.4714
2828.5	14.4714
2831.48	14.4714
2834.45	9.47139
2837.42	15.4714
2840.39	6.47139
2843.36	5.47139
2846.32	22.4714
2849.29	16.4714
2852.26	15.4714
2855.23	19.4714
2858.2	12.4714
2861.16	12.4714
2864.13	25.4714
2867.09	16.4714
2870.06	21.4714
2873.02	24.4714
2875.99	25.4714
2878.95	16.4714
2881.91	28.4714
2884.88	17.4714
2887.84	22.4714
2890.8	23.4714
2893.76	47.4714
2896.73	28.4714
2899.69	22.4714
2902.65	34.4714
2905.6	35.4714
2908.56	40.4714
2911.52	43.4714
2914.48	35.4714
2917.44	38.4714
2920.4	36.4714
2923.35	42.4714
2926.31	40.4714
2929.27	46.4714
2932.22	45.4714
2935.18	39.4714
2938.13	59.4714
2941.08	56.4714
2944.04	42.4714
2946.99	62.4714
2949.94	60.4714
2952.89	54.4714
2955.85	64.4714
2958.8	61.4714
2961.75	61.4714
2964.7	61.4714
2967.65	72.4714
2970.6	59.4714
2973.54	65.4714
2976.49	70.4714
2979.44	88.4714
2982.39	88.4714
2985.34	76.4714
2988.28	76.4714
2991.23	90.4714
2994.17	71.4714
2997.12	88.4714
3000.07	106.471
3003.01	99.4714
3005.95	103.471
3008.9	106.471
3011.84	120.471
3014.78	118.471
3017.72	128.471
3020.67	115.471
3023.6	130.471
3026.55	123.471
3029.49	145.471
3032.43	165.471
3035.37	151.471
3038.31	154.471
3041.24	143.471
3044.18	164.471
3047.12	176.471
3050.06	195.471
3052.99	181.471
3055.93	192.471
3058.86	180.471
3061.8	186.471
3064.73	189.471
3067.67	226.471
3070.6	212.471
3073.53	222.471
3076.47	216.471
3079.4	217.471
3082.33	232.471
3085.26	258.471
3088.19	265.471
3091.12	261.471
3094.05	263.471
3096.98	291.471
3099.91	273.471
3102.84	286.471
3105.77	315.471
3108.69	301.471
3111.62	311.471
3114.55	315.471
3117.48	330.471
3120.4	341.471
3123.33	340.471
3126.25	351.471
3129.18	371.471
3132.1	392.471
3135.02	422.471
3137.95	385.471
3140.87	403.471
3143.79	427.471
3146.71	470.471
3149.63	472.471
3152.56	434.471
3155.48	448.471
3158.4	489.471
3161.31	505.471
3164.23	523.471
3167.15	548.471
3170.07	513.471
3172.99	522.471
3175.91	570.471
3178.82	563.471
3181.74	594.471
3184.66	575.471
3187.57	638.471
3190.48	635.471
3193.4	662.471
3196.31	652.471
3199.23	652.471
3202.14	669.471
3205.05	685.471
3207.96	672.471
3210.88	639.471
3213.79	642.471
3216.7	688.471
3219.61	701.471
3222.52	708.471
3225.43	760.471
3228.34	658.471
3231.25	688.471
3234.15	689.471
3237.06	720.471
3239.97	715.471
3242.88	761.471
3245.78	768.471
3248.69	737.471
3251.59	787.471
3254.5	712.471
3257.4	731.471
3260.31	772.471
3263.21	739.471
3266.11	751.471
3269.02	762.471
3271.92	759.471
3274.82	770.471
3277.72	726.471
3280.62	753.471
3283.52	748.471
3286.42	751.471
3289.32	783.471
3292.22	805.471
3295.12	799.471
3298.02	743.471
3300.91	780.471
3303.81	803.471
3306.71	780.471
3309.61	790.471
3312.5	810.471
3315.4	812.471
3318.29	773.471
3321.18	822.471
3324.08	809.471
3326.97	776.471
3329.87	800.471
3332.76	834.471
3335.65	774.471
3338.54	847.471
3341.43	833.471
3344.32	825.471
3347.21	851.471
3350.11	835.471
3353	867.471
3355.88	840.471
3358.77	858.471
3361.66	922.471
3364.55	832.471
3367.44	931.471
3370.32	882.471
3373.21	867.471
3376.09	906.471
3378.98	935.471
3381.86	956.471
3384.75	898.471
3387.63	926.471
3390.52	907.471
3393.4	885.471
3396.28	905.471
3399.17	909.471
3402.05	975.471
3404.93	886.471
3407.81	878.471
3410.69	908.471
3413.57	899.471
3416.45	877.471
3419.33	776.471
3422.21	857.471
3425.09	821.471
3427.96	863.471
3430.84	781.471
3433.72	794.471
3436.59	830.471
3439.47	827.471
3442.35	805.471
3445.22	813.471
3448.1	791.471
3450.97	838.471
3453.85	772.471
3456.72	757.471
3459.59	750.471
3462.46	756.471
3465.34	759.471
3468.21	768.471
3471.08	671.471
3473.95	729.471
3476.82	769.471
3479.69	710.471
3482.56	662.471
3485.43	690.471
3488.3	674.471
3491.16	648.471
3494.03	659.471
3496.9	670.471
3499.77	654.471
3502.63	642.471
3505.5	641.471
3508.36	598.471
3511.23	604.471
3514.09	583.471
3516.96	613.471
3519.82	562.471
3522.68	547.471
3525.55	555.471
3528.41	548.471
3531.27	557.471
3534.13	488.471
3536.99	496.471
3539.85	508.471
3542.71	497.471
3545.57	468.471
3548.43	490.471
3551.29	466.471
3554.15	489.471
3557.01	443.471
3559.86	416.471
3562.72	399.471
3565.58	443.471
3568.43	424.471
3571.29	433.471
3574.14	375.471
3577	415.471
3579.85	376.471
3582.71	387.471
3585.56	395.471
3588.41	377.471
3591.26	359.471
3594.12	370.471
3596.97	324.471
3599.82	350.471
3602.67	318.471
3605.52	335.471
3608.37	282.471
3611.22	293.471
3614.07	316.471
3616.92	316.471
3619.77	253.471
3622.61	273.471
3625.46	280.471
3628.31	249.471
3631.15	254.471
3634	260.471
3636.84	258.471
3639.69	248.471
3642.53	230.471
3645.38	231.471
3648.22	201.471
3651.06	199.471
3653.91	200.471
3656.75	200.471
3659.59	198.471
3662.43	187.471
3665.27	173.471
3668.11	165.471
3670.95	120.471
3673.8	152.471
3676.63	122.471
3679.47	103.471
3682.31	108.471
3685.15	108.471
3687.99	109.471
3690.82	97.4714
3693.66	103.471
3696.5	90.4714
3699.33	62.4714
3702.17	70.4714
3705	60.4714
3707.84	49.4714
3710.67	59.4714
3713.5	47.4714
3716.34	46.4714
3719.17	43.4714
3722	33.4714
3724.83	44.4714
3727.66	28.4714
3730.5	30.4714
3733.33	31.4714
3736.16	24.4714
3738.99	23.4714
3741.81	30.4714
3744.64	21.4714
3747.47	19.4714
3750.3	20.4714
3753.13	24.4714
3755.95	15.4714
3758.78	19.4714
3761.61	13.4714
3764.43	12.4714
3767.26	12.4714
3770.08	21.4714
3772.91	15.4714
3775.73	11.4714
3778.55	5.47139
3781.38	10.4714
3784.2	9.47139
3787.02	10.4714
3789.84	11.4714
3792.67	15.4714
3795.49	4.47139
3798.31	7.47139
3801.13	19.4714
3803.95	0.471388
3806.76	9.47139
3809.58	3.47139
3812.4	8.47139
3815.22	4.47139
3818.04	11.4714
3820.85	1.47139
3823.67	1.47139
3826.49	4.47139
3829.3	-9.52861
3832.12	7.47139
3834.93	3.47139
3837.75	-1.52861
3840.56	2.47139
3843.37	6.47139
3846.19	-7.52861
3849	9.47139
3850.41	9.47139