File: DUV Raman/_14_08_30_2021_04_15_Lebanon_3_120 s_229 nm_1800 (500nm)_X40_UVB_150_100%_01.txt
#Acq. time (s)=	120
#Accumulations=	3
#Range=	Off
#Autofocus=	Off
#Macrospot=	Off
#AutoExposure=	Off
#Spike filter=	Multiple accum.
#Delay time (s)=	0
#Binning=	1
#Readout mode=	Signal-Dark
#DeNoise=	Off
#ICS correction=	Off
#Dark correction=	Off
#Inst. Process=	Off
#Detector temperature (°C)=	-75.13
#Instrument=	LabRAM HR Evol
#Detector=	Synapse
#Objective=	X40_UVB
#Grating=	1800 (500nm)
#ND Filter=	100%
#Laser (nm)=	229
#Spectro (cm-¹)=	2350.07
#Hole=	150.001
#Range=	UV
#StageXY=	Marzhauser
#StageZ=	Marzhauser
#X (µm)=	0
#Y (µm)=	0
#Z (µm)=	0
#Full time(mm:ss)=	6:02
#Project=	2021-4-15_Andrew_fertilizer_DUV
#Sample=
#Site=
#Title=	_14_02_28_2021_04_15_Lebanon_3_120 s_229 nm_1800 (500nm)_X40_UVB_150_100%
#Remark=
#Date=	15.04.2021 14:04
#Acquired=	15.04.2021 14:04:29
#Edit:Mul=	15.04.2021 14:08:56
#Edit:Mul=	15.04.2021 14:09:04
727.454	6.3493
730.763	38.0958
734.071	50.7944
737.376	38.0958
740.683	60.3183
743.989	34.9211
747.295	15.8732
750.6	47.6197
753.905	95.2395
757.21	88.8902
760.511	66.6676
763.814	57.1437
767.117	111.113
770.42	104.763
773.721	114.287
777.02	82.5409
780.321	149.208
783.621	88.8902
786.921	53.969
790.218	66.6676
793.517	114.287
796.815	101.589
800.113	53.969
803.407	66.6676
806.704	142.859
810	104.763
813.293	174.606
816.589	25.3972
819.881	76.1916
823.175	126.986
826.469	107.938
829.759	101.589
833.052	107.938
836.341	117.462
839.633	114.287
842.924	149.208
846.212	76.1916
849.502	136.51
852.789	133.335
856.079	133.335
859.365	95.2395
862.653	161.907
865.938	98.4141
869.225	88.8902
872.509	117.462
875.792	88.8902
879.078	-3.17465
882.36	92.0648
885.645	126.986
888.926	63.493
892.207	79.3662
895.49	50.7944
898.77	88.8902
902.05	114.287
905.331	73.0169
908.61	104.763
911.887	82.5409
915.168	111.113
918.444	50.7944
921.721	50.7944
924.999	82.5409
928.275	88.8902
931.55	31.7465
934.824	120.637
938.098	152.383
941.374	126.986
944.647	126.986
947.919	133.335
951.191	82.5409
954.462	187.304
957.736	133.335
961.006	168.256
964.276	136.51
967.545	126.986
970.814	92.0648
974.083	126.986
977.35	107.938
980.618	114.287
983.884	130.161
987.151	73.0169
990.417	111.113
993.682	171.431
996.947	371.434
1000.21	330.163
1003.47	365.085
1006.74	336.513
1010	196.828
1013.26	231.749
1016.53	212.701
1019.79	180.955
1023.05	180.955
1026.31	190.479
1029.57	136.51
1032.83	123.811
1036.09	247.623
1039.34	190.479
1042.6	142.859
1045.86	136.51
1049.11	152.383
1052.37	149.208
1055.63	126.986
1058.88	92.0648
1062.13	85.7155
1065.39	139.685
1068.64	73.0169
1071.89	130.161
1075.14	123.811
1078.4	9.52395
1081.65	123.811
1084.9	101.589
1088.15	130.161
1091.4	104.763
1094.65	117.462
1097.9	136.51
1101.14	117.462
1104.39	85.7155
1107.64	19.0479
1110.89	60.3183
1114.13	126.986
1117.38	168.256
1120.62	66.6676
1123.86	152.383
1127.11	206.352
1130.35	95.2395
1133.6	152.383
1136.84	15.8732
1140.08	193.654
1143.32	130.161
1146.56	123.811
1149.8	92.0648
1153.04	161.907
1156.28	130.161
1159.52	76.1916
1162.75	212.701
1165.99	101.589
1169.23	149.208
1172.46	180.955
1175.7	206.352
1178.94	161.907
1182.17	228.575
1185.4	165.082
1188.64	85.7155
1191.87	66.6676
1195.1	168.256
1198.34	190.479
1201.57	57.1437
1204.8	136.51
1208.03	187.304
1211.26	120.637
1214.49	133.335
1217.72	212.701
1220.95	123.811
1224.18	104.763
1227.4	190.479
1230.63	158.732
1233.86	193.654
1237.08	126.986
1240.31	200.003
1243.53	177.78
1246.76	95.2395
1249.98	158.732
1253.2	130.161
1256.43	168.256
1259.65	168.256
1262.87	152.383
1266.09	133.335
1269.31	234.924
1272.53	139.685
1275.75	161.907
1278.97	212.701
1282.19	174.606
1285.41	212.701
1288.62	187.304
1291.84	136.51
1295.06	203.178
1298.27	247.623
1301.49	187.304
1304.7	180.955
1307.92	171.431
1311.13	149.208
1314.35	184.13
1317.56	196.828
1320.77	180.955
1323.98	130.161
1327.19	228.575
1330.41	228.575
1333.61	206.352
1336.82	184.13
1340.03	225.4
1343.24	231.749
1346.45	209.527
1349.66	190.479
1352.87	307.941
1356.07	269.845
1359.28	215.876
1362.48	241.273
1365.69	231.749
1368.89	349.211
1372.1	238.099
1375.3	304.766
1378.5	304.766
1381.71	203.178
1384.91	212.701
1388.11	238.099
1391.31	241.273
1394.51	203.178
1397.71	126.986
1400.91	274.29
1404.11	219.686
1407.31	247.623
1410.5	218.416
1413.7	144.764
1416.9	250.797
1420.1	168.256
1423.29	171.431
1426.48	168.256
1429.68	206.352
1432.87	250.797
1436.07	241.273
1439.26	231.749
1442.46	228.575
1445.65	222.225
1448.84	295.242
1452.03	247.623
1455.22	215.876
1458.41	165.082
1461.6	298.417
1464.79	222.225
1467.98	120.637
1471.17	311.116
1474.35	215.876
1477.54	200.003
1480.72	200.003
1483.91	206.352
1487.1	219.051
1490.28	193.654
1493.47	234.924
1496.65	228.575
1499.83	193.654
1503.02	203.178
1506.2	206.352
1509.38	187.304
1512.56	212.701
1515.74	203.178
1518.92	209.527
1522.1	184.13
1525.28	228.575
1528.46	253.972
1531.64	244.448
1534.82	238.099
1537.99	234.924
1541.17	228.575
1544.35	253.972
1547.52	269.845
1550.7	336.513
1553.87	314.29
1557.05	307.941
1560.22	374.609
1563.39	260.321
1566.56	301.592
1569.74	307.941
1572.91	358.735
1576.08	380.958
1579.25	438.102
1582.42	476.197
1585.59	419.054
1588.76	482.547
1591.93	463.499
1595.1	488.896
1598.26	444.451
1601.43	514.293
1604.6	587.31
1607.76	568.262
1610.93	504.769
1614.09	590.485
1617.26	549.214
1620.42	501.594
1623.59	434.927
1626.75	346.037
1629.91	339.687
1633.07	333.338
1636.24	336.513
1639.39	339.687
1642.56	304.766
1645.72	215.876
1648.87	298.417
1652.03	266.67
1655.19	342.862
1658.35	225.4
1661.51	384.132
1664.66	307.941
1667.82	374.609
1670.98	320.64
1674.13	298.417
1677.29	263.496
1680.44	336.513
1683.59	273.02
1686.75	304.766
1689.9	250.797
1693.05	234.924
1696.21	149.208
1699.36	184.13
1702.51	130.161
1705.66	196.828
1708.81	171.431
1711.96	212.701
1715.1	139.685
1718.25	184.13
1721.4	165.082
1724.55	133.335
1727.69	114.287
1730.84	130.161
1733.99	139.685
1737.13	101.589
1740.28	117.462
1743.42	31.7465
1746.56	133.335
1749.71	133.335
1752.85	152.383
1755.99	142.859
1759.14	107.938
1762.28	117.462
1765.42	123.811
1768.56	88.8902
1771.7	98.4141
1774.83	149.208
1777.97	88.8902
1781.11	15.8732
1784.25	60.3183
1787.38	98.4141
1790.52	136.51
1793.66	92.0648
1796.8	133.335
1799.93	111.113
1803.07	28.5718
1806.2	142.859
1809.33	133.335
1812.47	63.493
1815.6	79.3662
1818.73	95.2395
1821.86	66.6676
1824.99	107.938
1828.12	88.8902
1831.25	95.2395
1834.38	117.462
1837.51	101.589
1840.64	76.1916
1843.77	107.938
1846.9	69.8423
1850.02	142.859
1853.15	149.208
1856.28	92.0648
1859.4	95.2395
1862.53	114.287
1865.65	139.685
1868.78	130.161
1871.9	146.034
1875.02	101.589
1878.14	101.589
1881.26	111.113
1884.39	92.0648
1887.51	142.859
1890.63	136.51
1893.75	111.113
1896.87	88.8902
1899.99	38.0958
1903.11	92.0648
1906.22	85.7155
1909.34	53.969
1912.46	79.3662
1915.58	174.606
1918.69	117.462
1921.81	82.5409
1924.92	133.335
1928.04	101.589
1931.15	123.811
1934.26	158.732
1937.38	123.811
1940.49	79.3662
1943.6	25.3972
1946.71	114.287
1949.82	95.2395
1952.94	149.208
1956.05	107.938
1959.15	149.208
1962.27	44.4451
1965.37	133.335
1968.48	101.589
1971.59	117.462
1974.7	107.938
1977.8	107.938
1980.91	85.7155
1984.01	88.8902
1987.12	50.7944
1990.22	130.161
1993.33	111.113
1996.43	22.2225
1999.53	101.589
2002.64	95.2395
2005.74	53.969
2008.84	155.558
2011.94	98.4141
2015.04	161.907
2018.14	76.1916
2021.24	142.859
2024.34	101.589
2027.44	111.113
2030.54	25.3972
2033.64	152.383
2036.73	104.763
2039.83	168.256
2042.93	123.811
2046.02	155.558
2049.12	174.606
2052.21	177.78
2055.31	82.5409
2058.4	130.161
2061.49	126.986
2064.59	69.8423
2067.68	101.589
2070.77	104.763
2073.86	130.161
2076.95	63.493
2080.04	82.5409
2083.13	155.558
2086.22	76.1916
2089.31	79.3662
2092.4	95.2395
2095.49	184.13
2098.57	88.8902
2101.66	88.8902
2104.75	120.637
2107.83	73.0169
2110.92	82.5409
2114	85.7155
2117.09	85.7155
2120.17	63.493
2123.26	98.4141
2126.34	174.606
2129.42	139.685
2132.5	180.955
2135.58	92.0648
2138.67	117.462
2141.75	142.859
2144.82	171.431
2147.91	155.558
2150.98	117.462
2154.06	139.685
2157.14	104.763
2160.22	136.51
2163.29	168.256
2166.37	114.287
2169.45	142.859
2172.52	76.1916
2175.6	165.082
2178.67	161.907
2181.75	149.208
2184.82	95.2395
2187.89	152.383
2190.97	126.986
2194.04	123.811
2197.11	88.8902
2200.18	126.986
2203.25	136.51
2206.32	133.335
2209.39	41.2704
2212.46	126.986
2215.53	123.811
2218.6	130.161
2221.67	146.034
2224.73	104.763
2227.8	126.986
2230.87	225.4
2233.93	136.51
2237	95.2395
2240.06	126.986
2243.12	44.4451
2246.19	139.685
2249.25	152.383
2252.32	123.811
2255.38	193.654
2258.44	76.1916
2261.5	117.462
2264.56	152.383
2267.62	101.589
2270.68	152.383
2273.74	136.51
2276.8	126.986
2279.86	92.0648
2282.92	76.1916
2285.98	111.113
2289.03	98.4141
2292.09	117.462
2295.15	152.383
2298.2	114.287
2301.25	155.558
2304.31	104.763
2307.36	133.335
2310.42	15.8732
2313.47	120.637
2316.52	69.8423
2319.58	139.685
2322.63	123.811
2325.68	117.462
2328.73	136.51
2331.78	222.225
2334.83	174.606
2337.88	190.479
2340.93	184.13
2343.97	88.8902
2347.02	101.589
2350.07	171.431
2353.12	114.287
2356.16	152.383
2359.21	158.732
2362.25	130.161
2365.3	161.907
2368.34	73.0169
2371.39	133.335
2374.43	111.113
2377.47	111.113
2380.52	44.4451
2383.56	155.558
2386.6	126.986
2389.64	53.969
2392.68	171.431
2395.72	117.462
2398.76	136.51
2401.8	38.0958
2404.84	171.431
2407.88	57.1437
2410.91	123.811
2413.95	120.637
2416.99	107.938
2420.02	114.287
2423.06	88.8902
2426.09	114.287
2429.13	107.938
2432.16	161.907
2435.2	124.446
2438.23	67.9375
2441.26	106.668
2444.3	116.827
2447.33	53.969
2450.36	104.763
2453.39	66.6676
2456.42	152.383
2459.45	142.859
2462.48	104.763
2465.51	158.732
2468.54	165.082
2471.57	130.161
2474.59	133.335
2477.62	101.589
2480.65	133.335
2483.67	88.8902
2486.7	152.383
2489.72	123.811
2492.75	136.51
2495.77	123.811
2498.8	158.732
2501.82	142.859
2504.84	126.986
2507.86	79.3662
2510.89	73.0169
2513.91	152.383
2516.93	120.637
2519.95	50.7944
2522.97	104.763
2525.99	152.383
2529.01	107.938
2532.03	139.685
2535.04	161.907
2538.06	180.955
2541.08	165.082
2544.09	174.606
2547.11	146.034
2550.13	203.178
2553.14	123.811
2556.16	104.763
2559.17	187.304
2562.18	158.732
2565.2	104.763
2568.21	79.3662
2571.22	95.2395
2574.23	95.2395
2577.25	136.51
2580.26	158.732
2583.27	57.1437
2586.28	76.1916
2589.29	120.637
2592.29	142.859
2595.3	126.986
2598.31	130.161
2601.32	101.589
2604.33	136.51
2607.33	120.637
2610.34	142.859
2613.34	114.287
2616.35	146.034
2619.35	174.606
2622.36	76.1916
2625.36	98.4141
2628.36	155.558
2631.37	130.161
2634.37	165.082
2637.37	101.589
2640.37	146.034
2643.38	88.8902
2646.37	168.256
2649.37	120.637
2652.37	142.859
2655.37	95.2395
2658.37	126.986
2661.37	69.8423
2664.37	126.986
2667.36	142.859
2670.36	168.256
2673.36	120.637
2676.35	177.78
2679.35	180.955
2682.34	146.034
2685.34	133.335
2688.33	139.685
2691.32	155.558
2694.32	107.938
2697.31	177.78
2700.3	165.082
2703.29	190.479
2706.28	76.1916
2709.27	120.637
2712.26	193.654
2715.25	139.685
2718.24	130.161
2721.23	146.034
2724.22	114.287
2727.21	95.2395
2730.19	180.955
2733.18	123.811
2736.17	133.335
2739.15	146.034
2742.14	133.335
2745.12	104.763
2748.11	187.304
2751.09	168.256
2754.07	209.527
2757.06	142.859
2760.04	177.78
2763.02	149.208
2766	206.352
2768.98	155.558
2771.96	152.383
2774.94	212.701
2777.92	231.749
2780.9	130.161
2783.88	180.955
2786.86	168.256
2789.84	95.2395
2792.81	120.637
2795.79	136.51
2798.77	126.986
2801.74	171.431
2804.72	120.637
2807.69	212.701
2810.67	73.0169
2813.64	177.78
2816.62	171.431
2819.59	149.208
2822.56	152.383
2825.53	165.082
2828.5	177.78
2831.48	200.003
2834.45	231.749
2837.42	165.082
2840.39	200.003
2843.36	95.2395
2846.32	200.003
2849.29	200.003
2852.26	152.383
2855.23	155.558
2858.2	184.13
2861.16	228.575
2864.13	190.479
2867.09	149.208
2870.06	136.51
2873.02	273.02
2875.99	200.003
2878.95	158.732
2881.91	155.558
2884.88	215.876
2887.84	241.273
2890.8	187.304
2893.76	133.335
2896.73	177.78
2899.69	190.479
2902.65	206.352
2905.6	250.797
2908.56	174.606
2911.52	241.273
2914.48	244.448
2917.44	206.352
2920.4	231.749
2923.35	228.575
2926.31	247.623
2929.27	244.448
2932.22	200.003
2935.18	212.701
2938.13	247.623
2941.08	279.369
2944.04	209.527
2946.99	288.893
2949.94	288.893
2952.89	282.544
2955.85	298.417
2958.8	301.592
2961.75	250.797
2964.7	231.749
2967.65	333.338
2970.6	323.814
2973.54	285.718
2976.49	311.116
2979.44	266.67
2982.39	326.989
2985.34	311.116
2988.28	323.814
2991.23	314.29
2994.17	282.544
2997.12	298.417
3000.07	250.797
3003.01	323.814
3005.95	380.958
3008.9	346.037
3011.84	447.625
3014.78	323.814
3017.72	422.228
3020.67	438.102
3023.6	444.451
3026.55	438.102
3029.49	295.242
3032.43	453.975
3035.37	403.18
3038.31	428.578
3041.24	434.927
3044.18	488.896
3047.12	469.848
3050.06	511.118
3052.99	574.611
3055.93	479.372
3058.86	530.166
3061.8	558.738
3064.73	571.437
3067.67	596.834
3070.6	485.721
3073.53	542.865
3076.47	647.628
3079.4	666.676
3082.33	657.152
3085.26	631.755
3088.19	660.327
3091.12	765.09
3094.05	628.58
3096.98	619.056
3099.91	634.93
3102.84	682.549
3105.77	733.344
3108.69	768.265
3111.62	695.248
3114.55	752.392
3117.48	739.693
3120.4	787.313
3123.33	714.296
3126.25	904.775
3129.18	841.282
3132.1	1063.51
3135.02	879.378
3137.95	796.837
3140.87	917.473
3143.79	885.727
3146.71	990.49
3149.63	984.141
3152.56	898.426
3155.48	923.823
3158.4	1136.52
3161.31	1076.21
3164.23	1146.05
3167.15	977.792
3170.07	1120.65
3172.99	1123.83
3175.91	1092.08
3178.82	1196.84
3181.74	1165.1
3184.66	1234.94
3187.57	1152.4
3190.48	1282.56
3193.4	1174.62
3196.31	1304.78
3199.23	1311.13
3202.14	1253.99
3205.05	1457.16
3207.96	1422.24
3210.88	1355.57
3213.79	1396.85
3216.7	1431.77
3219.61	1384.15
3222.52	1400.02
3225.43	1323.83
3228.34	1568.28
3231.25	1520.66
3234.15	1457.16
3237.06	1406.37
3239.97	1317.48
3242.88	1466.69
3245.78	1574.63
3248.69	1761.93
3251.59	1400.02
3254.5	1593.67
3257.4	1400.02
3260.31	1438.12
3263.21	1431.77
3266.11	1584.15
3269.02	1447.64
3271.92	1482.56
3274.82	1438.12
3277.72	1533.36
3280.62	1533.36
3283.52	1609.55
3286.42	1485.74
3289.32	1415.89
3292.22	1463.51
3295.12	1565.1
3298.02	1587.32
3300.91	1457.16
3303.81	1565.1
3306.71	1536.53
3309.61	1603.2
3312.5	1561.93
3315.4	1590.5
3318.29	1539.7
3321.18	1482.56
3324.08	1463.51
3326.97	1482.56
3329.87	1523.83
3332.76	1469.86
3335.65	1577.8
3338.54	1600.02
3341.43	1590.5
3344.32	1561.93
3347.21	1660.34
3350.11	1663.52
3353	1631.77
3355.88	1828.6
3358.77	1622.25
3361.66	1498.43
3364.55	1647.64
3367.44	1733.36
3370.32	1714.31
3373.21	1587.32
3376.09	1685.74
3378.98	1730.18
3381.86	1549.23
3384.75	1625.42
3387.63	1603.2
3390.52	1749.23
3393.4	1698.44
3396.28	1755.58
3399.17	1695.26
3402.05	1666.69
3404.93	1660.34
3407.81	1704.79
3410.69	1495.26
3413.57	1717.48
3416.45	1673.04
3419.33	1796.85
3422.21	1606.37
3425.09	1574.63
3427.96	1650.82
3430.84	1520.66
3433.72	1612.72
3436.59	1609.55
3439.47	1631.77
3442.35	1527.01
3445.22	1428.59
3448.1	1542.88
3450.97	1498.43
3453.85	1495.26
3456.72	1536.53
3459.59	1520.66
3462.46	1482.56
3465.34	1504.78
3468.21	1434.94
3471.08	1492.08
3473.95	1425.42
3476.82	1434.94
3479.69	1215.89
3482.56	1415.89
3485.43	1342.88
3488.3	1285.73
3491.16	1339.7
3494.03	1234.94
3496.9	1095.25
3499.77	1250.81
3502.63	1184.14
3505.5	1177.79
3508.36	1269.86
3511.23	1250.81
3514.09	1238.11
3516.96	1212.72
3519.82	1171.45
3522.68	1171.45
3525.55	1304.78
3528.41	1006.36
3531.27	968.268
3534.13	1009.54
3536.99	1044.46
3539.85	1034.94
3542.71	904.775
3545.57	987.316
3548.43	933.347
3551.29	939.696
3554.15	898.426
3557.01	901.6
3559.86	914.299
3562.72	838.107
3565.58	857.155
3568.43	901.6
3571.29	822.234
3574.14	780.964
3577	882.552
3579.85	771.44
3582.71	800.011
3585.56	873.028
3588.41	590.485
3591.26	711.121
3594.12	701.597
3596.97	746.042
3599.82	771.44
3602.67	695.248
3605.52	612.707
3608.37	752.392
3611.22	663.502
3614.07	673.026
3616.92	571.437
3619.77	619.056
3622.61	546.04
3625.46	647.628
3628.31	555.563
3631.15	647.628
3634	587.31
3636.84	504.769
3639.69	558.738
3642.53	552.389
3645.38	447.625
3648.22	425.403
3651.06	526.992
3653.91	371.434
3656.75	428.578
3659.59	469.848
3662.43	412.704
3665.27	390.482
3668.11	320.64
3670.95	346.037
3673.8	400.006
3676.63	234.924
3679.47	311.116
3682.31	260.321
3685.15	276.194
3687.99	282.544
3690.82	222.225
3693.66	257.147
3696.5	206.352
3699.33	165.082
3702.17	130.161
3705	209.527
3707.84	146.034
3710.67	139.685
3713.5	203.178
3716.34	206.352
3719.17	149.208
3722	212.701
3724.83	107.938
3727.66	219.051
3730.5	142.859
3733.33	149.208
3736.16	88.8902
3738.99	130.161
3741.81	95.2395
3744.64	57.1437
3747.47	101.589
3750.3	146.034
3753.13	47.6197
3755.95	158.732
3758.78	142.859
3761.61	133.335
3764.43	107.938
3767.26	41.2704
3770.08	174.606
3772.91	149.208
3775.73	104.763
3778.55	85.7155
3781.38	38.0958
3784.2	136.51
3787.02	98.4141
3789.84	82.5409
3792.67	57.1437
3795.49	63.493
3798.31	66.6676
3801.13	152.383
3803.95	114.287
3806.76	123.811
3809.58	9.52395
3812.4	126.986
3815.22	98.4141
3818.04	161.907
3820.85	114.287
3823.67	79.3662
3826.49	12.6986
3829.3	66.6676
3832.12	107.938
3834.93	25.3972
3837.75	76.1916
3840.56	82.5409
3843.37	82.5409
3846.19	107.938
3849	104.763
3850.41	88.8902