File: DUV Raman/_14_30_37_2021_04_15_Stone Wall_3_120 s_229 nm_1800 (500nm)_X40_UVB_150_100%_01.txt
#Acq. time (s)=	120
#Accumulations=	3
#Range=	Off
#Autofocus=	Off
#Macrospot=	Off
#AutoExposure=	Off
#Spike filter=	Multiple accum.
#Delay time (s)=	0
#Binning=	1
#Readout mode=	Signal-Dark
#DeNoise=	Off
#ICS correction=	Off
#Dark correction=	Off
#Inst. Process=	Off
#Detector temperature (°C)=	-75.13
#Instrument=	LabRAM HR Evol
#Detector=	Synapse
#Objective=	X40_UVB
#Grating=	1800 (500nm)
#ND Filter=	100%
#Laser (nm)=	229
#Spectro (cm-¹)=	2350.07
#Hole=	150.001
#Range=	UV
#StageXY=	Marzhauser
#StageZ=	Marzhauser
#X (µm)=	0
#Y (µm)=	0
#Z (µm)=	0
#Full time(mm:ss)=	8:10
#Project=	2021-4-15_Andrew_fertilizer_DUV
#Sample=
#Site=
#Title=	_14_22_34_2021_04_15_Stone Wall_3_120 s_229 nm_1800 (500nm)_X40_UVB_150_100%
#Remark=
#Date=	15.04.2021 14:26
#Acquired=	15.04.2021 14:26:36
727.454	-6.5
730.763	8.5
734.071	6
737.376	6.5
740.683	5
743.989	6
747.295	2
750.6	1.5
753.905	8
757.21	21.5
760.511	6
763.814	5
767.117	11
770.42	0
773.721	3
777.02	3
780.321	8
783.621	4
786.921	7
790.218	4
793.517	11
796.815	0
800.113	9.5
803.407	8
806.704	6
810	-10
813.293	12.5
816.589	10.5
819.881	17
823.175	11
826.469	8
829.759	5.5
833.052	4
836.341	1
839.633	6.5
842.924	0.5
846.212	17.5
849.502	7
852.789	5
856.079	10
859.365	10
862.653	3
865.938	17.5
869.225	11
872.509	2
875.792	7
879.078	7
882.36	6
885.645	14
888.926	4
892.207	9.5
895.49	2
898.77	9
902.05	10
905.331	10
908.61	5
911.887	1
915.168	-5
918.444	24
921.721	27
924.999	18.5
928.275	4
931.55	7
934.824	-3
938.098	15
941.374	8
944.647	11.5
947.919	7
951.191	14
954.462	1.5
957.736	7
961.006	9
964.276	21
967.545	1.5
970.814	6
974.083	1
977.35	10
980.618	11.5
983.884	8
987.151	12
990.417	18.5
993.682	11
996.947	30
1000.21	25
1003.47	17.5
1006.74	28
1010	24.5
1013.26	23
1016.53	25
1019.79	16
1023.05	23
1026.31	16.5
1029.57	7
1032.83	11
1036.09	9
1039.34	12
1042.6	1
1045.86	1
1049.11	16
1052.37	7.5
1055.63	12
1058.88	6.5
1062.13	17.5
1065.39	8
1068.64	-1
1071.89	12
1075.14	5
1078.4	5
1081.65	14
1084.9	6
1088.15	10
1091.4	6.5
1094.65	7.5
1097.9	11.5
1101.14	4
1104.39	5.5
1107.64	4
1110.89	11
1114.13	13
1117.38	9.5
1120.62	11
1123.86	5.5
1127.11	8
1130.35	2
1133.6	5
1136.84	1
1140.08	18
1143.32	2
1146.56	8
1149.8	14
1153.04	6
1156.28	8.5
1159.52	13
1162.75	3.5
1165.99	19
1169.23	1
1172.46	8
1175.7	17
1178.94	21.5
1182.17	9.5
1185.4	21
1188.64	7
1191.87	8.5
1195.1	1
1198.34	10.5
1201.57	25
1204.8	18.5
1208.03	13
1211.26	10
1214.49	8.5
1217.72	13
1220.95	1
1224.18	22
1227.4	16
1230.63	12
1233.86	6.5
1237.08	0
1240.31	2
1243.53	10
1246.76	12
1249.98	11.5
1253.2	9.5
1256.43	17
1259.65	17
1262.87	14
1266.09	9
1269.31	10
1272.53	14.5
1275.75	13
1278.97	6.5
1282.19	19
1285.41	5
1288.62	7
1291.84	6.5
1295.06	11
1298.27	17
1301.49	3
1304.7	14.5
1307.92	15.5
1311.13	16.5
1314.35	11.5
1317.56	13
1320.77	18.5
1323.98	1.5
1327.19	17.5
1330.41	11
1333.61	23
1336.82	12
1340.03	19.5
1343.24	11
1346.45	24.5
1349.66	14
1352.87	21
1356.07	22
1359.28	12
1362.48	29
1365.69	19
1368.89	29.5
1372.1	28.5
1375.3	29.5
1378.5	21
1381.71	30
1384.91	24
1388.11	29
1391.31	14
1394.51	10.5
1397.71	20.5
1400.91	20.5
1404.11	17
1407.31	16
1410.5	19.5
1413.7	20
1416.9	10
1420.1	21
1423.29	17
1426.48	13.5
1429.68	16
1432.87	12.5
1436.07	7
1439.26	9.5
1442.46	23
1445.65	9.5
1448.84	20.5
1452.03	20
1455.22	20.5
1458.41	6
1461.6	6
1464.79	15.5
1467.98	11.5
1471.17	16
1474.35	20
1477.54	15
1480.72	17.5
1483.91	12.5
1487.1	13
1490.28	12.5
1493.47	11
1496.65	14
1499.83	16.5
1503.02	15
1506.2	6.5
1509.38	7
1512.56	26
1515.74	15
1518.92	9
1522.1	27
1525.28	3
1528.46	17
1531.64	24.5
1534.82	23
1537.99	18.5
1541.17	2
1544.35	20
1547.52	16
1550.7	20
1553.87	15.5
1557.05	35
1560.22	18.5
1563.39	20
1566.56	28.5
1569.74	20
1572.91	27
1576.08	27
1579.25	16.5
1582.42	36.5
1585.59	12
1588.76	28
1591.93	16
1595.1	35
1598.26	33
1601.43	31
1604.6	24.5
1607.76	26
1610.93	42
1614.09	36.5
1617.26	44.5
1620.42	32
1623.59	27
1626.75	35.5
1629.91	36.5
1633.07	32.5
1636.24	36
1639.39	26
1642.56	28.5
1645.72	22
1648.87	17
1652.03	18
1655.19	35.5
1658.35	27
1661.51	21
1664.66	22
1667.82	23
1670.98	16.5
1674.13	15.5
1677.29	19.5
1680.44	19
1683.59	22
1686.75	7
1689.9	15
1693.05	18
1696.21	19
1699.36	14.5
1702.51	6
1705.66	22.5
1708.81	13.5
1711.96	22
1715.1	13.5
1718.25	8.5
1721.4	21.5
1724.55	12.5
1727.69	21
1730.84	10
1733.99	11.5
1737.13	15
1740.28	22.5
1743.42	-2.5
1746.56	9
1749.71	25
1752.85	8
1755.99	6.5
1759.14	10.5
1762.28	13
1765.42	3
1768.56	9
1771.7	8
1774.83	-1
1777.97	9
1781.11	14.5
1784.25	21
1787.38	4.5
1790.52	0
1793.66	6
1796.8	6
1799.93	8.5
1803.07	9
1806.2	9
1809.33	9
1812.47	6
1815.6	5
1818.73	4
1821.86	9
1824.99	2.5
1828.12	-1
1831.25	-3
1834.38	6
1837.51	0.5
1840.64	4
1843.77	10.5
1846.9	9.5
1850.02	17.5
1853.15	12
1856.28	-0.5
1859.4	16.5
1862.53	6
1865.65	10.5
1868.78	2
1871.9	14.5
1875.02	15.5
1878.14	4
1881.26	2
1884.39	11.5
1887.51	15.5
1890.63	6.5
1893.75	5.5
1896.87	10
1899.99	2.5
1903.11	5
1906.22	14
1909.34	3.5
1912.46	12
1915.58	10
1918.69	15
1921.81	6
1924.92	15
1928.04	8
1931.15	15.5
1934.26	9
1937.38	15
1940.49	16
1943.6	7.5
1946.71	9.5
1949.82	4
1952.94	18
1956.05	19
1959.15	-5
1962.27	14
1965.37	8.5
1968.48	15.5
1971.59	17.5
1974.7	19.5
1977.8	14
1980.91	18
1984.01	0.5
1987.12	6
1990.22	9
1993.33	10
1996.43	12
1999.53	10
2002.64	8
2005.74	8
2008.84	15.5
2011.94	-3
2015.04	5
2018.14	8
2021.24	0.5
2024.34	15.5
2027.44	6.5
2030.54	10.5
2033.64	9.5
2036.73	8.5
2039.83	8.5
2042.93	11
2046.02	7
2049.12	1
2052.21	17.5
2055.31	1
2058.4	5.5
2061.49	5
2064.59	4
2067.68	11
2070.77	15.5
2073.86	10
2076.95	11.5
2080.04	8
2083.13	8.5
2086.22	13
2089.31	5.5
2092.4	7.5
2095.49	18
2098.57	4
2101.66	12
2104.75	10
2107.83	8.5
2110.92	13.5
2114	11
2117.09	2
2120.17	10
2123.26	12.5
2126.34	8.5
2129.42	9.5
2132.5	4
2135.58	14.5
2138.67	10
2141.75	7
2144.82	10
2147.91	11
2150.98	4
2154.06	18
2157.14	11
2160.22	-0.5
2163.29	6
2166.37	7
2169.45	16
2172.52	1.5
2175.6	1
2178.67	12
2181.75	6
2184.82	4
2187.89	7
2190.97	9
2194.04	12
2197.11	15.5
2200.18	13
2203.25	6
2206.32	10.5
2209.39	1
2212.46	11.5
2215.53	13
2218.6	7.5
2221.67	8
2224.73	-1
2227.8	12.5
2230.87	14
2233.93	1
2237	13.5
2240.06	3.5
2243.12	0.5
2246.19	7.5
2249.25	4.5
2252.32	6
2255.38	0
2258.44	11
2261.5	-1
2264.56	20
2267.62	-1
2270.68	6
2273.74	11
2276.8	17
2279.86	6
2282.92	1
2285.98	16
2289.03	-2
2292.09	13
2295.15	6
2298.2	2
2301.25	19
2304.31	13.5
2307.36	5
2310.42	8
2313.47	6.5
2316.52	5
2319.58	13.5
2322.63	12
2325.68	6
2328.73	10
2331.78	11.5
2334.83	13.5
2337.88	10.5
2340.93	14.5
2343.97	16
2347.02	2
2350.07	13
2353.12	12.5
2356.16	1.5
2359.21	0
2362.25	8
2365.3	4
2368.34	5
2371.39	10.5
2374.43	20
2377.47	9.5
2380.52	15.5
2383.56	8
2386.6	14
2389.64	12.5
2392.68	13
2395.72	13
2398.76	10
2401.8	17
2404.84	12.5
2407.88	10
2410.91	9
2413.95	6
2416.99	4
2420.02	12
2423.06	17.5
2426.09	11
2429.13	11
2432.16	9.5
2435.2	4.5
2438.23	9
2441.26	16
2444.3	9.5
2447.33	11
2450.36	15
2453.39	9
2456.42	18
2459.45	4
2462.48	15
2465.51	3
2468.54	7
2471.57	13.5
2474.59	10
2477.62	16.5
2480.65	6.5
2483.67	22
2486.7	5
2489.72	17.5
2492.75	11.5
2495.77	5
2498.8	13
2501.82	9
2504.84	4
2507.86	8.5
2510.89	8.5
2513.91	14.5
2516.93	19
2519.95	15
2522.97	-7
2525.99	22
2529.01	9
2532.03	6.5
2535.04	7
2538.06	14
2541.08	10
2544.09	14.5
2547.11	20.5
2550.13	3
2553.14	12
2556.16	21
2559.17	-1.5
2562.18	16
2565.2	9.5
2568.21	11
2571.22	3
2574.23	7
2577.25	15
2580.26	4
2583.27	8
2586.28	8
2589.29	2
2592.29	15.5
2595.3	15
2598.31	11
2601.32	17.5
2604.33	7.5
2607.33	7
2610.34	10.5
2613.34	13.5
2616.35	2.5
2619.35	6
2622.36	1
2625.36	13
2628.36	12
2631.37	9
2634.37	7
2637.37	7
2640.37	11.5
2643.38	14
2646.37	7
2649.37	12
2652.37	7
2655.37	13.5
2658.37	8
2661.37	3
2664.37	6
2667.36	9
2670.36	19
2673.36	15
2676.35	5
2679.35	12
2682.34	18.5
2685.34	17
2688.33	7
2691.32	17.5
2694.32	13
2697.31	-3
2700.3	8
2703.29	10.5
2706.28	3.5
2709.27	7
2712.26	11.5
2715.25	10.5
2718.24	6.5
2721.23	5.5
2724.22	11
2727.21	17
2730.19	14
2733.18	9
2736.17	14.5
2739.15	11
2742.14	18.5
2745.12	15
2748.11	2
2751.09	6.5
2754.07	11
2757.06	14
2760.04	18
2763.02	4
2766	12
2768.98	11.5
2771.96	10
2774.94	13
2777.92	2
2780.9	13
2783.88	11
2786.86	17
2789.84	12.5
2792.81	18.5
2795.79	9
2798.77	19
2801.74	10
2804.72	7
2807.69	3
2810.67	2
2813.64	10.5
2816.62	15
2819.59	25.5
2822.56	18
2825.53	17
2828.5	3.5
2831.48	15.5
2834.45	20
2837.42	10
2840.39	13
2843.36	7.5
2846.32	9
2849.29	13
2852.26	9
2855.23	10
2858.2	15
2861.16	21
2864.13	26
2867.09	16
2870.06	15.5
2873.02	14
2875.99	5
2878.95	12
2881.91	19
2884.88	14
2887.84	20
2890.8	5.5
2893.76	16.5
2896.73	19
2899.69	16
2902.65	10.5
2905.6	15
2908.56	18.5
2911.52	18
2914.48	20.5
2917.44	24
2920.4	14
2923.35	3
2926.31	7.5
2929.27	6
2932.22	15.5
2935.18	18
2938.13	18
2941.08	21
2944.04	17
2946.99	23
2949.94	14
2952.89	12
2955.85	18.5
2958.8	7.5
2961.75	12.5
2964.7	22
2967.65	23
2970.6	13.5
2973.54	14
2976.49	11.5
2979.44	8.5
2982.39	19
2985.34	21
2988.28	22.5
2991.23	20
2994.17	24
2997.12	7
3000.07	21.5
3003.01	16.5
3005.95	23
3008.9	37.5
3011.84	20.5
3014.78	33.5
3017.72	14
3020.67	15.5
3023.6	16
3026.55	24
3029.49	29
3032.43	20.5
3035.37	30
3038.31	26.5
3041.24	29.5
3044.18	24
3047.12	45
3050.06	29
3052.99	34
3055.93	14.5
3058.86	46
3061.8	30.5
3064.73	29
3067.67	33.5
3070.6	34
3073.53	31.5
3076.47	31
3079.4	41
3082.33	47.5
3085.26	34.5
3088.19	33
3091.12	43
3094.05	39
3096.98	45
3099.91	40.5
3102.84	43
3105.77	41
3108.69	42.5
3111.62	36.5
3114.55	52.5
3117.48	44
3120.4	55.5
3123.33	56
3126.25	58.5
3129.18	51.5
3132.1	52
3135.02	53
3137.95	44
3140.87	42
3143.79	68
3146.71	61
3149.63	67
3152.56	58.5
3155.48	59.5
3158.4	66.5
3161.31	63
3164.23	67.5
3167.15	62.5
3170.07	64.5
3172.99	70.5
3175.91	69.5
3178.82	60
3181.74	71.5
3184.66	71.5
3187.57	76
3190.48	75.5
3193.4	79.5
3196.31	59
3199.23	77
3202.14	79.5
3205.05	95.5
3207.96	98.5
3210.88	61
3213.79	79.5
3216.7	82
3219.61	75
3222.52	87.5
3225.43	93
3228.34	82
3231.25	94.5
3234.15	80.5
3237.06	75.5
3239.97	87
3242.88	89
3245.78	86
3248.69	86.5
3251.59	90.5
3254.5	86
3257.4	96
3260.31	79.5
3263.21	85
3266.11	85.5
3269.02	84
3271.92	77.5
3274.82	81.5
3277.72	73.5
3280.62	85
3283.52	73
3286.42	98
3289.32	96
3292.22	99
3295.12	88
3298.02	97
3300.91	82.5
3303.81	85.5
3306.71	104
3309.61	103.5
3312.5	100.5
3315.4	98
3318.29	105.5
3321.18	94
3324.08	108
3326.97	82
3329.87	103.5
3332.76	97
3335.65	88
3338.54	104.5
3341.43	94.5
3344.32	92
3347.21	105.5
3350.11	98.5
3353	103.5
3355.88	113.5
3358.77	98
3361.66	88
3364.55	102.5
3367.44	98
3370.32	91.5
3373.21	89.5
3376.09	97.5
3378.98	102
3381.86	104
3384.75	117
3387.63	103.5
3390.52	113
3393.4	89
3396.28	126.5
3399.17	105.5
3402.05	110
3404.93	112
3407.81	108.5
3410.69	105.5
3413.57	117
3416.45	99
3419.33	98
3422.21	101.5
3425.09	96
3427.96	95.5
3430.84	103
3433.72	101
3436.59	105.5
3439.47	102
3442.35	101.5
3445.22	93.5
3448.1	89
3450.97	91
3453.85	99
3456.72	98.5
3459.59	95
3462.46	89.5
3465.34	98.5
3468.21	74.5
3471.08	84.5
3473.95	79.5
3476.82	84.5
3479.69	97.5
3482.56	92
3485.43	85
3488.3	98
3491.16	92.5
3494.03	88
3496.9	85.5
3499.77	74.5
3502.63	74
3505.5	72.5
3508.36	84.5
3511.23	78
3514.09	79
3516.96	70
3519.82	59
3522.68	72.5
3525.55	71.5
3528.41	82
3531.27	81
3534.13	68
3536.99	77
3539.85	58
3542.71	63.5
3545.57	56
3548.43	57
3551.29	66.5
3554.15	53.5
3557.01	76
3559.86	57.5
3562.72	57.5
3565.58	61
3568.43	52
3571.29	41.5
3574.14	51
3577	56
3579.85	56.5
3582.71	50.5
3585.56	45.5
3588.41	45.5
3591.26	62
3594.12	55
3596.97	52
3599.82	38
3602.67	43.5
3605.52	61
3608.37	39
3611.22	51
3614.07	40.5
3616.92	38.5
3619.77	45
3622.61	37.5
3625.46	39.5
3628.31	39
3631.15	46.5
3634	43
3636.84	42
3639.69	30.5
3642.53	30
3645.38	37.5
3648.22	25
3651.06	27.5
3653.91	29
3656.75	25
3659.59	39.5
3662.43	29
3665.27	18.5
3668.11	28
3670.95	33.5
3673.8	17
3676.63	22
3679.47	28
3682.31	26.5
3685.15	14
3687.99	22
3690.82	23
3693.66	10.5
3696.5	13.5
3699.33	21.5
3702.17	17
3705	15
3707.84	9.5
3710.67	16
3713.5	15.5
3716.34	9.5
3719.17	13
3722	7.5
3724.83	18
3727.66	2
3730.5	15.5
3733.33	9
3736.16	20
3738.99	8.5
3741.81	3.5
3744.64	18
3747.47	10.5
3750.3	2.5
3753.13	18.5
3755.95	9
3758.78	2
3761.61	8
3764.43	12
3767.26	-2
3770.08	1.5
3772.91	12.5
3775.73	3
3778.55	9
3781.38	7
3784.2	9
3787.02	5
3789.84	3
3792.67	8
3795.49	12
3798.31	7
3801.13	15
3803.95	23
3806.76	3
3809.58	14.5
3812.4	14
3815.22	14.5
3818.04	15
3820.85	6.5
3823.67	3
3826.49	3
3829.3	2
3832.12	17.5
3834.93	9.5
3837.75	9
3840.56	15
3843.37	0
3846.19	3
3849	5
3850.41	4