File: DUV Raman/_14_43_31_2021_04_15_water-cp 10-1_3_120 s_229 nm_1800 (500nm)_X40_UVB_150_100%_01.txt
#Acq. time (s)=	120
#Accumulations=	3
#Range=	Off
#Autofocus=	Off
#Macrospot=	Off
#AutoExposure=	Off
#Spike filter=	Multiple accum.
#Delay time (s)=	0
#Binning=	1
#Readout mode=	Signal
#DeNoise=	Off
#ICS correction=	Off
#Dark correction=	Off
#Inst. Process=	Off
#Detector temperature (°C)=	-75.13
#Instrument=	LabRAM HR Evol
#Detector=	Synapse
#Objective=	X40_UVB
#Grating=	1800 (500nm)
#ND Filter=	100%
#Laser (nm)=	229
#Spectro (cm-¹)=	2350.07
#Hole=	150.001
#Range=	UV
#StageXY=	Marzhauser
#StageZ=	Marzhauser
#X (µm)=	0
#Y (µm)=	0
#Z (µm)=	0
#Full time(mm:ss)=	6:02
#Project=	2021-4-15_Andrew_fertilizer_DUV
#Sample=
#Site=
#Title=	_14_37_29_2021_04_15_water-cp 10-1_3_120 s_229 nm_1800 (500nm)_X40_UVB_150_100%
#Remark=
#Date=	15.04.2021 14:39
#Acquired=	15.04.2021 14:39:31
727.454	35.5
730.763	52.5
734.071	53
737.376	48.5
740.683	45
743.989	45
747.295	59.5
750.6	52
753.905	59
757.21	77.5
760.511	72.5
763.814	65.5
767.117	69
770.42	66.5
773.721	73.5
777.02	74.5
780.321	67
783.621	77
786.921	69.5
790.218	58.5
793.517	73
796.815	66
800.113	58
803.407	77
806.704	71.5
810	81.5
813.293	87
816.589	70
819.881	83.5
823.175	85.5
826.469	67
829.759	69
833.052	82
836.341	77
839.633	74.5
842.924	80.5
846.212	77
849.502	86
852.789	75
856.079	75.5
859.365	86
862.653	77.5
865.938	90
869.225	86
872.509	77.5
875.792	82.5
879.078	85
882.36	92
885.645	73.5
888.926	73
892.207	72
895.49	75
898.77	70
902.05	79.5
905.331	81
908.61	68.5
911.887	67.5
915.168	72.5
918.444	62.5
921.721	74
924.999	72.5
928.275	80
931.55	72.5
934.824	79
938.098	68
941.374	70
944.647	67
947.919	71.5
951.191	70.5
954.462	70.5
957.736	67.5
961.006	69
964.276	69
967.545	74
970.814	72
974.083	69.5
977.35	71.5
980.618	76
983.884	56
987.151	71
990.417	69.5
993.682	58.5
996.947	90
1000.21	78.5
1003.47	82
1006.74	76.5
1010	80
1013.26	71.5
1016.53	82.5
1019.79	88.5
1023.05	73
1026.31	69.5
1029.57	60.5
1032.83	64
1036.09	70
1039.34	68.5
1042.6	74.5
1045.86	72.5
1049.11	71
1052.37	73.5
1055.63	76
1058.88	70.5
1062.13	74.5
1065.39	76.5
1068.64	77
1071.89	69
1075.14	77
1078.4	68
1081.65	81
1084.9	73
1088.15	83.5
1091.4	76.5
1094.65	84.5
1097.9	80.5
1101.14	82
1104.39	85
1107.64	89.5
1110.89	90
1114.13	99
1117.38	79.5
1120.62	79.5
1123.86	82.5
1127.11	96.5
1130.35	82.5
1133.6	104.5
1136.84	101
1140.08	90.5
1143.32	102.5
1146.56	104
1149.8	97.5
1153.04	110
1156.28	101.5
1159.52	123.5
1162.75	97.5
1165.99	113.5
1169.23	113.5
1172.46	116
1175.7	122.5
1178.94	117.5
1182.17	127.5
1185.4	124
1188.64	121.5
1191.87	130.5
1195.1	111
1198.34	125.5
1201.57	129
1204.8	119.5
1208.03	121.5
1211.26	152.5
1214.49	147
1217.72	140
1220.95	142.5
1224.18	135
1227.4	146
1230.63	137
1233.86	145.5
1237.08	141.5
1240.31	143
1243.53	151
1246.76	151
1249.98	157
1253.2	139
1256.43	164
1259.65	173
1262.87	166.5
1266.09	163.5
1269.31	164
1272.53	155
1275.75	177.5
1278.97	182
1282.19	169.5
1285.41	177.5
1288.62	165
1291.84	156.5
1295.06	171
1298.27	177.5
1301.49	187.5
1304.7	179.5
1307.92	170.5
1311.13	183
1314.35	174
1317.56	174
1320.77	193.5
1323.98	182
1327.19	185.5
1330.41	198.5
1333.61	198
1336.82	188.5
1340.03	190.5
1343.24	188
1346.45	189
1349.66	201.5
1352.87	204.5
1356.07	185.5
1359.28	193.5
1362.48	213.5
1365.69	174
1368.89	178
1372.1	191
1375.3	200.5
1378.5	183.5
1381.71	202
1384.91	198.5
1388.11	210
1391.31	202
1394.51	187
1397.71	184
1400.91	191.5
1404.11	207.5
1407.31	190.5
1410.5	192
1413.7	175
1416.9	176
1420.1	212
1423.29	199.5
1426.48	190
1429.68	197.5
1432.87	182.5
1436.07	199.5
1439.26	184.5
1442.46	184
1445.65	171.5
1448.84	199.5
1452.03	191
1455.22	191.5
1458.41	195
1461.6	185
1464.79	190
1467.98	184
1471.17	180.5
1474.35	172.5
1477.54	187
1480.72	190
1483.91	193
1487.1	184
1490.28	198
1493.47	195
1496.65	184
1499.83	181
1503.02	174.5
1506.2	173
1509.38	172
1512.56	177
1515.74	172.5
1518.92	194.5
1522.1	196.5
1525.28	168.5
1528.46	180.5
1531.64	196.5
1534.82	203.5
1537.99	205.5
1541.17	224
1544.35	238
1547.52	239.5
1550.7	251
1553.87	240
1557.05	244.5
1560.22	249.5
1563.39	275
1566.56	287
1569.74	273.5
1572.91	313
1576.08	325
1579.25	341
1582.42	350
1585.59	350.5
1588.76	396
1591.93	407
1595.1	450.5
1598.26	465.5
1601.43	508.5
1604.6	496.5
1607.76	501
1610.93	509.5
1614.09	494
1617.26	507
1620.42	442
1623.59	383.5
1626.75	359
1629.91	363
1633.07	333.5
1636.24	346.5
1639.39	292
1642.56	308.5
1645.72	300.5
1648.87	304
1652.03	283.5
1655.19	283.5
1658.35	266
1661.51	273.5
1664.66	229.5
1667.82	239.5
1670.98	209.5
1674.13	210.5
1677.29	202.5
1680.44	200.5
1683.59	206.5
1686.75	174.5
1689.9	186.5
1693.05	164
1696.21	155.5
1699.36	176.5
1702.51	159.5
1705.66	146
1708.81	138.5
1711.96	129
1715.1	152
1718.25	136
1721.4	118
1724.55	124.5
1727.69	117
1730.84	111
1733.99	117
1737.13	108.5
1740.28	115
1743.42	103
1746.56	109
1749.71	117
1752.85	112
1755.99	101
1759.14	99.5
1762.28	88.5
1765.42	105
1768.56	99
1771.7	82
1774.83	100.5
1777.97	94.5
1781.11	90.5
1784.25	87.5
1787.38	83.5
1790.52	97
1793.66	79.5
1796.8	89.5
1799.93	98.5
1803.07	97
1806.2	80.5
1809.33	86
1812.47	92
1815.6	75.5
1818.73	85.5
1821.86	93.5
1824.99	95.5
1828.12	101.5
1831.25	89
1834.38	93.5
1837.51	90
1840.64	80.5
1843.77	84
1846.9	88.5
1850.02	85.5
1853.15	89.5
1856.28	98.5
1859.4	87
1862.53	81.5
1865.65	80.5
1868.78	79.5
1871.9	98.5
1875.02	84
1878.14	96
1881.26	86.5
1884.39	84.5
1887.51	93.5
1890.63	82.5
1893.75	88.5
1896.87	93
1899.99	85.5
1903.11	85.5
1906.22	92
1909.34	79
1912.46	96.5
1915.58	85
1918.69	89.5
1921.81	94
1924.92	89
1928.04	91.5
1931.15	86
1934.26	109
1937.38	102.5
1940.49	95
1943.6	93
1946.71	92
1949.82	97
1952.94	92.5
1956.05	84.5
1959.15	95.5
1962.27	80.5
1965.37	89.5
1968.48	114
1971.59	83.5
1974.7	91.5
1977.8	86
1980.91	91.5
1984.01	88
1987.12	89.5
1990.22	93.5
1993.33	91.5
1996.43	91.5
1999.53	89.5
2002.64	90.5
2005.74	90
2008.84	90.5
2011.94	95.5
2015.04	88
2018.14	106.5
2021.24	116
2024.34	85
2027.44	104
2030.54	88.5
2033.64	96
2036.73	81.5
2039.83	86.5
2042.93	80.5
2046.02	96.5
2049.12	88.5
2052.21	79
2055.31	86
2058.4	91
2061.49	77.5
2064.59	80.5
2067.68	90.5
2070.77	80.5
2073.86	85.5
2076.95	75
2080.04	87
2083.13	85
2086.22	103.5
2089.31	90
2092.4	93.5
2095.49	96.5
2098.57	94.5
2101.66	95
2104.75	93.5
2107.83	93.5
2110.92	90
2114	86
2117.09	93.5
2120.17	94
2123.26	92
2126.34	102.5
2129.42	92
2132.5	75.5
2135.58	79
2138.67	91
2141.75	92.5
2144.82	92.5
2147.91	95
2150.98	96.5
2154.06	100
2157.14	90
2160.22	97
2163.29	101
2166.37	91.5
2169.45	103.5
2172.52	72
2175.6	89.5
2178.67	97.5
2181.75	92.5
2184.82	116.5
2187.89	91.5
2190.97	93.5
2194.04	113.5
2197.11	103.5
2200.18	85.5
2203.25	96.5
2206.32	101.5
2209.39	97.5
2212.46	115.5
2215.53	104.5
2218.6	101
2221.67	108.5
2224.73	111
2227.8	103.5
2230.87	105.5
2233.93	115
2237	94.5
2240.06	107
2243.12	112
2246.19	103
2249.25	115
2252.32	90
2255.38	112.5
2258.44	98.5
2261.5	109.5
2264.56	99
2267.62	99
2270.68	110
2273.74	100.5
2276.8	115
2279.86	103.5
2282.92	108.5
2285.98	100
2289.03	101
2292.09	112.5
2295.15	104
2298.2	105.5
2301.25	100
2304.31	99.5
2307.36	101
2310.42	87.5
2313.47	90.5
2316.52	100
2319.58	117
2322.63	96
2325.68	113
2328.73	113
2331.78	117
2334.83	105.5
2337.88	105
2340.93	106.5
2343.97	107
2347.02	90
2350.07	95
2353.12	115
2356.16	101.5
2359.21	84.5
2362.25	99
2365.3	94.5
2368.34	95
2371.39	92.5
2374.43	97
2377.47	114
2380.52	100
2383.56	112.5
2386.6	111
2389.64	105
2392.68	95.5
2395.72	100.5
2398.76	103
2401.8	102.5
2404.84	112.5
2407.88	96.5
2410.91	97.5
2413.95	108
2416.99	103
2420.02	94
2423.06	94.5
2426.09	94
2429.13	104.5
2432.16	103.5
2435.2	99
2438.23	85.5
2441.26	96.5
2444.3	97
2447.33	87.5
2450.36	102.5
2453.39	106.5
2456.42	94
2459.45	93
2462.48	104
2465.51	116.5
2468.54	103
2471.57	89
2474.59	96
2477.62	100
2480.65	104.5
2483.67	102
2486.7	103
2489.72	112
2492.75	100
2495.77	98
2498.8	103
2501.82	98.5
2504.84	107
2507.86	95
2510.89	100.5
2513.91	101
2516.93	102.5
2519.95	106.5
2522.97	101.5
2525.99	112.5
2529.01	96.5
2532.03	111.5
2535.04	93
2538.06	106
2541.08	106.5
2544.09	102
2547.11	108
2550.13	106
2553.14	110
2556.16	103.5
2559.17	113.5
2562.18	104
2565.2	103.5
2568.21	100.5
2571.22	115.5
2574.23	114.5
2577.25	108.5
2580.26	111
2583.27	111.5
2586.28	108.5
2589.29	104
2592.29	115.5
2595.3	107.5
2598.31	110
2601.32	113.5
2604.33	109.5
2607.33	103
2610.34	114
2613.34	114
2616.35	115.5
2619.35	116
2622.36	98
2625.36	90
2628.36	122.5
2631.37	105
2634.37	110.5
2637.37	118.5
2640.37	100.5
2643.38	109
2646.37	122
2649.37	120
2652.37	110
2655.37	115
2658.37	107
2661.37	108
2664.37	109.5
2667.36	114
2670.36	106
2673.36	101
2676.35	114.5
2679.35	112
2682.34	122
2685.34	102
2688.33	110
2691.32	109
2694.32	121
2697.31	98
2700.3	114.5
2703.29	112
2706.28	122.5
2709.27	110
2712.26	115
2715.25	110
2718.24	117
2721.23	104
2724.22	121
2727.21	117
2730.19	117.5
2733.18	116.5
2736.17	115
2739.15	131.5
2742.14	125
2745.12	115
2748.11	120
2751.09	111.5
2754.07	116.5
2757.06	125
2760.04	127.5
2763.02	126
2766	117.5
2768.98	115.5
2771.96	117
2774.94	135
2777.92	113
2780.9	115.5
2783.88	104
2786.86	102
2789.84	118
2792.81	121.5
2795.79	106.5
2798.77	135
2801.74	116
2804.72	120
2807.69	125
2810.67	111.5
2813.64	115
2816.62	111
2819.59	115
2822.56	99
2825.53	124.5
2828.5	99.5
2831.48	129
2834.45	120.5
2837.42	109.5
2840.39	109
2843.36	120.5
2846.32	110
2849.29	121.5
2852.26	108
2855.23	121.5
2858.2	116
2861.16	133.5
2864.13	128
2867.09	115.5
2870.06	126
2873.02	136.5
2875.99	126
2878.95	122
2881.91	127.5
2884.88	129
2887.84	129
2890.8	118
2893.76	126.5
2896.73	126.5
2899.69	125
2902.65	138
2905.6	128.5
2908.56	135
2911.52	122.5
2914.48	126
2917.44	142
2920.4	142
2923.35	141
2926.31	132
2929.27	136
2932.22	156.5
2935.18	143
2938.13	155
2941.08	171.5
2944.04	160.5
2946.99	134
2949.94	145.5
2952.89	145.5
2955.85	153
2958.8	139
2961.75	143.5
2964.7	147
2967.65	149
2970.6	143
2973.54	146.5
2976.49	167.5
2979.44	157
2982.39	150
2985.34	145
2988.28	172
2991.23	154
2994.17	159
2997.12	165.5
3000.07	158.5
3003.01	154
3005.95	162
3008.9	164.5
3011.84	175.5
3014.78	175.5
3017.72	154
3020.67	167.5
3023.6	187.5
3026.55	178.5
3029.49	171
3032.43	191.5
3035.37	166
3038.31	186
3041.24	180
3044.18	182.5
3047.12	189
3050.06	208
3052.99	206
3055.93	205
3058.86	203.5
3061.8	226
3064.73	200
3067.67	204
3070.6	224.5
3073.53	223.5
3076.47	230
3079.4	241
3082.33	219.5
3085.26	242
3088.19	240.5
3091.12	258.5
3094.05	255
3096.98	234
3099.91	257
3102.84	280.5
3105.77	292.5
3108.69	280
3111.62	278
3114.55	288.5
3117.48	281.5
3120.4	317
3123.33	310.5
3126.25	304.5
3129.18	307
3132.1	327
3135.02	314
3137.95	340
3140.87	368
3143.79	348.5
3146.71	356.5
3149.63	350
3152.56	378
3155.48	373
3158.4	390.5
3161.31	420.5
3164.23	381
3167.15	384
3170.07	406.5
3172.99	406.5
3175.91	423
3178.82	447
3181.74	448
3184.66	431
3187.57	448
3190.48	442.5
3193.4	473.5
3196.31	466.5
3199.23	458.5
3202.14	480
3205.05	463
3207.96	481
3210.88	474
3213.79	474.5
3216.7	479.5
3219.61	477
3222.52	479.5
3225.43	498.5
3228.34	504
3231.25	471
3234.15	505.5
3237.06	494.5
3239.97	500
3242.88	485
3245.78	493.5
3248.69	498
3251.59	506
3254.5	486.5
3257.4	512.5
3260.31	525.5
3263.21	519
3266.11	497.5
3269.02	510
3271.92	512.5
3274.82	518.5
3277.72	515.5
3280.62	506.5
3283.52	513.5
3286.42	509.5
3289.32	523
3292.22	517.5
3295.12	515
3298.02	496
3300.91	511.5
3303.81	525.5
3306.71	537
3309.61	523.5
3312.5	526.5
3315.4	522.5
3318.29	515
3321.18	520.5
3324.08	549.5
3326.97	515.5
3329.87	696
3332.76	530.5
3335.65	523
3338.54	517.5
3341.43	535
3344.32	545
3347.21	521
3350.11	535
3353	525.5
3355.88	563.5
3358.77	546.5
3361.66	510.5
3364.55	531
3367.44	546
3370.32	588
3373.21	562
3376.09	548
3378.98	543.5
3381.86	568
3384.75	583
3387.63	559
3390.52	550.5
3393.4	552.5
3396.28	548.5
3399.17	551.5
3402.05	559
3404.93	577.5
3407.81	547
3410.69	591
3413.57	583.5
3416.45	541.5
3419.33	605
3422.21	566.5
3425.09	551.5
3427.96	533
3430.84	538.5
3433.72	524
3436.59	531.5
3439.47	539
3442.35	542
3445.22	535
3448.1	545
3450.97	571
3453.85	539.5
3456.72	512
3459.59	527
3462.46	538
3465.34	509.5
3468.21	512.5
3471.08	494
3473.95	516.5
3476.82	489
3479.69	467
3482.56	464.5
3485.43	448.5
3488.3	496
3491.16	513
3494.03	447
3496.9	437.5
3499.77	461
3502.63	445.5
3505.5	423.5
3508.36	433
3511.23	449.5
3514.09	391
3516.96	424.5
3519.82	394
3522.68	402
3525.55	376
3528.41	379
3531.27	382
3534.13	385.5
3536.99	372.5
3539.85	372
3542.71	342.5
3545.57	392.5
3548.43	354
3551.29	355
3554.15	337
3557.01	326.5
3559.86	338
3562.72	322.5
3565.58	321
3568.43	329.5
3571.29	313
3574.14	332.5
3577	318.5
3579.85	291
3582.71	318.5
3585.56	302
3588.41	275
3591.26	291
3594.12	273.5
3596.97	279.5
3599.82	274.5
3602.67	267.5
3605.52	260
3608.37	263
3611.22	260.5
3614.07	254
3616.92	255
3619.77	262.5
3622.61	229
3625.46	237.5
3628.31	235
3631.15	223.5
3634	237
3636.84	220.5
3639.69	220.5
3642.53	213.5
3645.38	212
3648.22	220
3651.06	199.5
3653.91	187.5
3656.75	188
3659.59	192
3662.43	164.5
3665.27	158.5
3668.11	161
3670.95	159
3673.8	171.5
3676.63	157
3679.47	156
3682.31	142.5
3685.15	130.5
3687.99	128.5
3690.82	135
3693.66	132
3696.5	111
3699.33	113.5
3702.17	106
3705	102
3707.84	109
3710.67	88.5
3713.5	106
3716.34	114.5
3719.17	92
3722	92.5
3724.83	77.5
3727.66	98
3730.5	90.5
3733.33	79.5
3736.16	94.5
3738.99	91
3741.81	77.5
3744.64	78.5
3747.47	80.5
3750.3	87
3753.13	68
3755.95	63.5
3758.78	74
3761.61	88
3764.43	81
3767.26	85
3770.08	83.5
3772.91	77
3775.73	81.5
3778.55	79
3781.38	81.5
3784.2	72
3787.02	82
3789.84	62
3792.67	79.5
3795.49	77
3798.31	81.5
3801.13	74.5
3803.95	75.5
3806.76	67
3809.58	75.5
3812.4	63
3815.22	59
3818.04	80
3820.85	74.5
3823.67	74.5
3826.49	76
3829.3	78
3832.12	64
3834.93	71
3837.75	70
3840.56	62
3843.37	68.5
3846.19	75.5
3849	64.5
3850.41	72.5